Workbook

Sheet 汇总
A1: 建筑资源产出统计（当前配置）
A2: 生成日期：2026-08-13；统计对象为当前配置中基础时产大于 0 的建筑。每座建筑、每小时、未叠加科技加成。
A4: 统计结论
A5: 产银两建筑数 | B5: =COUNTIF('参数'!A5:A9,"银两")+COUNTIF('参数'!C5:C9,"latrine")
A6: 产粮食建筑数 | B6: =COUNTIF('参数'!A5:A9,"粮食")
A7: 口径 | B7: 基础建筑产出；茅厕同时产粮食和等量银两；不含科技加成。
A10: 资源 | B10: 建筑名称 | C10: Key | D10: 基础时产 | E10: 每级增长系数 | F10: 最大等级 | G10: 1级产出/小时 | H10: 满级产出/小时 | I10: 特殊规则
A11: 银两 | B11: ='参数'!B6 | C11: ='参数'!C6 | D11: ='参数'!E6 | E11: ='参数'!F6 | F11: ='参数'!G6 | G11: ='参数'!E6 | H11: ='参数'!E6*(1+'参数'!F6*('参数'!G6-1))
A12: 银两 | B12: ='参数'!B7 | C12: ='参数'!C7 | D12: ='参数'!E7 | E12: ='参数'!F7 | F12: ='参数'!G7 | G12: ='参数'!E7 | H12: ='参数'!E7*(1+'参数'!F7*('参数'!G7-1))
A13: 银两 | B13: ='参数'!B8 | C13: ='参数'!C8 | D13: ='参数'!E8 | E13: ='参数'!F8 | F13: ='参数'!G8 | G13: ='参数'!E8 | H13: ='参数'!E8*(1+'参数'!F8*('参数'!G8-1)) | I13: 配置为粮食产出；运行时额外按相同数值计入银两。
A14: 银两 | B14: ='参数'!B9 | C14: ='参数'!C9 | D14: ='参数'!E9 | E14: ='参数'!F9 | F14: ='参数'!G9 | G14: ='参数'!E9 | H14: ='参数'!E9*(1+'参数'!F9*('参数'!G9-1))
A15: 粮食 | B15: ='参数'!B5 | C15: ='参数'!C5 | D15: ='参数'!E5 | E15: ='参数'!F5 | F15: ='参数'!G5 | G15: ='参数'!E5 | H15: ='参数'!E5*(1+'参数'!F5*('参数'!G5-1))

Sheet 参数
A1: 建筑资源产出参数（当前配置）
A2: 输入值来自 data/building_templates.yaml；最大等级来自 gameplay/constants.py 的 BUILDING_MAX_LEVELS。蓝色字体为配置输入，产出明细中的计算结果由公式生成。
A4: 资源类型 | B4: 建筑名称 | C4: Key | D4: 建筑分类 | E4: 基础时产 | F4: 每级增长系数 | G4: 最大等级 | H4: 产出规则 | I4: 配置来源 | J4: 等级上限来源
A5: 粮食 | B5: 农田 | C5: farm | D5: 资源生产 | E5: 850 | F5: 0.1197551 | G5: 50 | H5: 按建筑自身 resource_type 计入。 | I5: data/building_templates.yaml | J5: gameplay/constants.py
A6: 银两 | B6: 税务司 | C6: tax_office | D6: 资源生产 | E6: 500 | F6: 0.17 | G6: 20 | H6: 按建筑自身 resource_type 计入。 | I6: data/building_templates.yaml | J6: gameplay/constants.py
A7: 银两 | B7: 澡堂 | C7: bathhouse | D7: 资源生产 | E7: 345 | F7: 0.1 | G7: 20 | H7: 按建筑自身 resource_type 计入。 | I7: data/building_templates.yaml | J7: gameplay/constants.py
A8: 粮食 | B8: 茅厕 | C8: latrine | D8: 资源生产 | E8: 430 | F8: 0.15 | G8: 20 | H8: 配置为粮食产出；运行时额外按相同数值计入银两。 | I8: data/building_templates.yaml | J8: gameplay/constants.py
A9: 银两 | B9: 酒馆 | C9: tavern | D9: 人员管理 | E9: 345 | F9: 0.211 | G9: 10 | H9: 按建筑自身 resource_type 计入。 | I9: data/building_templates.yaml | J9: gameplay/constants.py

Sheet 银两产出
A1: 银两建筑逐级产出
A2: 单位：银两/小时；按每座建筑计算，未叠加科技加成。公式：基础时产 × (1 + 每级增长系数 × (等级 - 1))。茅厕的银两产出为运行时特殊追加。
A4: 建筑名称 | B4: Key | C4: 基础时产 | D4: 等级 | E4: 最大等级 | F4: 每级增长系数 | G4: 银两产出/小时 | H4: 备注
A5: ='参数'!B6 | B5: ='参数'!C6 | C5: ='参数'!E6 | D5: 1 | E5: ='参数'!G6 | F5: ='参数'!F6 | G5: =IF(D5<=E5,C5*(1+F5*(D5-1)),"")
A6: ='参数'!B6 | B6: ='参数'!C6 | C6: ='参数'!E6 | D6: 2 | E6: ='参数'!G6 | F6: ='参数'!F6 | G6: =IF(D6<=E6,C6*(1+F6*(D6-1)),"")
A7: ='参数'!B6 | B7: ='参数'!C6 | C7: ='参数'!E6 | D7: 3 | E7: ='参数'!G6 | F7: ='参数'!F6 | G7: =IF(D7<=E7,C7*(1+F7*(D7-1)),"")
A8: ='参数'!B6 | B8: ='参数'!C6 | C8: ='参数'!E6 | D8: 4 | E8: ='参数'!G6 | F8: ='参数'!F6 | G8: =IF(D8<=E8,C8*(1+F8*(D8-1)),"")
A9: ='参数'!B6 | B9: ='参数'!C6 | C9: ='参数'!E6 | D9: 5 | E9: ='参数'!G6 | F9: ='参数'!F6 | G9: =IF(D9<=E9,C9*(1+F9*(D9-1)),"")
A10: ='参数'!B6 | B10: ='参数'!C6 | C10: ='参数'!E6 | D10: 6 | E10: ='参数'!G6 | F10: ='参数'!F6 | G10: =IF(D10<=E10,C10*(1+F10*(D10-1)),"")
A11: ='参数'!B6 | B11: ='参数'!C6 | C11: ='参数'!E6 | D11: 7 | E11: ='参数'!G6 | F11: ='参数'!F6 | G11: =IF(D11<=E11,C11*(1+F11*(D11-1)),"")
A12: ='参数'!B6 | B12: ='参数'!C6 | C12: ='参数'!E6 | D12: 8 | E12: ='参数'!G6 | F12: ='参数'!F6 | G12: =IF(D12<=E12,C12*(1+F12*(D12-1)),"")
A13: ='参数'!B6 | B13: ='参数'!C6 | C13: ='参数'!E6 | D13: 9 | E13: ='参数'!G6 | F13: ='参数'!F6 | G13: =IF(D13<=E13,C13*(1+F13*(D13-1)),"")
A14: ='参数'!B6 | B14: ='参数'!C6 | C14: ='参数'!E6 | D14: 10 | E14: ='参数'!G6 | F14: ='参数'!F6 | G14: =IF(D14<=E14,C14*(1+F14*(D14-1)),"")
A15: ='参数'!B6 | B15: ='参数'!C6 | C15: ='参数'!E6 | D15: 11 | E15: ='参数'!G6 | F15: ='参数'!F6 | G15: =IF(D15<=E15,C15*(1+F15*(D15-1)),"")
A16: ='参数'!B6 | B16: ='参数'!C6 | C16: ='参数'!E6 | D16: 12 | E16: ='参数'!G6 | F16: ='参数'!F6 | G16: =IF(D16<=E16,C16*(1+F16*(D16-1)),"")
A17: ='参数'!B6 | B17: ='参数'!C6 | C17: ='参数'!E6 | D17: 13 | E17: ='参数'!G6 | F17: ='参数'!F6 | G17: =IF(D17<=E17,C17*(1+F17*(D17-1)),"")
A18: ='参数'!B6 | B18: ='参数'!C6 | C18: ='参数'!E6 | D18: 14 | E18: ='参数'!G6 | F18: ='参数'!F6 | G18: =IF(D18<=E18,C18*(1+F18*(D18-1)),"")
A19: ='参数'!B6 | B19: ='参数'!C6 | C19: ='参数'!E6 | D19: 15 | E19: ='参数'!G6 | F19: ='参数'!F6 | G19: =IF(D19<=E19,C19*(1+F19*(D19-1)),"")
A20: ='参数'!B6 | B20: ='参数'!C6 | C20: ='参数'!E6 | D20: 16 | E20: ='参数'!G6 | F20: ='参数'!F6 | G20: =IF(D20<=E20,C20*(1+F20*(D20-1)),"")
A21: ='参数'!B6 | B21: ='参数'!C6 | C21: ='参数'!E6 | D21: 17 | E21: ='参数'!G6 | F21: ='参数'!F6 | G21: =IF(D21<=E21,C21*(1+F21*(D21-1)),"")
A22: ='参数'!B6 | B22: ='参数'!C6 | C22: ='参数'!E6 | D22: 18 | E22: ='参数'!G6 | F22: ='参数'!F6 | G22: =IF(D22<=E22,C22*(1+F22*(D22-1)),"")
A23: ='参数'!B6 | B23: ='参数'!C6 | C23: ='参数'!E6 | D23: 19 | E23: ='参数'!G6 | F23: ='参数'!F6 | G23: =IF(D23<=E23,C23*(1+F23*(D23-1)),"")
A24: ='参数'!B6 | B24: ='参数'!C6 | C24: ='参数'!E6 | D24: 20 | E24: ='参数'!G6 | F24: ='参数'!F6 | G24: =IF(D24<=E24,C24*(1+F24*(D24-1)),"")
A25: ='参数'!B7 | B25: ='参数'!C7 | C25: ='参数'!E7 | D25: 1 | E25: ='参数'!G7 | F25: ='参数'!F7 | G25: =IF(D25<=E25,C25*(1+F25*(D25-1)),"")
A26: ='参数'!B7 | B26: ='参数'!C7 | C26: ='参数'!E7 | D26: 2 | E26: ='参数'!G7 | F26: ='参数'!F7 | G26: =IF(D26<=E26,C26*(1+F26*(D26-1)),"")
A27: ='参数'!B7 | B27: ='参数'!C7 | C27: ='参数'!E7 | D27: 3 | E27: ='参数'!G7 | F27: ='参数'!F7 | G27: =IF(D27<=E27,C27*(1+F27*(D27-1)),"")
A28: ='参数'!B7 | B28: ='参数'!C7 | C28: ='参数'!E7 | D28: 4 | E28: ='参数'!G7 | F28: ='参数'!F7 | G28: =IF(D28<=E28,C28*(1+F28*(D28-1)),"")
A29: ='参数'!B7 | B29: ='参数'!C7 | C29: ='参数'!E7 | D29: 5 | E29: ='参数'!G7 | F29: ='参数'!F7 | G29: =IF(D29<=E29,C29*(1+F29*(D29-1)),"")
A30: ='参数'!B7 | B30: ='参数'!C7 | C30: ='参数'!E7 | D30: 6 | E30: ='参数'!G7 | F30: ='参数'!F7 | G30: =IF(D30<=E30,C30*(1+F30*(D30-1)),"")
A31: ='参数'!B7 | B31: ='参数'!C7 | C31: ='参数'!E7 | D31: 7 | E31: ='参数'!G7 | F31: ='参数'!F7 | G31: =IF(D31<=E31,C31*(1+F31*(D31-1)),"")
A32: ='参数'!B7 | B32: ='参数'!C7 | C32: ='参数'!E7 | D32: 8 | E32: ='参数'!G7 | F32: ='参数'!F7 | G32: =IF(D32<=E32,C32*(1+F32*(D32-1)),"")
A33: ='参数'!B7 | B33: ='参数'!C7 | C33: ='参数'!E7 | D33: 9 | E33: ='参数'!G7 | F33: ='参数'!F7 | G33: =IF(D33<=E33,C33*(1+F33*(D33-1)),"")
A34: ='参数'!B7 | B34: ='参数'!C7 | C34: ='参数'!E7 | D34: 10 | E34: ='参数'!G7 | F34: ='参数'!F7 | G34: =IF(D34<=E34,C34*(1+F34*(D34-1)),"")
A35: ='参数'!B7 | B35: ='参数'!C7 | C35: ='参数'!E7 | D35: 11 | E35: ='参数'!G7 | F35: ='参数'!F7 | G35: =IF(D35<=E35,C35*(1+F35*(D35-1)),"")
A36: ='参数'!B7 | B36: ='参数'!C7 | C36: ='参数'!E7 | D36: 12 | E36: ='参数'!G7 | F36: ='参数'!F7 | G36: =IF(D36<=E36,C36*(1+F36*(D36-1)),"")
A37: ='参数'!B7 | B37: ='参数'!C7 | C37: ='参数'!E7 | D37: 13 | E37: ='参数'!G7 | F37: ='参数'!F7 | G37: =IF(D37<=E37,C37*(1+F37*(D37-1)),"")
A38: ='参数'!B7 | B38: ='参数'!C7 | C38: ='参数'!E7 | D38: 14 | E38: ='参数'!G7 | F38: ='参数'!F7 | G38: =IF(D38<=E38,C38*(1+F38*(D38-1)),"")
A39: ='参数'!B7 | B39: ='参数'!C7 | C39: ='参数'!E7 | D39: 15 | E39: ='参数'!G7 | F39: ='参数'!F7 | G39: =IF(D39<=E39,C39*(1+F39*(D39-1)),"")
A40: ='参数'!B7 | B40: ='参数'!C7 | C40: ='参数'!E7 | D40: 16 | E40: ='参数'!G7 | F40: ='参数'!F7 | G40: =IF(D40<=E40,C40*(1+F40*(D40-1)),"")
A41: ='参数'!B7 | B41: ='参数'!C7 | C41: ='参数'!E7 | D41: 17 | E41: ='参数'!G7 | F41: ='参数'!F7 | G41: =IF(D41<=E41,C41*(1+F41*(D41-1)),"")
...

Sheet 粮食产出
A1: 粮食建筑逐级产出
A2: 单位：粮食/小时；按每座建筑计算，未叠加科技加成。公式：基础时产 × (1 + 每级增长系数 × (等级 - 1))。
A4: 建筑名称 | B4: Key | C4: 基础时产 | D4: 等级 | E4: 最大等级 | F4: 每级增长系数 | G4: 粮食产出/小时 | H4: 备注
A5: ='参数'!B5 | B5: ='参数'!C5 | C5: ='参数'!E5 | D5: 1 | E5: ='参数'!G5 | F5: ='参数'!F5 | G5: =IF(D5<=E5,C5*(1+F5*(D5-1)),"")
A6: ='参数'!B5 | B6: ='参数'!C5 | C6: ='参数'!E5 | D6: 2 | E6: ='参数'!G5 | F6: ='参数'!F5 | G6: =IF(D6<=E6,C6*(1+F6*(D6-1)),"")
A7: ='参数'!B5 | B7: ='参数'!C5 | C7: ='参数'!E5 | D7: 3 | E7: ='参数'!G5 | F7: ='参数'!F5 | G7: =IF(D7<=E7,C7*(1+F7*(D7-1)),"")
A8: ='参数'!B5 | B8: ='参数'!C5 | C8: ='参数'!E5 | D8: 4 | E8: ='参数'!G5 | F8: ='参数'!F5 | G8: =IF(D8<=E8,C8*(1+F8*(D8-1)),"")
A9: ='参数'!B5 | B9: ='参数'!C5 | C9: ='参数'!E5 | D9: 5 | E9: ='参数'!G5 | F9: ='参数'!F5 | G9: =IF(D9<=E9,C9*(1+F9*(D9-1)),"")
A10: ='参数'!B5 | B10: ='参数'!C5 | C10: ='参数'!E5 | D10: 6 | E10: ='参数'!G5 | F10: ='参数'!F5 | G10: =IF(D10<=E10,C10*(1+F10*(D10-1)),"")
A11: ='参数'!B5 | B11: ='参数'!C5 | C11: ='参数'!E5 | D11: 7 | E11: ='参数'!G5 | F11: ='参数'!F5 | G11: =IF(D11<=E11,C11*(1+F11*(D11-1)),"")
A12: ='参数'!B5 | B12: ='参数'!C5 | C12: ='参数'!E5 | D12: 8 | E12: ='参数'!G5 | F12: ='参数'!F5 | G12: =IF(D12<=E12,C12*(1+F12*(D12-1)),"")
A13: ='参数'!B5 | B13: ='参数'!C5 | C13: ='参数'!E5 | D13: 9 | E13: ='参数'!G5 | F13: ='参数'!F5 | G13: =IF(D13<=E13,C13*(1+F13*(D13-1)),"")
A14: ='参数'!B5 | B14: ='参数'!C5 | C14: ='参数'!E5 | D14: 10 | E14: ='参数'!G5 | F14: ='参数'!F5 | G14: =IF(D14<=E14,C14*(1+F14*(D14-1)),"")
A15: ='参数'!B5 | B15: ='参数'!C5 | C15: ='参数'!E5 | D15: 11 | E15: ='参数'!G5 | F15: ='参数'!F5 | G15: =IF(D15<=E15,C15*(1+F15*(D15-1)),"")
A16: ='参数'!B5 | B16: ='参数'!C5 | C16: ='参数'!E5 | D16: 12 | E16: ='参数'!G5 | F16: ='参数'!F5 | G16: =IF(D16<=E16,C16*(1+F16*(D16-1)),"")
A17: ='参数'!B5 | B17: ='参数'!C5 | C17: ='参数'!E5 | D17: 13 | E17: ='参数'!G5 | F17: ='参数'!F5 | G17: =IF(D17<=E17,C17*(1+F17*(D17-1)),"")
A18: ='参数'!B5 | B18: ='参数'!C5 | C18: ='参数'!E5 | D18: 14 | E18: ='参数'!G5 | F18: ='参数'!F5 | G18: =IF(D18<=E18,C18*(1+F18*(D18-1)),"")
A19: ='参数'!B5 | B19: ='参数'!C5 | C19: ='参数'!E5 | D19: 15 | E19: ='参数'!G5 | F19: ='参数'!F5 | G19: =IF(D19<=E19,C19*(1+F19*(D19-1)),"")
A20: ='参数'!B5 | B20: ='参数'!C5 | C20: ='参数'!E5 | D20: 16 | E20: ='参数'!G5 | F20: ='参数'!F5 | G20: =IF(D20<=E20,C20*(1+F20*(D20-1)),"")
A21: ='参数'!B5 | B21: ='参数'!C5 | C21: ='参数'!E5 | D21: 17 | E21: ='参数'!G5 | F21: ='参数'!F5 | G21: =IF(D21<=E21,C21*(1+F21*(D21-1)),"")
A22: ='参数'!B5 | B22: ='参数'!C5 | C22: ='参数'!E5 | D22: 18 | E22: ='参数'!G5 | F22: ='参数'!F5 | G22: =IF(D22<=E22,C22*(1+F22*(D22-1)),"")
A23: ='参数'!B5 | B23: ='参数'!C5 | C23: ='参数'!E5 | D23: 19 | E23: ='参数'!G5 | F23: ='参数'!F5 | G23: =IF(D23<=E23,C23*(1+F23*(D23-1)),"")
A24: ='参数'!B5 | B24: ='参数'!C5 | C24: ='参数'!E5 | D24: 20 | E24: ='参数'!G5 | F24: ='参数'!F5 | G24: =IF(D24<=E24,C24*(1+F24*(D24-1)),"")
A25: ='参数'!B5 | B25: ='参数'!C5 | C25: ='参数'!E5 | D25: 21 | E25: ='参数'!G5 | F25: ='参数'!F5 | G25: =IF(D25<=E25,C25*(1+F25*(D25-1)),"")
A26: ='参数'!B5 | B26: ='参数'!C5 | C26: ='参数'!E5 | D26: 22 | E26: ='参数'!G5 | F26: ='参数'!F5 | G26: =IF(D26<=E26,C26*(1+F26*(D26-1)),"")
A27: ='参数'!B5 | B27: ='参数'!C5 | C27: ='参数'!E5 | D27: 23 | E27: ='参数'!G5 | F27: ='参数'!F5 | G27: =IF(D27<=E27,C27*(1+F27*(D27-1)),"")
A28: ='参数'!B5 | B28: ='参数'!C5 | C28: ='参数'!E5 | D28: 24 | E28: ='参数'!G5 | F28: ='参数'!F5 | G28: =IF(D28<=E28,C28*(1+F28*(D28-1)),"")
A29: ='参数'!B5 | B29: ='参数'!C5 | C29: ='参数'!E5 | D29: 25 | E29: ='参数'!G5 | F29: ='参数'!F5 | G29: =IF(D29<=E29,C29*(1+F29*(D29-1)),"")
A30: ='参数'!B5 | B30: ='参数'!C5 | C30: ='参数'!E5 | D30: 26 | E30: ='参数'!G5 | F30: ='参数'!F5 | G30: =IF(D30<=E30,C30*(1+F30*(D30-1)),"")
A31: ='参数'!B5 | B31: ='参数'!C5 | C31: ='参数'!E5 | D31: 27 | E31: ='参数'!G5 | F31: ='参数'!F5 | G31: =IF(D31<=E31,C31*(1+F31*(D31-1)),"")
A32: ='参数'!B5 | B32: ='参数'!C5 | C32: ='参数'!E5 | D32: 28 | E32: ='参数'!G5 | F32: ='参数'!F5 | G32: =IF(D32<=E32,C32*(1+F32*(D32-1)),"")
A33: ='参数'!B5 | B33: ='参数'!C5 | C33: ='参数'!E5 | D33: 29 | E33: ='参数'!G5 | F33: ='参数'!F5 | G33: =IF(D33<=E33,C33*(1+F33*(D33-1)),"")
A34: ='参数'!B5 | B34: ='参数'!C5 | C34: ='参数'!E5 | D34: 30 | E34: ='参数'!G5 | F34: ='参数'!F5 | G34: =IF(D34<=E34,C34*(1+F34*(D34-1)),"")
A35: ='参数'!B5 | B35: ='参数'!C5 | C35: ='参数'!E5 | D35: 31 | E35: ='参数'!G5 | F35: ='参数'!F5 | G35: =IF(D35<=E35,C35*(1+F35*(D35-1)),"")
A36: ='参数'!B5 | B36: ='参数'!C5 | C36: ='参数'!E5 | D36: 32 | E36: ='参数'!G5 | F36: ='参数'!F5 | G36: =IF(D36<=E36,C36*(1+F36*(D36-1)),"")
A37: ='参数'!B5 | B37: ='参数'!C5 | C37: ='参数'!E5 | D37: 33 | E37: ='参数'!G5 | F37: ='参数'!F5 | G37: =IF(D37<=E37,C37*(1+F37*(D37-1)),"")
A38: ='参数'!B5 | B38: ='参数'!C5 | C38: ='参数'!E5 | D38: 34 | E38: ='参数'!G5 | F38: ='参数'!F5 | G38: =IF(D38<=E38,C38*(1+F38*(D38-1)),"")
A39: ='参数'!B5 | B39: ='参数'!C5 | C39: ='参数'!E5 | D39: 35 | E39: ='参数'!G5 | F39: ='参数'!F5 | G39: =IF(D39<=E39,C39*(1+F39*(D39-1)),"")
A40: ='参数'!B5 | B40: ='参数'!C5 | C40: ='参数'!E5 | D40: 36 | E40: ='参数'!G5 | F40: ='参数'!F5 | G40: =IF(D40<=E40,C40*(1+F40*(D40-1)),"")
A41: ='参数'!B5 | B41: ='参数'!C5 | C41: ='参数'!E5 | D41: 37 | E41: ='参数'!G5 | F41: ='参数'!F5 | G41: =IF(D41<=E41,C41*(1+F41*(D41-1)),"")
...
