Workbook

Sheet 装备总表
A1: 序号 | B1: 装备key | C1: 装备名称 | D1: 价格 | E1: 占用空间 | F1: 生命 | G1: 防御 | H1: 武力 | I1: 智力 | J1: 敏捷 | K1: 带兵上限 | L1: 运势 | M1: 合计 | N1: 套装名称 | O1: 套装属性 | P1: 稀有度 | Q1: 稀有度中文 | R1: 装备类型 | S1: 细分类型 | T1: 装备描述 | U1: 可交易 | V1: 可在仓库直接使用 | W1: 图片文件 | X1: 图标 | Y1: effect_type | Z1: 套装key | AA1: 护院兵种加成 | AB1: 可普通锻造 | AC1: 可图纸合成 | AD1: 图纸key | AE1: 获取途径摘要 | AF1: 原始effect_payload(JSON) | AG1: 数据来源
A2: 1 | B2: equip_bumao | C2: 布帽 | D2: 100 | E2: 50 | F2: 100 | G2: 5 | H2: 0 | I2: 8 | J2: 5 | K2: 0 | L2: 0 | M2: =F2/54+G2+H2+I2+J2+L2*1.2+K2/2 -> 19.851852 | N2: 无 | O2: 无 | P2: black | Q2: 普通/白 | R2: 头盔 | S2: 头盔 | T2: 一般老百姓戴的帽子，遮风遮日用。 | U2: 是 | V2: 否 | W2: equip_bumao.png | Y2: equip_helmet | AA2: 无 | AB2: 是 | AC2: 否 | AE2: 铁匠铺直接锻造 | AF2: {"hp":100,"defense":5,"intellect":8,"agility":5} | AG2: data/item_templates.yaml:L3336
A3: 2 | B3: equip_caomao | C3: 斗笠 | D3: 0 | E3: 50 | F3: 250 | G3: 10 | H3: 5 | I3: 0 | J3: 0 | K3: 0 | L3: 0 | M3: =F3/54+G3+H3+I3+J3+L3*1.2+K3/2 -> 19.62963 | N3: 一蓑烟雨 | O3: 一蓑烟雨4件: 生命+200、武力+20、带兵上限+20、运势+15 | P3: black | Q3: 普通/白 | R3: 头盔 | S3: 头盔 | T3: 由棕叶编织而成的宽边帽，可以简单遮蔽风雨。 | U3: 否 | V3: 否 | W3: equip_caomao.png | Y3: equip_helmet | Z3: starter_cloth_set | AA3: 无 | AB3: 否 | AC3: 否 | AE3: 宝箱随机装备 | AF3: {"hp":250,"defense":10,"force":5,"set_key":"starter_cloth_set","set_description":"一蓑烟雨","set_bonus":{"pieces":4,"bonus":{"hp":200,"force":20,"troop_capacity":20,"luck":15}}} | AG3: data/item_templates.yaml:L3240
A4: 3 | B4: equip_niupimao | C4: 牛皮帽 | D4: 300 | E4: 50 | F4: 100 | G4: 10 | H4: 5 | I4: 0 | J4: 5 | K4: 0 | L4: 0 | M4: =F4/54+G4+H4+I4+J4+L4*1.2+K4/2 -> 21.851852 | N4: 无 | O4: 无 | P4: black | Q4: 普通/白 | R4: 头盔 | S4: 头盔 | T4: 既能御寒，又能稍微保护脑袋。 | U4: 是 | V4: 否 | W4: equip_niupimao.png | Y4: equip_helmet | AA4: 无 | AB4: 是 | AC4: 否 | AE4: 铁匠铺直接锻造 | AF4: {"hp":100,"defense":10,"force":5,"agility":5} | AG4: data/item_templates.yaml:L3351
A5: 4 | B5: equip_zhubiankui | C5: 竹编盔 | D5: 200 | E5: 50 | F5: 300 | G5: 15 | H5: 0 | I5: 0 | J5: 0 | K5: 0 | L5: 0 | M5: =F5/54+G5+H5+I5+J5+L5*1.2+K5/2 -> 20.555556 | N5: 无 | O5: 无 | P5: black | Q5: 普通/白 | R5: 头盔 | S5: 头盔 | T5: 终南山道士所编，取材自千年古竹林，轻巧透气。 | U5: 是 | V5: 否 | W5: equip_zhubiankui.png | Y5: equip_helmet | AA5: 无 | AB5: 否 | AC5: 否 | AE5: 宝箱随机装备 | AF5: {"hp":300,"defense":15} | AG5: data/item_templates.yaml:L3410
A6: 5 | B6: equip_baihongkui | C6: 白虹盔 | D6: 3000 | E6: 75 | F6: 160 | G6: 12 | H6: 4 | I6: 0 | J6: 0 | K6: 16 | L6: 0 | M6: =F6/54+G6+H6+I6+J6+L6*1.2+K6/2 -> 26.962963 | N6: 无 | O6: 无 | P6: green | Q6: 优秀/绿 | R6: 头盔 | S6: 头盔 | T6: 精钢铸就，盔顶白缨飘飘，威武不凡。 | U6: 是 | V6: 否 | W6: equip_baihongkui.png | Y6: equip_helmet | AA6: 无 | AB6: 是 | AC6: 否 | AE6: 商铺购买；宝箱随机装备；铁匠铺直接锻造 | AF6: {"hp":160,"defense":12,"force":4,"troop_capacity":16} | AG6: data/item_templates.yaml:L3395
A7: 6 | B7: equip_baoutoukui | C7: 豹头盔 | D7: 2800 | E7: 75 | F7: 200 | G7: 20 | H7: 0 | I7: 0 | J7: 15 | K7: 0 | L7: 0 | M7: =F7/54+G7+H7+I7+J7+L7*1.2+K7/2 -> 38.703704 | N7: 无 | O7: 无 | P7: green | Q7: 优秀/绿 | R7: 头盔 | S7: 头盔 | T7: 豹首造型的头盔，相传为豹子头林冲年轻时所佩。 | U7: 是 | V7: 否 | W7: equip_baoutoukui.png | Y7: equip_helmet | AA7: 无 | AB7: 否 | AC7: 否 | AE7: 任务宝箱装备；宝箱随机装备 | AF7: {"hp":200,"defense":20,"agility":15} | AG7: data/item_templates.yaml:L3460
A8: 7 | B8: equip_huwenkui | C8: 虎纹盔 | D8: 2500 | E8: 75 | F8: 220 | G8: 18 | H8: 15 | I8: 0 | J8: 0 | K8: 0 | L8: 0 | M8: =F8/54+G8+H8+I8+J8+L8*1.2+K8/2 -> 37.074074 | N8: 无 | O8: 无 | P8: green | Q8: 优秀/绿 | R8: 头盔 | S8: 头盔 | T8: 据说是某位虎将的遗物，虎纹威猛，煞气逼人。 | U8: 是 | V8: 否 | W8: equip_huwenkui.png | Y8: equip_helmet | AA8: 无 | AB8: 否 | AC8: 否 | AE8: 任务宝箱装备；宝箱随机装备 | AF8: {"hp":220,"defense":18,"force":15} | AG8: data/item_templates.yaml:L3446
A9: 8 | B9: equip_qingtengguan | C9: 青藤冠 | D9: 2600 | E9: 75 | F9: 200 | G9: 10 | H9: 0 | I9: 15 | J9: 0 | K9: 0 | L9: 5 | M9: =F9/54+G9+H9+I9+J9+L9*1.2+K9/2 -> 34.703704 | N9: 无 | O9: 无 | P9: green | Q9: 优秀/绿 | R9: 头盔 | S9: 头盔 | T9: 以藤蔓与玉扣编织而成，据说出自某位隐居山林的高人之手。 | U9: 是 | V9: 否 | W9: equip_qingtengguan.png | Y9: equip_helmet | AA9: 无 | AB9: 否 | AC9: 否 | AE9: 任务宝箱装备；宝箱随机装备 | AF9: {"hp":200,"defense":10,"intellect":15,"luck":5} | AG9: data/item_templates.yaml:L3488
A10: 9 | B10: equip_tieyekui | C10: 铁叶盔 | D10: 800 | E10: 75 | F10: 120 | G10: 8 | H10: 12 | I10: 0 | J10: 0 | K10: 0 | L10: 0 | M10: =F10/54+G10+H10+I10+J10+L10*1.2+K10/2 -> 22.222222 | N10: 无 | O10: 无 | P10: green | Q10: 优秀/绿 | R10: 头盔 | S10: 头盔 | T10: 有不错的保护效果，但是太过沉重，压着脑袋很难受。 | U10: 是 | V10: 否 | W10: equip_tieyekui.png | Y10: equip_helmet | AA10: 无 | AB10: 是 | AC10: 否 | AE10: 商铺购买；宝箱随机装备；铁匠铺直接锻造 | AF10: {"hp":120,"defense":8,"force":12} | AG10: data/item_templates.yaml:L3366
A11: 10 | B11: equip_yanlingmao | C11: 雁翎帽 | D11: 2200 | E11: 75 | F11: 200 | G11: 15 | H11: 0 | I11: 0 | J11: 15 | K11: 0 | L11: 0 | M11: =F11/54+G11+H11+I11+J11+L11*1.2+K11/2 -> 33.703704 | N11: 无 | O11: 无 | P11: green | Q11: 优秀/绿 | R11: 头盔 | S11: 头盔 | T11: 以雁翎装饰的轻帽，是江湖侠客间广为流传的款式。 | U11: 是 | V11: 否 | W11: equip_yanlingmao.png | Y11: equip_helmet | AA11: 无 | AB11: 否 | AC11: 否 | AE11: 任务宝箱装备；宝箱随机装备 | AF11: {"hp":200,"defense":15,"agility":15} | AG11: data/item_templates.yaml:L3474
A12: 11 | B12: equip_yemantoukie | C12: 野蛮头盔 | D12: 2000 | E12: 75 | F12: 150 | G12: 10 | H12: 20 | I12: 0 | J12: 0 | K12: 0 | L12: 0 | M12: =F12/54+G12+H12+I12+J12+L12*1.2+K12/2 -> 32.777778 | N12: 野蛮套装 | O12: 野蛮套装2件: 生命+300、武力+25、防御+10 | P12: green | Q12: 优秀/绿 | R12: 头盔 | S12: 头盔 | T12: 北方蛮族的战利品，以兽皮与铁铆拼制，带有异域风格。 | U12: 是 | V12: 否 | W12: equip_yemantoukie.png | Y12: equip_helmet | Z12: yeman_set | AA12: 无 | AB12: 否 | AC12: 否 | AE12: 任务宝箱装备 | AF12: {"hp":150,"defense":10,"force":20,"set_key":"yeman_set","set_description":"野蛮套装","set_bonus":{"pieces":2,"bonus":{"hp":300,"force":25,"defense":10}}} | AG12: data/item_templates.yaml:L3425
A13: 12 | B13: equip_yulindin | C13: 鱼鳞顶 | D13: 1500 | E13: 75 | F13: 400 | G13: 12 | H13: 1 | I13: 0 | J13: 4 | K13: 0 | L13: 0 | M13: =F13/54+G13+H13+I13+J13+L13*1.2+K13/2 -> 24.407407 | N13: 无 | O13: 无 | P13: green | Q13: 优秀/绿 | R13: 头盔 | S13: 头盔 | T13: 鱼鳞状的铜片编成，轻便而坚固。 | U13: 是 | V13: 否 | W13: equip_yulindin.png | Y13: equip_helmet | AA13: 无 | AB13: 是 | AC13: 否 | AE13: 商铺购买；宝箱随机装备；铁匠铺直接锻造 | AF13: {"hp":400,"defense":12,"force":1,"agility":4} | AG13: data/item_templates.yaml:L3380
A14: 13 | B14: equip_action_mask | C14: 动感超人面具 | D14: 6000 | E14: 100 | F14: 300 | G14: 5 | H14: 20 | I14: 0 | J14: 15 | K14: 0 | L14: 0 | M14: =F14/54+G14+H14+I14+J14+L14*1.2+K14/2 -> 45.555556 | N14: 春日部防卫队 | O14: 春日部防卫队2件: 防御+20、攻击+30；春日部防卫队4件: 生命+600、敏捷+20、运势+15 | P14: blue | Q14: 稀有/蓝 | R14: 头盔 | S14: 头盔 | T14: 春日部防卫队收藏的英雄面具，戴上后总觉得出拳更有气势。 | U14: 是 | V14: 否 | W14: equip_action_mask.png | Y14: equip_helmet | Z14: kasukabe_defense_set | AA14: 无 | AB14: 否 | AC14: 否 | AE14: 任务宝箱装备 | AF14: {"hp":300,"defense":5,"force":20,"agility":15,"set_key":"kasukabe_defense_set","set_description":"春日部防卫队","set_bonus":[{"pieces":2,"bonus":{"defense":20,"attack":30}},{"pieces":4,"bonus":{"hp":600,"agility":20,"luck":15}}]} | AG14: data/item_templates.yaml:L3113
A15: 14 | B15: equip_feiyukui | C15: 飞羽盔 | D15: 5600 | E15: 100 | F15: 400 | G15: 15 | H15: 0 | I15: 0 | J15: 25 | K15: 0 | L15: 10 | M15: =F15/54+G15+H15+I15+J15+L15*1.2+K15/2 -> 59.407407 | N15: 无 | O15: 无 | P15: blue | Q15: 稀有/蓝 | R15: 头盔 | S15: 头盔 | T15: 以百鸟之羽装饰的轻盔，据说曾是某位神箭手的心爱之物。 | U15: 是 | V15: 否 | W15: equip_feiyukui.png | Y15: equip_helmet | AA15: 无 | AB15: 否 | AC15: 否 | AE15: 任务宝箱装备 | AF15: {"hp":400,"defense":15,"agility":25,"luck":10} | AG15: data/item_templates.yaml:L3615
A16: 15 | B16: equip_hantiekui | C16: 寒铁盔 | D16: 6500 | E16: 100 | F16: 380 | G16: 35 | H16: 5 | I16: 0 | J16: 0 | K16: 0 | L16: 0 | M16: =F16/54+G16+H16+I16+J16+L16*1.2+K16/2 -> 47.037037 | N16: 无 | O16: 无 | P16: blue | Q16: 稀有/蓝 | R16: 头盔 | S16: 头盔 | T16: 以极北寒铁铸就，触之冰凉入骨，常年不受寒侵。 | U16: 是 | V16: 否 | W16: equip_hantiekui.png | Y16: equip_helmet | AA16: 无 | AB16: 否 | AC16: 否 | AE16: 任务宝箱装备 | AF16: {"hp":380,"defense":35,"force":5} | AG16: data/item_templates.yaml:L3586
A17: 16 | B17: equip_jiaodoushitoukui | C17: 角斗士头盔 | D17: 6200 | E17: 100 | F17: 350 | G17: 25 | H17: 20 | I17: 0 | J17: 0 | K17: 0 | L17: 0 | M17: =F17/54+G17+H17+I17+J17+L17*1.2+K17/2 -> 51.481481 | N17: 角斗士套装 | O17: 角斗士套装4件: 生命+280、防御+10、武力+30、敏捷+15 | P17: blue | Q17: 稀有/蓝 | R17: 头盔 | S17: 头盔 | T17: 角斗场老兵常用的重盔，面甲刻有胜场纹记，兼顾防护与压迫感。 | U17: 是 | V17: 否 | W17: equip_jiaodoushitoukui.png | Y17: equip_helmet | Z17: jiaodoushi_set | AA17: 无 | AB17: 否 | AC17: 否 | AE17: 宝箱随机装备；竞技场随机兑换 | AF17: {"hp":350,"defense":25,"force":20,"set_key":"jiaodoushi_set","set_description":"角斗士套装","set_bonus":{"pieces":4,"bonus":{"hp":280,"defense":10,"force":30,"agility":15}}} | AG17: data/item_templates.yaml:L3528
A18: 17 | B18: equip_langyakui | C18: 狼牙盔 | D18: 5800 | E18: 100 | F18: 300 | G18: 20 | H18: 20 | I18: 0 | J18: 15 | K18: 0 | L18: 0 | M18: =F18/54+G18+H18+I18+J18+L18*1.2+K18/2 -> 60.555556 | N18: 无 | O18: 无 | P18: blue | Q18: 稀有/蓝 | R18: 头盔 | S18: 头盔 | T18: 草原狼王的头骨所制，盔缘嵌有狼牙，凶悍异常。 | U18: 是 | V18: 否 | W18: equip_langyakui.png | Y18: equip_helmet | AA18: 无 | AB18: 否 | AC18: 否 | AE18: 任务宝箱装备 | AF18: {"hp":300,"defense":20,"force":20,"agility":15} | AG18: data/item_templates.yaml:L3600
A19: 18 | B19: equip_qinglongkui | C19: 青龙盔 | D19: 5500 | E19: 100 | F19: 400 | G19: 20 | H19: 0 | I19: 22 | J19: 0 | K19: 0 | L19: 0 | M19: =F19/54+G19+H19+I19+J19+L19*1.2+K19/2 -> 49.407407 | N19: 四象套装 | O19: 四象套装4件: 生命+360、武力+35、智力+35、敏捷+20 | P19: blue | Q19: 稀有/蓝 | R19: 头盔 | S19: 头盔 | T19: 青龙纹路盘绕其上，相传是东方青龙庙镇殿之物。 | U19: 是 | V19: 否 | W19: equip_qinglongkui.png | Y19: equip_helmet | Z19: sixiang_set | AA19: 无 | AB19: 否 | AC19: 是 | AD19: blueprint_qinglongkui | AE19: 图纸合成（任务宝箱）；图纸合成（帮会图纸领取）；图纸合成（竞技场随机图纸兑换） | AF19: {"hp":400,"defense":20,"intellect":22,"set_key":"sixiang_set","set_description":"四象套装","set_bonus":{"pieces":4,"bonus":{"hp":360,"force":35,"intellect":35,"agility":20}}} | AG19: data/item_templates.yaml:L3564
A20: 19 | B20: equip_xiaoweitoukui | C20: 校尉头盔 | D20: 5000 | E20: 100 | F20: 350 | G20: 20 | H20: 15 | I20: 0 | J20: 0 | K20: 20 | L20: 0 | M20: =F20/54+G20+H20+I20+J20+L20*1.2+K20/2 -> 51.481481 | N20: 校尉套装 | O20: 校尉套装4件: 生命+360、防御+15、武力+40、带兵上限+100 | P20: blue | Q20: 稀有/蓝 | R20: 头盔 | S20: 头盔 | T20: 军中校尉制式头盔，上有龙纹标识，象征军阶与荣誉。 | U20: 是 | V20: 否 | W20: equip_xiaoweitoukui.png | Y20: equip_helmet | Z20: xiaowei_set | AA20: 无 | AB20: 否 | AC20: 是 | AD20: blueprint_xiaoweitoukie | AE20: 任务宝箱装备；图纸合成（任务宝箱）；图纸合成（帮会图纸领取）；图纸合成（竞技场随机图纸兑换）；宝箱随机装备 | AF20: {"hp":350,"defense":20,"force":15,"troop_capacity":20,"set_key":"xiaowei_set","set_description":"校尉套装","set_bonus":{"pieces":4,"bonus":{"hp":360,"defense":15,"force":40,"troop_capacity":100}}} | AG20: data/item_templates.yaml:L3505
A21: 20 | B21: equip_xuantiekui | C21: 玄铁盔 | D21: 6000 | E21: 100 | F21: 340 | G21: 40 | H21: 15 | I21: 0 | J21: 0 | K21: 0 | L21: 0 | M21: =F21/54+G21+H21+I21+J21+L21*1.2+K21/2 -> 61.296296 | N21: 无 | O21: 无 | P21: blue | Q21: 稀有/蓝 | R21: 头盔 | S21: 头盔 | T21: 以罕见玄铁锻成，据传耗费了三位铁匠十年心血。 | U21: 是 | V21: 否 | W21: equip_xuantiekui.png | Y21: equip_helmet | AA21: 无 | AB21: 否 | AC21: 否 | AE21: 任务宝箱装备 | AF21: {"hp":340,"defense":40,"force":15} | AG21: data/item_templates.yaml:L3550
A22: 21 | B22: equip_yunwenkui | C22: 云纹盔 | D22: 6200 | E22: 100 | F22: 300 | G22: 15 | H22: 0 | I22: 25 | J22: 0 | K22: 0 | L22: 10 | M22: =F22/54+G22+H22+I22+J22+L22*1.2+K22/2 -> 57.555556 | N22: 无 | O22: 无 | P22: blue | Q22: 稀有/蓝 | R22: 头盔 | S22: 头盔 | T22: 盔面云纹如行云流水，出自名匠"云中子"之手。 | U22: 是 | V22: 否 | W22: equip_yunwenkui.png | Y22: equip_helmet | AA22: 无 | AB22: 否 | AC22: 否 | AE22: 任务宝箱装备 | AF22: {"hp":300,"defense":15,"intellect":25,"luck":10} | AG22: data/item_templates.yaml:L3630
A23: 22 | B23: equip_bawangkui | C23: 霸王盔 | D23: 18000 | E23: 150 | F23: 500 | G23: 30 | H23: 35 | I23: 0 | J23: 0 | K23: 0 | L23: 0 | M23: =F23/54+G23+H23+I23+J23+L23*1.2+K23/2 -> 74.259259 | N23: 无 | O23: 无 | P23: purple | Q23: 史诗/紫 | R23: 头盔 | S23: 头盔 | T23: 相传为西楚霸王项羽的遗物，气势撼人，威压四方。 | U23: 是 | V23: 否 | W23: equip_bawangkui.png | Y23: equip_helmet | AA23: 无 | AB23: 否 | AC23: 否 | AE23: 任务宝箱装备 | AF23: {"hp":500,"defense":30,"force":35} | AG23: data/item_templates.yaml:L3691
A24: 23 | B24: equip_fenglingguan | C24: 凤翎冠 | D24: 14000 | E24: 150 | F24: 360 | G24: 21 | H24: 0 | I24: 32 | J24: 0 | K24: 0 | L24: 11 | M24: =F24/54+G24+H24+I24+J24+L24*1.2+K24/2 -> 72.866667 | N24: 凤翎套装 | O24: 凤翎套装3件: 智力+60、运势+30 | P24: purple | Q24: 史诗/紫 | R24: 头盔 | S24: 头盔 | T24: 以凤凰翎羽点缀的华冠，曾是后宫贵妃所赐之物。 | U24: 是 | V24: 否 | W24: equip_fenglingguan.png | Y24: equip_helmet | Z24: fengling_set | AA24: 无 | AB24: 否 | AC24: 是 | AD24: blueprint_fenglingguan | AE24: 图纸合成（竞技场随机图纸兑换） | AF24: {"hp":360,"defense":21,"intellect":32,"luck":11,"set_key":"fengling_set","set_description":"凤翎套装","set_bonus":{"pieces":3,"bonus":{"intellect":60,"luck":30}}} | AG24: data/item_templates.yaml:L3670
A25: 24 | B25: equip_pojunkui | C25: 破军盔 | D25: 15500 | E25: 150 | F25: 445 | G25: 26 | H25: 27 | I25: 0 | J25: 15 | K25: 0 | L25: 0 | M25: =F25/54+G25+H25+I25+J25+L25*1.2+K25/2 -> 76.240741 | N25: 无 | O25: 无 | P25: purple | Q25: 史诗/紫 | R25: 头盔 | S25: 头盔 | T25: 破军星位所铸，据传戴者必成一方悍将。 | U25: 是 | V25: 否 | W25: equip_pojunkui.png | Y25: equip_helmet | AA25: 无 | AB25: 否 | AC25: 否 | AE25: 任务宝箱装备 | AF25: {"hp":445,"defense":26,"force":27,"agility":15} | AG25: data/item_templates.yaml:L3727
A26: 25 | B26: equip_qilinkui | C26: 麒麟盔 | D26: 15000 | E26: 150 | F26: 440 | G26: 33 | H26: 28 | I26: 3 | J26: 0 | K26: 0 | L26: 0 | M26: =F26/54+G26+H26+I26+J26+L26*1.2+K26/2 -> 72.148148 | N26: 麒麟套装 | O26: 麒麟套装4件: 生命+420、武力+38、敏捷+18、运势+30 | P26: purple | Q26: 史诗/紫 | R26: 头盔 | S26: 头盔 | T26: 仿麒麟头颅锻造，相传是某位开国将军的传家之宝。 | U26: 是 | V26: 否 | W26: equip_qilinkui.png | Y26: equip_helmet | Z26: qilin_set | AA26: 无 | AB26: 否 | AC26: 是 | AD26: blueprint_qilinkui | AE26: 图纸合成（任务宝箱）；图纸合成（帮会图纸领取）；图纸合成（竞技场随机图纸兑换）；宝箱随机装备 | AF26: {"hp":440,"defense":33,"force":28,"intellect":3,"set_key":"qilin_set","set_description":"麒麟套装","set_bonus":{"pieces":4,"bonus":{"hp":420,"force":38,"agility":18,"luck":30}}} | AG26: data/item_templates.yaml:L3647
A27: 26 | B27: equip_tianjiguan | C27: 天机冠 | D27: 14500 | E27: 150 | F27: 390 | G27: 20 | H27: 0 | I27: 38 | J27: 0 | K27: 0 | L27: 14 | M27: =F27/54+G27+H27+I27+J27+L27*1.2+K27/2 -> 82.022222 | N27: 无 | O27: 无 | P27: purple | Q27: 史诗/紫 | R27: 头盔 | S27: 头盔 | T27: 以天机门秘法打造，冠中暗藏机括，可察天象变化。 | U27: 是 | V27: 否 | W27: equip_tianjiguan.png | Y27: equip_helmet | AA27: 无 | AB27: 否 | AC27: 否 | AE27: 任务宝箱装备 | AF27: {"hp":390,"defense":20,"intellect":38,"luck":14} | AG27: data/item_templates.yaml:L3742
A28: 27 | B28: equip_xuanwukui | C28: 玄武盔 | D28: 16000 | E28: 150 | F28: 545 | G28: 44 | H28: 10 | I28: 10 | J28: 0 | K28: 0 | L28: 0 | M28: =F28/54+G28+H28+I28+J28+L28*1.2+K28/2 -> 74.092593 | N28: 玄武套装 | O28: 玄武套装4件: 生命+260、防御+70、武力+20 | P28: purple | Q28: 史诗/紫 | R28: 头盔 | S28: 头盔 | T28: 仿玄武之形锻造，背负龟壳纹样，象征长寿与坚固。 | U28: 是 | V28: 否 | W28: equip_xuanwukui.png | Y28: equip_helmet | Z28: xuanwu_set | AA28: 无 | AB28: 否 | AC28: 是 | AD28: blueprint_xuanwukui | AE28: 任务宝箱装备；图纸合成（竞技场随机图纸兑换） | AF28: {"hp":545,"defense":44,"force":10,"intellect":10,"set_key":"xuanwu_set","set_description":"玄武套装","set_bonus":{"pieces":4,"bonus":{"hp":260,"defense":70,"force":20}}} | AG28: data/item_templates.yaml:L3705
A29: 28 | B29: equip_diwangkui | C29: 帝王盔 | D29: 48000 | E29: 200 | F29: 503 | G29: 29 | H29: 29 | I29: 29 | J29: 0 | K29: 0 | L29: 0 | M29: =F29/54+G29+H29+I29+J29+L29*1.2+K29/2 -> 96.314815 | N29: 无 | O29: 无 | P29: orange | Q29: 传说/橙 | R29: 头盔 | S29: 头盔 | T29: 历代帝王御用的铠甲头盔，象征至高无上的权威。 | U29: 是 | V29: 否 | W29: equip_diwangkui.png | Y29: equip_helmet | AA29: 无 | AB29: 否 | AC29: 否 | AE29: 任务宝箱装备；碎片累计兑换（任务宝箱） | AF29: {"hp":503,"defense":29,"force":29,"intellect":29} | AG29: data/item_templates.yaml:L3775
A30: 29 | B30: equip_longhuangguan | C30: 龙皇冠 | D30: 50000 | E30: 200 | F30: 620 | G30: 26 | H30: 12 | I30: 32 | J30: 0 | K30: 20 | L30: 0 | M30: =F30/54+G30+H30+I30+J30+L30*1.2+K30/2 -> 91.481481 | N30: 无 | O30: 无 | P30: orange | Q30: 传说/橙 | R30: 头盔 | S30: 头盔 | T30: 相传为远古龙皇遗落人间的宝物，冠身隐有龙吟。 | U30: 是 | V30: 否 | W30: equip_longhuangguan.png | Y30: equip_helmet | AA30: 无 | AB30: 否 | AC30: 否 | AE30: 任务宝箱装备 | AF30: {"hp":620,"defense":26,"force":12,"intellect":32,"troop_capacity":20} | AG30: data/item_templates.yaml:L3759
A31: 30 | B31: equip_taixudiguan | C31: 太虚帝冠 | D31: 55000 | E31: 200 | F31: 560 | G31: 30 | H31: 0 | I31: 34 | J31: 0 | K31: 0 | L31: 14 | M31: =F31/54+G31+H31+I31+J31+L31*1.2+K31/2 -> 91.17037 | N31: 无 | O31: 无 | P31: orange | Q31: 传说/橙 | R31: 头盔 | S31: 头盔 | T31: 传说为太虚剑宗创派祖师所佩，内藏太虚真意。 | U31: 是 | V31: 否 | W31: equip_taixudiguan.png | Y31: equip_helmet | AA31: 无 | AB31: 否 | AC31: 否 | AE31: 任务宝箱装备 | AF31: {"hp":560,"defense":30,"intellect":34,"luck":14} | AG31: data/item_templates.yaml:L3790
A32: 31 | B32: equip_bupao | C32: 布袍 | D32: 100 | E32: 50 | F32: 80 | G32: 6 | H32: 0 | I32: 8 | J32: 0 | K32: 0 | L32: 0 | M32: =F32/54+G32+H32+I32+J32+L32*1.2+K32/2 -> 15.481481 | N32: 无 | O32: 无 | P32: black | Q32: 普通/白 | R32: 护甲 | S32: 护甲 | T32: 普通老百姓穿的衣服，所谓布衣。 | U32: 是 | V32: 否 | W32: equip_bupao.png | Y32: equip_armor | AA32: 无 | AB32: 是 | AC32: 否 | AE32: 商铺购买；宝箱随机装备；铁匠铺直接锻造 | AF32: {"hp":80,"defense":6,"intellect":8} | AG32: data/item_templates.yaml:L3809
A33: 32 | B33: equip_cubujia | C33: 粗布甲 | D33: 200 | E33: 50 | F33: 150 | G33: 10 | H33: 5 | I33: 0 | J33: 5 | K33: 0 | L33: 0 | M33: =F33/54+G33+H33+I33+J33+L33*1.2+K33/2 -> 22.777778 | N33: 无 | O33: 无 | P33: black | Q33: 普通/白 | R33: 护甲 | S33: 护甲 | T33: 多层粗布压缝而成，出自军中后勤的批量制作。 | U33: 是 | V33: 否 | W33: equip_cubujia.png | Y33: equip_armor | AA33: 无 | AB33: 否 | AC33: 否 | AE33: 宝箱随机装备 | AF33: {"hp":150,"defense":10,"force":5,"agility":5} | AG33: data/item_templates.yaml:L3867
A34: 33 | B34: equip_shengpijia | C34: 生皮甲 | D34: 300 | E34: 50 | F34: 160 | G34: 12 | H34: 4 | I34: 0 | J34: 0 | K34: 0 | L34: 0 | M34: =F34/54+G34+H34+I34+J34+L34*1.2+K34/2 -> 18.962963 | N34: 无 | O34: 无 | P34: black | Q34: 普通/白 | R34: 护甲 | S34: 护甲 | T34: 没经过硝制的动物皮做成的护甲，防御力很弱。 | U34: 是 | V34: 否 | W34: equip_shengpijia.png | Y34: equip_armor | AA34: 无 | AB34: 是 | AC34: 否 | AE34: 商铺购买；宝箱随机装备；铁匠铺直接锻造 | AF34: {"hp":160,"defense":12,"force":4} | AG34: data/item_templates.yaml:L3823
A35: 34 | B35: equip_suoyi | C35: 蓑衣 | D35: 0 | E35: 50 | F35: 100 | G35: 10 | H35: 5 | I35: 0 | J35: 5 | K35: 0 | L35: 0 | M35: =F35/54+G35+H35+I35+J35+L35*1.2+K35/2 -> 21.851852 | N35: 一蓑烟雨 | O35: 一蓑烟雨4件: 生命+200、武力+20、带兵上限+20、运势+15 | P35: black | Q35: 普通/白 | R35: 护甲 | S35: 护甲 | T35: 以莎草编织而成，劳动人民遮风避雨的必需品。 | U35: 否 | V35: 否 | W35: buyi.png | Y35: equip_armor | Z35: starter_cloth_set | AA35: 无 | AB35: 否 | AC35: 否 | AE35: 宝箱随机装备 | AF35: {"hp":100,"defense":10,"force":5,"agility":5,"set_key":"starter_cloth_set","set_description":"一蓑烟雨","set_bonus":{"pieces":4,"bonus":{"hp":200,"force":20,"troop_capacity":20,"luck":15}}} | AG35: data/item_templates.yaml:L3263
A36: 35 | B36: equip_housipao | C36: 厚丝袍 | D36: 800 | E36: 75 | F36: 80 | G36: 12 | H36: 0 | I36: 4 | J36: 6 | K36: 0 | L36: 0 | M36: =F36/54+G36+H36+I36+J36+L36*1.2+K36/2 -> 23.481481 | N36: 无 | O36: 无 | P36: green | Q36: 优秀/绿 | R36: 护甲 | S36: 护甲 | T36: 用油浸泡过的粗丝织成，又软又轻，但却能抵挡普通刀剑。 | U36: 是 | V36: 否 | W36: equip_housipao.png | Y36: equip_armor | AA36: 无 | AB36: 是 | AC36: 否 | AE36: 商铺购买；宝箱随机装备；铁匠铺直接锻造 | AF36: {"hp":80,"defense":12,"intellect":4,"agility":6} | AG36: data/item_templates.yaml:L3837
A37: 36 | B37: equip_nichangyuyi | C37: 霓裳羽衣 | D37: 2800 | E37: 75 | F37: 50 | G37: 15 | H37: 0 | I37: 15 | J37: 0 | K37: 0 | L37: 8 | M37: =F37/54+G37+H37+I37+J37+L37*1.2+K37/2 -> 40.525926 | N37: 霓裳 | O37: 霓裳3件: 生命+150、智力+20、敏捷+10、运势+15 | P37: green | Q37: 优秀/绿 | R37: 护甲 | S37: 护甲 | T37: 以流霞丝与细甲片缀成的羽衣，轻灵不失护身之力，文武门客都能穿出从容气度。 | U37: 是 | V37: 否 | W37: equip_nichangyuyi.png | Y37: equip_armor | Z37: nichang_set | AA37: 无 | AB37: 否 | AC37: 否 | AE37: 任务宝箱装备；宝箱独立随机物品组 | AF37: {"hp":50,"defense":15,"intellect":15,"luck":8,"set_key":"nichang_set","set_description":"霓裳","set_bonus":{"pieces":3,"bonus":{"hp":150,"intellect":20,"agility":10,"luck":15}}} | AG37: data/item_templates.yaml:L3954
A38: 37 | B38: equip_qingzhujia | C38: 青竹甲 | D38: 2200 | E38: 75 | F38: 200 | G38: 20 | H38: 5 | I38: 0 | J38: 12 | K38: 0 | L38: 0 | M38: =F38/54+G38+H38+I38+J38+L38*1.2+K38/2 -> 40.703704 | N38: 无 | O38: 无 | P38: green | Q38: 优秀/绿 | R38: 护甲 | S38: 护甲 | T38: 以蜀中翠竹片编织而成，是巴蜀匠人的独门手艺。 | U38: 是 | V38: 否 | W38: equip_qingzhujia.png | Y38: equip_armor | AA38: 无 | AB38: 否 | AC38: 否 | AE38: 任务宝箱装备；宝箱随机装备 | AF38: {"hp":200,"defense":20,"force":5,"agility":12} | AG38: data/item_templates.yaml:L3925
A39: 38 | B39: equip_shanwenjia | C39: 山纹甲 | D39: 2800 | E39: 75 | F39: 500 | G39: 20 | H39: 10 | I39: 0 | J39: 0 | K39: 0 | L39: 0 | M39: =F39/54+G39+H39+I39+J39+L39*1.2+K39/2 -> 39.259259 | N39: 无 | O39: 无 | P39: green | Q39: 优秀/绿 | R39: 护甲 | S39: 护甲 | T39: 甲面刻有五岳山纹，相传是五岳派镇派之物。 | U39: 是 | V39: 否 | W39: equip_shanwenjia.png | Y39: equip_armor | AA39: 无 | AB39: 否 | AC39: 否 | AE39: 任务宝箱装备；宝箱随机装备 | AF39: {"hp":500,"defense":20,"force":10} | AG39: data/item_templates.yaml:L3911
A40: 39 | B40: equip_shapijia | C40: 鲨皮甲 | D40: 1500 | E40: 75 | F40: 200 | G40: 14 | H40: 4 | I40: 0 | J40: 4 | K40: 0 | L40: 0 | M40: =F40/54+G40+H40+I40+J40+L40*1.2+K40/2 -> 25.703704 | N40: 无 | O40: 无 | P40: green | Q40: 优秀/绿 | R40: 护甲 | S40: 护甲 | T40: 鲨鱼皮做成的铠甲，是轻便铠甲中最坚固的。 | U40: 是 | V40: 否 | W40: equip_shapijia.png | Y40: equip_armor | AA40: 无 | AB40: 是 | AC40: 否 | AE40: 商铺购买；宝箱随机装备；铁匠铺直接锻造 | AF40: {"hp":200,"defense":14,"force":4,"agility":4} | AG40: data/item_templates.yaml:L3852
...

Sheet 套装效果
A1: 套装key | B1: 套装名称 | C1: 生效件数 | D1: 攻击 | E1: 防御 | F1: 生命 | G1: 武力 | H1: 智力 | I1: 敏捷 | J1: 运势 | K1: 带兵上限 | L1: 成员装备 | M1: 成员装备key | N1: 数据来源
A2: starter_cloth_set | B2: 一蓑烟雨 | C2: 4 | D2: 0 | E2: 0 | F2: 200 | G2: 20 | H2: 0 | I2: 0 | J2: 15 | K2: 20 | L2: 斗笠；蓑衣；草鞋；铁剑 | M2: equip_caomao；equip_suoyi；equip_caoxie；equip_tiejian | N2: data/item_templates.yaml:L3240
A3: yeman_set | B3: 野蛮套装 | C3: 2 | D3: 0 | E3: 10 | F3: 300 | G3: 25 | H3: 0 | I3: 0 | J3: 0 | K3: 0 | L3: 野蛮头盔；野蛮砍刀 | M3: equip_yemantoukie；equip_yemankandao | N3: data/item_templates.yaml:L3425
A4: kasukabe_defense_set | B4: 春日部防卫队 | C4: 2 | D4: 30 | E4: 20 | F4: 0 | G4: 0 | H4: 0 | I4: 0 | J4: 0 | K4: 0 | L4: 动感超人面具；春日部小书包；动感光波手套；野原家的平底锅；小白的散步绳 | M4: equip_action_mask；equip_kasukabe_satchel；equip_action_beam_glove；equip_nohara_pan；equip_shiro_leash | N4: data/item_templates.yaml:L3113
A5: kasukabe_defense_set | B5: 春日部防卫队 | C5: 4 | D5: 0 | E5: 0 | F5: 600 | G5: 0 | H5: 0 | I5: 20 | J5: 15 | K5: 0 | L5: 动感超人面具；春日部小书包；动感光波手套；野原家的平底锅；小白的散步绳 | M5: equip_action_mask；equip_kasukabe_satchel；equip_action_beam_glove；equip_nohara_pan；equip_shiro_leash | N5: data/item_templates.yaml:L3113
A6: jiaodoushi_set | B6: 角斗士套装 | C6: 4 | D6: 0 | E6: 10 | F6: 280 | G6: 30 | H6: 0 | I6: 15 | J6: 0 | K6: 0 | L6: 角斗士头盔；角斗士胸甲；角斗士之靴；角斗士之锤 | M6: equip_jiaodoushitoukui；equip_jiaodoushixiongjia；equip_jiaodoushizhixue；equip_jiaodoushizhichui | N6: data/item_templates.yaml:L3528
A7: sixiang_set | B7: 四象套装 | C7: 4 | D7: 0 | E7: 0 | F7: 360 | G7: 35 | H7: 35 | I7: 20 | J7: 0 | K7: 0 | L7: 青龙盔；青龙甲；青龙靴；青龙刀 | M7: equip_qinglongkui；equip_qinglongjia；equip_qinglongxue；equip_qinglongdao | N7: data/item_templates.yaml:L3564
A8: xiaowei_set | B8: 校尉套装 | C8: 4 | D8: 0 | E8: 15 | F8: 360 | G8: 40 | H8: 0 | I8: 0 | J8: 0 | K8: 100 | L8: 校尉头盔；校尉铠甲；校尉长靴；校尉长剑 | M8: equip_xiaoweitoukui；equip_xiaoweikaijia；equip_xiaoweichangxue；equip_xiaoweichangjian | N8: data/item_templates.yaml:L3505
A9: fengling_set | B9: 凤翎套装 | C9: 3 | D9: 0 | E9: 0 | F9: 0 | G9: 0 | H9: 60 | I9: 0 | J9: 30 | K9: 0 | L9: 凤翎冠；凤翎扇；凤凰羽 | M9: equip_fenglingguan；equip_fenglingshan；equip_fenghuangyu | N9: data/item_templates.yaml:L3670
A10: qilin_set | B10: 麒麟套装 | C10: 4 | D10: 0 | E10: 0 | F10: 420 | G10: 38 | H10: 0 | I10: 18 | J10: 30 | K10: 0 | L10: 麒麟盔；麒麟甲；麒麟靴；麒麟刀；麒麟坠 | M10: equip_qilinkui；equip_qilinjia；equip_qilinxue；equip_qilindao；equip_qilinzui | N10: data/item_templates.yaml:L3647
A11: xuanwu_set | B11: 玄武套装 | C11: 4 | D11: 0 | E11: 70 | F11: 260 | G11: 20 | H11: 0 | I11: 0 | J11: 0 | K11: 0 | L11: 玄武盔；玄武甲；玄武靴；玄武锤 | M11: equip_xuanwukui；equip_xuanwujia；equip_xuanwuxue；equip_xuanwuchui | N11: data/item_templates.yaml:L3705
A12: nichang_set | B12: 霓裳 | C12: 3 | D12: 0 | E12: 0 | F12: 150 | G12: 0 | H12: 20 | I12: 10 | J12: 15 | K12: 0 | L12: 霓裳羽衣；霓裳舞鞋；霓裳剑 | M12: equip_nichangyuyi；equip_nichangwuxie；equip_nichangjian | N12: data/item_templates.yaml:L3954
A13: huxian_set | B13: 狐仙套装 | C13: 3 | D13: 0 | E13: 0 | F13: 280 | G13: 0 | H13: 64 | I13: 0 | J13: 18 | K13: 0 | L13: 狐仙袍；狐仙鞋；狐仙剑 | M13: equip_huxianpao；equip_huxianxie；equip_huxianjian | N13: data/item_templates.yaml:L4104

Sheet 护院兵种加成
A1: 装备key | B1: 装备名称 | C1: 兵种代码 | D1: 兵种 | E1: 攻击固定值 | F1: 攻击比例 | G1: 防御固定值 | H1: 防御比例 | I1: 生命固定值 | J1: 生命比例 | K1: 数据来源
A2: equip_tongchanjiguan | B2: 铜蝉机关 | C2: dao | D2: 刀系 | E2: 0 | F2: 0.005 | G2: 0 | H2: 0 | I2: 0 | J2: 0 | K2: data/item_templates.yaml:L6575
A3: equip_tongchanjiguan | B3: 铜蝉机关 | C3: qiang | D3: 枪系 | E3: 0 | F3: 0.005 | G3: 0 | H3: 0 | I3: 0 | J3: 0 | K3: data/item_templates.yaml:L6575
A4: equip_tongchanjiguan | B4: 铜蝉机关 | C4: jian | D4: 剑系 | E4: 0 | F4: 0.005 | G4: 0 | H4: 0 | I4: 0 | J4: 0 | K4: data/item_templates.yaml:L6575
A5: equip_tongchanjiguan | B5: 铜蝉机关 | C5: quan | D5: 拳系 | E5: 0 | F5: 0.005 | G5: 0 | H5: 0 | I5: 0 | J5: 0 | K5: data/item_templates.yaml:L6575
A6: equip_tongchanjiguan | B6: 铜蝉机关 | C6: gong | D6: 弓系 | E6: 0 | F6: 0.005 | G6: 0 | H6: 0 | I6: 0 | J6: 0 | K6: data/item_templates.yaml:L6575
A7: equip_tongchanjiguan | B7: 铜蝉机关 | C7: scout | D7: 探子 | E7: 0 | F7: 0.005 | G7: 0 | H7: 0 | I7: 0 | J7: 0 | K7: data/item_templates.yaml:L6575
A8: equip_xiaoxingjiguanshu | B8: 小型机关鼠 | C8: dao | D8: 刀系 | E8: 0 | F8: 0 | G8: 0 | H8: 0 | I8: 0 | J8: 0.005 | K8: data/item_templates.yaml:L6554
A9: equip_xiaoxingjiguanshu | B9: 小型机关鼠 | C9: qiang | D9: 枪系 | E9: 0 | F9: 0 | G9: 0 | H9: 0 | I9: 0 | J9: 0.005 | K9: data/item_templates.yaml:L6554
A10: equip_xiaoxingjiguanshu | B10: 小型机关鼠 | C10: jian | D10: 剑系 | E10: 0 | F10: 0 | G10: 0 | H10: 0 | I10: 0 | J10: 0.005 | K10: data/item_templates.yaml:L6554
A11: equip_xiaoxingjiguanshu | B11: 小型机关鼠 | C11: quan | D11: 拳系 | E11: 0 | F11: 0 | G11: 0 | H11: 0 | I11: 0 | J11: 0.005 | K11: data/item_templates.yaml:L6554
A12: equip_xiaoxingjiguanshu | B12: 小型机关鼠 | C12: gong | D12: 弓系 | E12: 0 | F12: 0 | G12: 0 | H12: 0 | I12: 0 | J12: 0.005 | K12: data/item_templates.yaml:L6554
A13: equip_xiaoxingjiguanshu | B13: 小型机关鼠 | C13: scout | D13: 探子 | E13: 0 | F13: 0 | G13: 0 | H13: 0 | I13: 0 | J13: 0.005 | K13: data/item_templates.yaml:L6554
... A48: equip_mojiajiguanren | B48: 墨家机关人 | C48: scout | D48: 探子 | E48: 0 | F48: 0.005 | G48: 0 | H48: 0.005 | I48: 0 | J48: 0.005 | K48: data/item_templates.yaml:L6978

Sheet 制作配方
A1: 装备key | B1: 装备名称 | C1: 制作方式 | D1: 类别 | E1: 所需技能等级 | F1: 基准耗时(秒) | G1: 单次产量 | H1: 消耗图纸key(每次1张) | I1: 图纸名称 | J1: 材料消耗(每次) | K1: 材料(JSON) | L1: 数据来源
A2: equip_bumao | B2: 布帽 | C2: 普通锻造 | D2: 头盔 | E2: 1 | F2: 120 | G2: 1 | J2: 铜×5 | K2: {"tong":5} | L2: data/forge_equipment.yaml:equipment.equip_bumao
A3: equip_niupimao | B3: 牛皮帽 | C3: 普通锻造 | D3: 头盔 | E3: 3 | F3: 180 | G3: 1 | J3: 铜×10、锡×5 | K3: {"tong":10,"xi":5} | L3: data/forge_equipment.yaml:equipment.equip_niupimao
A4: equip_baihongkui | B4: 白虹盔 | C4: 普通锻造 | D4: 头盔 | E4: 9 | F4: 360 | G4: 1 | J4: 铁×30 | K4: {"tie":30} | L4: data/forge_equipment.yaml:equipment.equip_baihongkui
A5: equip_tieyekui | B5: 铁叶盔 | C5: 普通锻造 | D5: 头盔 | E5: 5 | F5: 240 | G5: 1 | J5: 铁×10 | K5: {"tie":10} | L5: data/forge_equipment.yaml:equipment.equip_tieyekui
A6: equip_yulindin | B6: 鱼鳞顶 | C6: 普通锻造 | D6: 头盔 | E6: 7 | F6: 300 | G6: 1 | J6: 铁×20 | K6: {"tie":20} | L6: data/forge_equipment.yaml:equipment.equip_yulindin
A7: equip_qinglongkui | B7: 青龙盔 | C7: 图纸合成 | D7: 头盔 | E7: 5 | F7: 即时合成 | G7: 1 | H7: blueprint_qinglongkui | I7: 青龙盔图纸 | J7: 铜×29、锡×17、铁×12、木质精华×3、铜质精华×2、紫檀木×5、黑原石×4、金刚煤×3、刨子×3、凿子×3、空气之石×2 | K7: {"tong":29,"xi":17,"tie":12,"wood_essence":3,"copper_essence":2,"zitanmu":5,"heiyuanshi":4,"jingangmei":3,"paozi":3,"zaozi":3,"air_stone":2} | L7: data/forge_blueprints.yaml:blueprint_key=blueprint_qinglongkui
A8: equip_xiaoweitoukui | B8: 校尉头盔 | C8: 图纸合成 | D8: 头盔 | E8: 5 | F8: 即时合成 | G8: 1 | H8: blueprint_xiaoweitoukie | I8: 校尉头盔图纸 | J8: 铜×27、锡×17、铁×12、木质精华×2、铜质精华×2、铁木×4、黑原石×5、金刚煤×4、凿子×4、大地之石×2 | K8: {"tong":27,"xi":17,"tie":12,"wood_essence":2,"copper_essence":2,"tiemu":4,"heiyuanshi":5,"jingangmei":4,"zaozi":4,"earth_stone":2} | L8: data/forge_blueprints.yaml:blueprint_key=blueprint_xiaoweitoukie
A9: equip_fenglingguan | B9: 凤翎冠 | C9: 图纸合成 | D9: 头盔 | E9: 7 | F9: 即时合成 | G9: 1 | H9: blueprint_fenglingguan | I9: 凤翎冠图纸 | J9: 铜×36、锡×22、铁×17、木质精华×3、铜质精华×4、紫檀木×9、水曲木×6、铁木×3、金刚煤×3、刨子×6、凿子×3、高炉×1、空气之石×3 | K9: {"tong":36,"xi":22,"tie":17,"wood_essence":3,"copper_essence":4,"zitanmu":9,"shuiqumu":6,"tiemu":3,"jingangmei":3,"paozi":6,"zaozi":3,"gaolu":1,"air_stone":3} | L9: data/forge_blueprints.yaml:blueprint_key=blueprint_fenglingguan
A10: equip_qilinkui | B10: 麒麟盔 | C10: 图纸合成 | D10: 头盔 | E10: 9 | F10: 即时合成 | G10: 1 | H10: blueprint_qilinkui | I10: 麒麟盔图纸 | J10: 铜×46、锡×29、铁×22、玄铁精华×2、紫檀木×4、铁木×8、黑原石×9、金刚煤×6、凿子×6、高炉×2、火焰之石×3 | K10: {"tong":46,"xi":29,"tie":22,"xuan_tie_essence":2,"zitanmu":4,"tiemu":8,"heiyuanshi":9,"jingangmei":6,"zaozi":6,"gaolu":2,"fire_stone":3} | L10: data/forge_blueprints.yaml:blueprint_key=blueprint_qilinkui
A11: equip_xuanwukui | B11: 玄武盔 | C11: 图纸合成 | D11: 头盔 | E11: 9 | F11: 即时合成 | G11: 1 | H11: blueprint_xuanwukui | I11: 玄武盔图纸 | J11: 铜×48、锡×32、铁×24、玄铁精华×2、铁木×9、黑原石×11、金刚煤×6、凿子×8、高炉×2、纯水之石×3 | K11: {"tong":48,"xi":32,"tie":24,"xuan_tie_essence":2,"tiemu":9,"heiyuanshi":11,"jingangmei":6,"zaozi":8,"gaolu":2,"water_stone":3} | L11: data/forge_blueprints.yaml:blueprint_key=blueprint_xuanwukui
A12: equip_bupao | B12: 布袍 | C12: 普通锻造 | D12: 护甲 | E12: 1 | F12: 120 | G12: 1 | J12: 铜×5 | K12: {"tong":5} | L12: data/forge_equipment.yaml:equipment.equip_bupao
A13: equip_shengpijia | B13: 生皮甲 | C13: 普通锻造 | D13: 护甲 | E13: 3 | F13: 180 | G13: 1 | J13: 铜×10、锡×5 | K13: {"tong":10,"xi":5} | L13: data/forge_equipment.yaml:equipment.equip_shengpijia
A14: equip_housipao | B14: 厚丝袍 | C14: 普通锻造 | D14: 护甲 | E14: 5 | F14: 240 | G14: 1 | J14: 铁×10 | K14: {"tie":10} | L14: data/forge_equipment.yaml:equipment.equip_housipao
A15: equip_shapijia | B15: 鲨皮甲 | C15: 普通锻造 | D15: 护甲 | E15: 7 | F15: 300 | G15: 1 | J15: 铁×20 | K15: {"tie":20} | L15: data/forge_equipment.yaml:equipment.equip_shapijia
A16: equip_qinglongjia | B16: 青龙甲 | C16: 图纸合成 | D16: 护甲 | E16: 5 | F16: 即时合成 | G16: 1 | H16: blueprint_qinglongjia | I16: 青龙甲图纸 | J16: 铜×36、锡×22、铁×17、木质精华×3、铜质精华×3、紫檀木×4、铁木×6、黑原石×6、金刚煤×4、凿子×5、纯水之石×2、大地之石×2 | K16: {"tong":36,"xi":22,"tie":17,"wood_essence":3,"copper_essence":3,"zitanmu":4,"tiemu":6,"heiyuanshi":6,"jingangmei":4,"zaozi":5,"water_stone":2,"earth_stone":2} | L16: data/forge_blueprints.yaml:blueprint_key=blueprint_qinglongjia
A17: equip_xiaoweikaijia | B17: 校尉铠甲 | C17: 图纸合成 | D17: 护甲 | E17: 5 | F17: 即时合成 | G17: 1 | H17: blueprint_xiaoweikaijia | I17: 校尉铠甲图纸 | J17: 铜×36、锡×22、铁×17、木质精华×2、铜质精华×3、铁木×6、黑原石×9、金刚煤×6、凿子×6、大地之石×3 | K17: {"tong":36,"xi":22,"tie":17,"wood_essence":2,"copper_essence":3,"tiemu":6,"heiyuanshi":9,"jingangmei":6,"zaozi":6,"earth_stone":3} | L17: data/forge_blueprints.yaml:blueprint_key=blueprint_xiaoweikaijia
A18: equip_huxianpao | B18: 狐仙袍 | C18: 图纸合成 | D18: 护甲 | E18: 7 | F18: 即时合成 | G18: 1 | H18: blueprint_huxianpao | I18: 狐仙袍图纸 | J18: 铜×41、锡×27、铁×20、木质精华×4、铜质精华×3、玄铁精华×2、紫檀木×11、水曲木×12、铁木×4、金刚煤×4、刨子×8、凿子×3、高炉×2、纯水之石×3 | K18: {"tong":41,"xi":27,"tie":20,"wood_essence":4,"copper_essence":3,"xuan_tie_essence":2,"zitanmu":11,"shuiqumu":12,"tiemu":4,"jingangmei":4,"paozi":8,"zaozi":3,"gaolu":2,"water_stone":3} | L18: data/forge_blueprints.yaml:blueprint_key=blueprint_huxianpao
A19: equip_qilinjia | B19: 麒麟甲 | C19: 图纸合成 | D19: 护甲 | E19: 9 | F19: 即时合成 | G19: 1 | H19: blueprint_qilinjia | I19: 麒麟甲图纸 | J19: 铜×56、锡×36、铁×29、玄铁精华×3、铁木×12、黑原石×15、金刚煤×10、刨子×3、凿子×10、高炉×3、火焰之石×3、大地之石×3 | K19: {"tong":56,"xi":36,"tie":29,"xuan_tie_essence":3,"tiemu":12,"heiyuanshi":15,"jingangmei":10,"paozi":3,"zaozi":10,"gaolu":3,"fire_stone":3,"earth_stone":3} | L19: data/forge_blueprints.yaml:blueprint_key=blueprint_qilinjia
A20: equip_xuanwujia | B20: 玄武甲 | C20: 图纸合成 | D20: 护甲 | E20: 9 | F20: 即时合成 | G20: 1 | H20: blueprint_xuanwujia | I20: 玄武甲图纸 | J20: 铜×58、锡×39、铁×32、玄铁精华×3、铁木×15、黑原石×17、金刚煤×11、刨子×3、凿子×11、高炉×3、纯水之石×3、大地之石×3 | K20: {"tong":58,"xi":39,"tie":32,"xuan_tie_essence":3,"tiemu":15,"heiyuanshi":17,"jingangmei":11,"paozi":3,"zaozi":11,"gaolu":3,"water_stone":3,"earth_stone":3} | L20: data/forge_blueprints.yaml:blueprint_key=blueprint_xuanwujia
A21: equip_buxie | B21: 布鞋 | C21: 普通锻造 | D21: 鞋子 | E21: 1 | F21: 120 | G21: 1 | J21: 铜×5 | K21: {"tong":5} | L21: data/forge_equipment.yaml:equipment.equip_buxie
A22: equip_yangpixue | B22: 羊皮靴 | C22: 普通锻造 | D22: 鞋子 | E22: 3 | F22: 180 | G22: 1 | J22: 铜×10、锡×5 | K22: {"tong":10,"xi":5} | L22: data/forge_equipment.yaml:equipment.equip_yangpixue
A23: equip_gangpianxue | B23: 钢片靴 | C23: 普通锻造 | D23: 鞋子 | E23: 5 | F23: 240 | G23: 1 | J23: 铁×10 | K23: {"tie":10} | L23: data/forge_equipment.yaml:equipment.equip_gangpianxue
A24: equip_yanyuxue | B24: 燕羽靴 | C24: 普通锻造 | D24: 鞋子 | E24: 7 | F24: 300 | G24: 1 | J24: 铁×20 | K24: {"tie":20} | L24: data/forge_equipment.yaml:equipment.equip_yanyuxue
A25: equip_qinglongxue | B25: 青龙靴 | C25: 图纸合成 | D25: 鞋子 | E25: 5 | F25: 即时合成 | G25: 1 | H25: blueprint_qinglongxue | I25: 青龙靴图纸 | J25: 铜×22、锡×12、铁×10、木质精华×3、铜质精华×2、紫檀木×4、水曲木×9、刨子×5、空气之石×2 | K25: {"tong":22,"xi":12,"tie":10,"wood_essence":3,"copper_essence":2,"zitanmu":4,"shuiqumu":9,"paozi":5,"air_stone":2} | L25: data/forge_blueprints.yaml:blueprint_key=blueprint_qinglongxue
A26: equip_xiaoweichangxue | B26: 校尉长靴 | C26: 图纸合成 | D26: 鞋子 | E26: 5 | F26: 即时合成 | G26: 1 | H26: blueprint_xiaoweichangxue | I26: 校尉长靴图纸 | J26: 铜×22、锡×12、铁×10、木质精华×2、铜质精华×2、水曲木×8、铁木×4、刨子×5、空气之石×2 | K26: {"tong":22,"xi":12,"tie":10,"wood_essence":2,"copper_essence":2,"shuiqumu":8,"tiemu":4,"paozi":5,"air_stone":2} | L26: data/forge_blueprints.yaml:blueprint_key=blueprint_xiaoweichangxue
A27: equip_huxianxie | B27: 狐仙鞋 | C27: 图纸合成 | D27: 鞋子 | E27: 7 | F27: 即时合成 | G27: 1 | H27: blueprint_huxianxie | I27: 狐仙鞋图纸 | J27: 铜×32、锡×20、铁×15、木质精华×3、铜质精华×3、玄铁精华×2、紫檀木×6、水曲木×12、铁木×3、金刚煤×2、刨子×8、凿子×2、高炉×1、空气之石×3 | K27: {"tong":32,"xi":20,"tie":15,"wood_essence":3,"copper_essence":3,"xuan_tie_essence":2,"zitanmu":6,"shuiqumu":12,"tiemu":3,"jingangmei":2,"paozi":8,"zaozi":2,"gaolu":1,"air_stone":3} | L27: data/forge_blueprints.yaml:blueprint_key=blueprint_huxianxie
A28: equip_qilinxue | B28: 麒麟靴 | C28: 图纸合成 | D28: 鞋子 | E28: 9 | F28: 即时合成 | G28: 1 | H28: blueprint_qilinxue | I28: 麒麟靴图纸 | J28: 铜×36、锡×22、铁×17、玄铁精华×2、水曲木×10、铁木×6、金刚煤×4、刨子×6、凿子×3、高炉×1、火焰之石×2、空气之石×2 | K28: {"tong":36,"xi":22,"tie":17,"xuan_tie_essence":2,"shuiqumu":10,"tiemu":6,"jingangmei":4,"paozi":6,"zaozi":3,"gaolu":1,"fire_stone":2,"air_stone":2} | L28: data/forge_blueprints.yaml:blueprint_key=blueprint_qilinxue
A29: equip_xuanwuxue | B29: 玄武靴 | C29: 图纸合成 | D29: 鞋子 | E29: 9 | F29: 即时合成 | G29: 1 | H29: blueprint_xuanwuxue | I29: 玄武靴图纸 | J29: 铜×39、锡×24、铁×20、玄铁精华×2、水曲木×8、铁木×9、黑原石×5、金刚煤×4、刨子×5、凿子×4、高炉×1、大地之石×3 | K29: {"tong":39,"xi":24,"tie":20,"xuan_tie_essence":2,"shuiqumu":8,"tiemu":9,"heiyuanshi":5,"jingangmei":4,"paozi":5,"zaozi":4,"gaolu":1,"earth_stone":3} | L29: data/forge_blueprints.yaml:blueprint_key=blueprint_xuanwuxue
A30: equip_dakandao | B30: 大砍刀 | C30: 普通锻造 | D30: 刀 | E30: 3 | F30: 180 | G30: 1 | J30: 铜×10、锡×5 | K30: {"tong":10,"xi":5} | L30: data/forge_equipment.yaml:equipment.equip_dakandao
A31: equip_duandao | B31: 短刀 | C31: 普通锻造 | D31: 刀 | E31: 1 | F31: 120 | G31: 1 | J31: 铜×5 | K31: {"tong":5} | L31: data/forge_equipment.yaml:equipment.equip_duandao
A32: equip_changjian | B32: 长剑 | C32: 普通锻造 | D32: 剑 | E32: 3 | F32: 180 | G32: 1 | J32: 铜×10、锡×5 | K32: {"tong":10,"xi":5} | L32: data/forge_equipment.yaml:equipment.equip_changjian
A33: equip_duanjian | B33: 短剑 | C33: 普通锻造 | D33: 剑 | E33: 1 | F33: 120 | G33: 1 | J33: 铜×5 | K33: {"tong":5} | L33: data/forge_equipment.yaml:equipment.equip_duanjian
A34: equip_changgong | B34: 长弓 | C34: 普通锻造 | D34: 弓 | E34: 1 | F34: 120 | G34: 1 | J34: 铜×5 | K34: {"tong":5} | L34: data/forge_equipment.yaml:equipment.equip_changgong
A35: equip_fanqugong | B35: 反曲弓 | C35: 普通锻造 | D35: 弓 | E35: 3 | F35: 180 | G35: 1 | J35: 铜×10、锡×5 | K35: {"tong":10,"xi":5} | L35: data/forge_equipment.yaml:equipment.equip_fanqugong
A36: equip_baoweiqiang | B36: 豹尾枪 | C36: 普通锻造 | D36: 枪 | E36: 3 | F36: 180 | G36: 1 | J36: 铜×10、锡×5 | K36: {"tong":10,"xi":5} | L36: data/forge_equipment.yaml:equipment.equip_baoweiqiang
A37: equip_changqiang | B37: 长枪 | C37: 普通锻造 | D37: 枪 | E37: 1 | F37: 120 | G37: 1 | J37: 铜×5 | K37: {"tong":5} | L37: data/forge_equipment.yaml:equipment.equip_changqiang
A38: equip_changbian | B38: 长鞭 | C38: 普通锻造 | D38: 鞭 | E38: 1 | F38: 120 | G38: 1 | J38: 铜×5 | K38: {"tong":5} | L38: data/forge_equipment.yaml:equipment.equip_changbian
A39: equip_niupibian | B39: 牛皮鞭 | C39: 普通锻造 | D39: 鞭 | E39: 3 | F39: 180 | G39: 1 | J39: 铜×10、锡×5 | K39: {"tong":10,"xi":5} | L39: data/forge_equipment.yaml:equipment.equip_niupibian
A40: equip_jingtiedao | B40: 精铁刀 | C40: 普通锻造 | D40: 刀 | E40: 7 | F40: 300 | G40: 1 | J40: 铁×20 | K40: {"tie":20} | L40: data/forge_equipment.yaml:equipment.equip_jingtiedao
...

Sheet 获取途径
A1: 装备key | B1: 装备名称 | C1: 获取方式 | D1: 条件与配置明细 | E1: 数据来源
A2: equip_bumao | B2: 布帽 | C2: 铁匠铺直接锻造 | D2: 锻造技1级；基础时长120秒（实际受时间缩放和建筑速度影响）；每件材料：铜(tong)×5 | E2: data/forge_equipment.yaml
A3: equip_caomao | B3: 斗笠 | C3: 宝箱随机装备 | D3: 持有打工宝箱（小）（work_chest_small）后开启；装备池概率10%；该装备概率0.526316%；数量1；宝箱来源：打工奖励：初级打工完成后领取1个宝箱 | E3: data/item_templates.yaml；gameplay/services/work.py
A4: equip_caomao | B4: 斗笠 | C4: 宝箱随机装备 | D4: 持有打工宝箱（中）（work_chest_medium）后开启；装备池概率10%；该装备概率0.333333%；数量1；宝箱来源：打工奖励：中级打工完成后领取1个宝箱 | E4: data/item_templates.yaml；gameplay/services/work.py
A5: equip_caomao | B5: 斗笠 | C5: 宝箱随机装备 | D5: 持有打工宝箱（大）（work_chest_large）后开启；装备池概率20%；该装备概率0.526316%；数量1；宝箱来源：打工奖励：高级打工完成后领取1个宝箱 | E5: data/item_templates.yaml；gameplay/services/work.py
A6: equip_niupimao | B6: 牛皮帽 | C6: 铁匠铺直接锻造 | D6: 锻造技3级；基础时长180秒（实际受时间缩放和建筑速度影响）；每件材料：铜(tong)×10、锡(xi)×5 | E6: data/forge_equipment.yaml
A7: equip_zhubiankui | B7: 竹编盔 | C7: 宝箱随机装备 | D7: 持有打工宝箱（小）（work_chest_small）后开启；装备池概率10%；该装备概率0.526316%；数量1；宝箱来源：打工奖励：初级打工完成后领取1个宝箱 | E7: data/item_templates.yaml；gameplay/services/work.py
A8: equip_zhubiankui | B8: 竹编盔 | C8: 宝箱随机装备 | D8: 持有打工宝箱（中）（work_chest_medium）后开启；装备池概率10%；该装备概率0.333333%；数量1；宝箱来源：打工奖励：中级打工完成后领取1个宝箱 | E8: data/item_templates.yaml；gameplay/services/work.py
A9: equip_zhubiankui | B9: 竹编盔 | C9: 宝箱随机装备 | D9: 持有打工宝箱（大）（work_chest_large）后开启；装备池概率20%；该装备概率0.526316%；数量1；宝箱来源：打工奖励：高级打工完成后领取1个宝箱 | E9: data/item_templates.yaml；gameplay/services/work.py
A10: equip_baihongkui | B10: 白虹盔 | C10: 商铺购买 | D10: 购买价22500银两/件；库存不限量；每日刷新否 | E10: data/shop_items.yaml
A11: equip_baihongkui | B11: 白虹盔 | C11: 宝箱随机装备 | D11: 持有打工宝箱（大）（work_chest_large）后开启；装备池概率20%；该装备概率0.526316%；数量1；宝箱来源：打工奖励：高级打工完成后领取1个宝箱 | E11: data/item_templates.yaml；gameplay/services/work.py
A12: equip_baihongkui | B12: 白虹盔 | C12: 宝箱随机装备 | D12: 持有帮会精制护院箱（guild_guard_box_refined）后开启；装备池概率100%；该装备概率14%；数量1；宝箱来源：帮会仓库兑换：帮会科技guard；解锁等级7；配置等级7,8,9,10；贡献兑换价[320]；每周个人兑换上限[1]；各科技等级每日产量7级×1,8级×2,9级×1,10级×1 | E12: data/item_templates.yaml；data/warehouse_production.yaml
... A574: equip_tianjiguan | B574: 天机冠 | C574: 任务宝箱装备 | D574: 任务：飞将浮沉录：白门楼命运抉择（baimenlou_mingyun_jueze）；胜利得白门楼宝箱×1，在仓库开启；组概率35.000000%，权重1/2，单项概率17.500000%，数量1—1 | E574: data/item_templates.yaml:mission_chest_v3_baimenlou_mingyun_jueze.effect_payload

Sheet 获取途径待核实
A1: 装备key | B1: 装备名称 | C1: 装备类型 | D1: 稀有度 | E1: 核对结果 | F1: 模板来源
A2: equip_tatianxue | B2: 踏天靴 | C2: 鞋子 | D2: 传说/橙 | E2: 当前主要配置未发现获取途径；不代表数据库或活动中绝对无法获得。 | F2: data/item_templates.yaml:L4714
A3: equip_wujixingxue | B3: 无极行靴 | C3: 鞋子 | D3: 传说/橙 | E3: 当前主要配置未发现获取途径；不代表数据库或活动中绝对无法获得。 | F3: data/item_templates.yaml:L4745
A4: equip_businiaoyu | B4: 不死鸟羽 | C4: 饰品 | D4: 传说/橙 | E4: 当前主要配置未发现获取途径；不代表数据库或活动中绝对无法获得。 | F4: data/item_templates.yaml:L6395
A5: equip_heshibi | B5: 和氏璧 | C5: 饰品 | D5: 传说/橙 | E5: 当前主要配置未发现获取途径；不代表数据库或活动中绝对无法获得。 | F5: data/item_templates.yaml:L6346
A6: equip_qiankunzhu | B6: 乾坤珠 | C6: 饰品 | D6: 传说/橙 | E6: 当前主要配置未发现获取途径；不代表数据库或活动中绝对无法获得。 | F6: data/item_templates.yaml:L6378

Sheet 装备分解
A1: 稀有度代码 | B1: 稀有度 | C1: 奖励类型 | D1: 材料key | E1: 材料名称 | F1: 最少数量 | G1: 最多数量 | H1: 获得概率 | I1: 数据来源
A2: green | B2: 优秀/绿 | C2: 每件必得区间 | D2: tong | E2: 铜 | F2: 2 | G2: 5 | I2: data/forge_decompose.yaml:base_materials.green.tong
A3: green | B3: 优秀/绿 | C3: 每件必得区间 | D3: xi | E3: 锡 | F3: 1 | G3: 3 | I3: data/forge_decompose.yaml:base_materials.green.xi
A4: green | B4: 优秀/绿 | C4: 每件必得区间 | D4: tie | E4: 铁 | F4: 1 | G4: 2 | I4: data/forge_decompose.yaml:base_materials.green.tie
A5: green | B5: 优秀/绿 | C5: 概率奖励 | D5: wood_essence | E5: 木质精华 | H5: 0.75 | I5: data/forge_decompose.yaml:chance_rewards.green.wood_essence
A6: green | B6: 优秀/绿 | C6: 概率奖励 | D6: copper_essence | E6: 铜质精华 | H6: 0.25 | I6: data/forge_decompose.yaml:chance_rewards.green.copper_essence
A7: green | B7: 优秀/绿 | C7: 概率奖励 | D7: shuiqumu | E7: 水曲木 | H7: 0.25 | I7: data/forge_decompose.yaml:chance_rewards.green.shuiqumu
A8: green | B8: 优秀/绿 | C8: 概率奖励 | D8: paozi | E8: 刨子 | H8: 0.12 | I8: data/forge_decompose.yaml:chance_rewards.green.paozi
A9: green | B9: 优秀/绿 | C9: 概率奖励 | D9: zaozi | E9: 凿子 | H9: 0.12 | I9: data/forge_decompose.yaml:chance_rewards.green.zaozi
A10: green | B10: 优秀/绿 | C10: 概率奖励 | D10: tiemu | E10: 铁木 | H10: 0.06 | I10: data/forge_decompose.yaml:chance_rewards.green.tiemu
A11: green | B11: 优秀/绿 | C11: 概率奖励 | D11: zitanmu | E11: 紫檀木 | H11: 0.05 | I11: data/forge_decompose.yaml:chance_rewards.green.zitanmu
A12: green | B12: 优秀/绿 | C12: 概率奖励 | D12: heiyuanshi | E12: 黑原石 | H12: 0.06 | I12: data/forge_decompose.yaml:chance_rewards.green.heiyuanshi
A13: green | B13: 优秀/绿 | C13: 概率奖励 | D13: jingangmei | E13: 金刚煤 | H13: 0.04 | I13: data/forge_decompose.yaml:chance_rewards.green.jingangmei
A14: blue | B14: 稀有/蓝 | C14: 每件必得区间 | D14: tong | E14: 铜 | F14: 4 | G14: 8 | I14: data/forge_decompose.yaml:base_materials.blue.tong
A15: blue | B15: 稀有/蓝 | C15: 每件必得区间 | D15: xi | E15: 锡 | F15: 2 | G15: 5 | I15: data/forge_decompose.yaml:base_materials.blue.xi
A16: blue | B16: 稀有/蓝 | C16: 每件必得区间 | D16: tie | E16: 铁 | F16: 1 | G16: 3 | I16: data/forge_decompose.yaml:base_materials.blue.tie
A17: blue | B17: 稀有/蓝 | C17: 概率奖励 | D17: wood_essence | E17: 木质精华 | H17: 0.8 | I17: data/forge_decompose.yaml:chance_rewards.blue.wood_essence
A18: blue | B18: 稀有/蓝 | C18: 概率奖励 | D18: copper_essence | E18: 铜质精华 | H18: 0.75 | I18: data/forge_decompose.yaml:chance_rewards.blue.copper_essence
A19: blue | B19: 稀有/蓝 | C19: 概率奖励 | D19: iron_essence | E19: 铁质精华 | H19: 0.5 | I19: data/forge_decompose.yaml:chance_rewards.blue.iron_essence
A20: blue | B20: 稀有/蓝 | C20: 概率奖励 | D20: xuan_tie_essence | E20: 玄铁精华 | H20: 0.25 | I20: data/forge_decompose.yaml:chance_rewards.blue.xuan_tie_essence
A21: blue | B21: 稀有/蓝 | C21: 概率奖励 | D21: air_stone | E21: 空气之石 | H21: 0.12 | I21: data/forge_decompose.yaml:chance_rewards.blue.air_stone
A22: blue | B22: 稀有/蓝 | C22: 概率奖励 | D22: fire_stone | E22: 火焰之石 | H22: 0.12 | I22: data/forge_decompose.yaml:chance_rewards.blue.fire_stone
A23: blue | B23: 稀有/蓝 | C23: 概率奖励 | D23: earth_stone | E23: 大地之石 | H23: 0.12 | I23: data/forge_decompose.yaml:chance_rewards.blue.earth_stone
A24: blue | B24: 稀有/蓝 | C24: 概率奖励 | D24: water_stone | E24: 纯水之石 | H24: 0.12 | I24: data/forge_decompose.yaml:chance_rewards.blue.water_stone
A25: blue | B25: 稀有/蓝 | C25: 概率奖励 | D25: shuiqumu | E25: 水曲木 | H25: 0.35 | I25: data/forge_decompose.yaml:chance_rewards.blue.shuiqumu
A26: blue | B26: 稀有/蓝 | C26: 概率奖励 | D26: paozi | E26: 刨子 | H26: 0.2 | I26: data/forge_decompose.yaml:chance_rewards.blue.paozi
A27: blue | B27: 稀有/蓝 | C27: 概率奖励 | D27: zaozi | E27: 凿子 | H27: 0.2 | I27: data/forge_decompose.yaml:chance_rewards.blue.zaozi
A28: blue | B28: 稀有/蓝 | C28: 概率奖励 | D28: tiemu | E28: 铁木 | H28: 0.14 | I28: data/forge_decompose.yaml:chance_rewards.blue.tiemu
... A32: blue | B32: 稀有/蓝 | C32: 概率奖励 | D32: gaolu | E32: 高炉 | H32: 0.05 | I32: data/forge_decompose.yaml:chance_rewards.blue.gaolu
A33: purple | B33: 史诗/紫 | C33: 每件必得区间 | D33: tong | E33: 铜 | F33: 6 | G33: 12 | I33: data/forge_decompose.yaml:base_materials.purple.tong
A34: purple | B34: 史诗/紫 | C34: 每件必得区间 | D34: xi | E34: 锡 | F34: 4 | G34: 8 | I34: data/forge_decompose.yaml:base_materials.purple.xi
A35: purple | B35: 史诗/紫 | C35: 每件必得区间 | D35: tie | E35: 铁 | F35: 2 | G35: 5 | I35: data/forge_decompose.yaml:base_materials.purple.tie
A36: purple | B36: 史诗/紫 | C36: 概率奖励 | D36: wood_essence | E36: 木质精华 | H36: 0.88 | I36: data/forge_decompose.yaml:chance_rewards.purple.wood_essence
A37: purple | B37: 史诗/紫 | C37: 概率奖励 | D37: copper_essence | E37: 铜质精华 | H37: 0.88 | I37: data/forge_decompose.yaml:chance_rewards.purple.copper_essence
A38: purple | B38: 史诗/紫 | C38: 概率奖励 | D38: xuan_tie_essence | E38: 玄铁精华 | H38: 0.4 | I38: data/forge_decompose.yaml:chance_rewards.purple.xuan_tie_essence
A39: purple | B39: 史诗/紫 | C39: 概率奖励 | D39: air_stone | E39: 空气之石 | H39: 0.22 | I39: data/forge_decompose.yaml:chance_rewards.purple.air_stone
A40: purple | B40: 史诗/紫 | C40: 概率奖励 | D40: fire_stone | E40: 火焰之石 | H40: 0.22 | I40: data/forge_decompose.yaml:chance_rewards.purple.fire_stone
A41: purple | B41: 史诗/紫 | C41: 概率奖励 | D41: earth_stone | E41: 大地之石 | H41: 0.22 | I41: data/forge_decompose.yaml:chance_rewards.purple.earth_stone
A42: purple | B42: 史诗/紫 | C42: 概率奖励 | D42: water_stone | E42: 纯水之石 | H42: 0.22 | I42: data/forge_decompose.yaml:chance_rewards.purple.water_stone
A43: purple | B43: 史诗/紫 | C43: 概率奖励 | D43: shuiqumu | E43: 水曲木 | H43: 0.5 | I43: data/forge_decompose.yaml:chance_rewards.purple.shuiqumu
...

Sheet 分类汇总
A1: 装备类型 | B1: 稀有度 | C1: 装备数量 | D1: 稀有度代码
A2: 头盔 | B2: 普通/白 | C2: =COUNTIFS(装备总表!$R$2:$R$266,A2,装备总表!$P$2:$P$266,D2) -> 4 | D2: black
A3: 头盔 | B3: 优秀/绿 | C3: =COUNTIFS(装备总表!$R$2:$R$266,A3,装备总表!$P$2:$P$266,D3) -> 8 | D3: green
A4: 头盔 | B4: 稀有/蓝 | C4: =COUNTIFS(装备总表!$R$2:$R$266,A4,装备总表!$P$2:$P$266,D4) -> 9 | D4: blue
A5: 头盔 | B5: 史诗/紫 | C5: =COUNTIFS(装备总表!$R$2:$R$266,A5,装备总表!$P$2:$P$266,D5) -> 6 | D5: purple
A6: 头盔 | B6: 传说/橙 | C6: =COUNTIFS(装备总表!$R$2:$R$266,A6,装备总表!$P$2:$P$266,D6) -> 3 | D6: orange
A7: 护甲 | B7: 普通/白 | C7: =COUNTIFS(装备总表!$R$2:$R$266,A7,装备总表!$P$2:$P$266,D7) -> 4 | D7: black
A8: 护甲 | B8: 优秀/绿 | C8: =COUNTIFS(装备总表!$R$2:$R$266,A8,装备总表!$P$2:$P$266,D8) -> 8 | D8: green
A9: 护甲 | B9: 稀有/蓝 | C9: =COUNTIFS(装备总表!$R$2:$R$266,A9,装备总表!$P$2:$P$266,D9) -> 8 | D9: blue
A10: 护甲 | B10: 史诗/紫 | C10: =COUNTIFS(装备总表!$R$2:$R$266,A10,装备总表!$P$2:$P$266,D10) -> 6 | D10: purple
A11: 护甲 | B11: 传说/橙 | C11: =COUNTIFS(装备总表!$R$2:$R$266,A11,装备总表!$P$2:$P$266,D11) -> 4 | D11: orange
A12: 鞋子 | B12: 普通/白 | C12: =COUNTIFS(装备总表!$R$2:$R$266,A12,装备总表!$P$2:$P$266,D12) -> 4 | D12: black
A13: 鞋子 | B13: 优秀/绿 | C13: =COUNTIFS(装备总表!$R$2:$R$266,A13,装备总表!$P$2:$P$266,D13) -> 8 | D13: green
... A36: 器械 | B36: 传说/橙 | C36: =COUNTIFS(装备总表!$R$2:$R$266,A36,装备总表!$P$2:$P$266,D36) -> 3 | D36: orange
A37: 全部装备 | C37: =COUNTA(装备总表!B2:B266) -> 265

Sheet 更新说明
A1: 项目 | B1: 说明
A2: 更新时间 | B2: 2026-10-01
A3: 数据范围 | B3: 当前工作区 data/item_templates.yaml 中 effect_type 以 equip_ 开头的全部装备模板；未查询运行中数据库。
A4: 装备数量 | B4: =COUNTA(装备总表!B2:B266) -> 265
A5: 更新结果 | B5: 旧表262件，新增3件；211件原有装备的价格、占用空间或基础属性已更新。
A6: 新增装备 | B6: 青铜之角斗士；白银之角斗士；黄金之角斗士
A7: 合计公式 | B7: 生命/54+防御+武力+智力+敏捷+运势×1.2+带兵上限/2；沿用旧表及平衡测试口径，不包含套装与护院加成。
A8: 模板价格 | B8: price 是模板字段。实际商店购买价格请查获取途径页；未配置 price 时按导入默认值0展示。
A9: 默认值 | B9: 与 load_item_templates._build_item_defaults 一致：price=0、storage_space=1、tradeable=False、is_usable=False；未出现的基础属性按0显示。
A10: 制作配方 | B10: 普通锻造、图纸合成、马厩养马分行列出；技能分别指锻造技或马术；图纸合成每次额外消耗1张图纸；耗时是配置基准，运行时受科技等影响。
A11: 套装效果 | B11: 各档套装效果是独立门槛，达到多个门槛时累加；仅有 set_key 的装备计入同套装。
A12: 护院加成 | B12: 器械的 troop_stat_bonus 加成对应护院兵种，不计入门客基础属性与原表合计。比例以Excel百分比展示。
A13: 装备分解 | B13: 按稀有度的当前配置展示基础材料区间及概率奖励；白色装备不在 supported_rarities 中。
A14: 获取途径范围 | B14: 根据当前配置及对应服务规则整理；列出掉落概率或随机权重时保留其配置语义，不将权重等同概率；获取条件详见明细。交易行还依赖玩家挂单。
A15: 途径待核实 | B15: 5件；个人任务途径已同步为宝箱与图纸合成。
A16: 细分类型 | B16: 沿用旧表细分类型；普通锻造装备使用当前配方类别。item_templates 未定义统一武器细分字段。
A17: 来源追溯 | B17: 总表保留原始effect_payload及YAML行号；各明细页标注来源配置键。
