Workbook

Sheet 装备总表
A1: 序号 | B1: 装备key | C1: 装备名称 | D1: 部位代码 | E1: 部位 | F1: effect_type | G1: 稀有度代码 | H1: 稀有度 | I1: 套装key | J1: 套装描述 | K1: 装备描述 | L1: 价格 | M1: 占用空间 | N1: 可交易 | O1: 生命 | P1: 防御 | Q1: 武力 | R1: 智力 | S1: 敏捷 | T1: 运势 | U1: 带兵上限 | V1: 属性总和 | W1: 基础强度评分 | X1: 动态候选Power | Y1: 可锻造 | Z1: 锻造类别 | AA1: 所需锻造等级 | AB1: 锻造基准耗时(秒) | AC1: 锻造材料(JSON) | AD1: 套装效果(JSON) | AE1: 原始effect_payload(JSON) | AF1: 数据来源
A2: 1 | B2: equip_action_mask | C2: 动感超人面具 | D2: helmet | E2: 头盔 | F2: equip_helmet | G2: blue | H2: 稀有/蓝 | I2: kasukabe_defense_set | J2: 春日部防卫队 | K2: 春日部防卫队收藏的英雄面具，戴上后总觉得出拳更有气势。 | L2: 6000 | M2: 100 | N2: 是 | O2: 300 | P2: 5 | Q2: 20 | R2: 0 | S2: 15 | T2: 0 | U2: 0 | V2: =SUM(O2:U2) | W2: =O2*'强度系数说明'!$B$7+P2*'强度系数说明'!$B$8+Q2*'强度系数说明'!$B$9+R2*'强度系数说明'!$B$10+S2*'强度系数说明'!$B$11+T2*'强度系数说明'!$B$12+U2*'强度系数说明'!$B$13 | X2: =SUMPRODUCT((O2:U2>0)*O2:U2) | Y2: 否 | AD2: [{"bonus":{"attack":30,"defense":20},"pieces":2},{"bonus":{"agility":20,"hp":600,"luck":15},"pieces":4}] | AE2: {"agility":15,"defense":5,"force":20,"hp":300,"set_bonus":[{"bonus":{"attack":30,"defense":20},"pieces":2},{"bonus":{"agility":20,"hp":600,"luck":15},"pieces":4}],"set_description":"春日部防卫队","set_key":"kasukabe_defense_set"} | AF2: data/item_templates.yaml:L2674
A3: 2 | B3: equip_shiro_leash | C3: 小白的散步绳 | D3: ornament | E3: 饰品 | F3: equip_ornament | G3: blue | H3: 稀有/蓝 | I3: kasukabe_defense_set | J3: 春日部防卫队 | K3: 看似普通的牵绳，却能在混战中稳住阵脚，守住不该乱跑的人。 | L3: 5600 | M3: 100 | N3: 是 | O3: 360 | P3: 15 | Q3: 5 | R3: 0 | S3: 0 | T3: 10 | U3: 0 | V3: =SUM(O3:U3) | W3: =O3*'强度系数说明'!$B$7+P3*'强度系数说明'!$B$8+Q3*'强度系数说明'!$B$9+R3*'强度系数说明'!$B$10+S3*'强度系数说明'!$B$11+T3*'强度系数说明'!$B$12+U3*'强度系数说明'!$B$13 | X3: =SUMPRODUCT((O3:U3>0)*O3:U3) | Y3: 否 | AD3: [{"bonus":{"attack":30,"defense":20},"pieces":2},{"bonus":{"agility":20,"hp":600,"luck":15},"pieces":4}] | AE3: {"defense":15,"force":5,"hp":360,"luck":10,"set_bonus":[{"bonus":{"attack":30,"defense":20},"pieces":2},{"bonus":{"agility":20,"hp":600,"luck":15},"pieces":4}],"set_description":"春日部防卫队","set_key":"kasukabe_defense_set"} | AF3: data/item_templates.yaml:L2700
A4: 3 | B4: equip_kasukabe_satchel | C4: 春日部小书包 | D4: armor | E4: 护甲 | F4: equip_armor | G4: blue | H4: 稀有/蓝 | I4: kasukabe_defense_set | J4: 春日部防卫队 | K4: 塞满点心、画纸和奇怪作战计划的小书包，防护意外地可靠。 | L4: 6200 | M4: 100 | N4: 是 | O4: 420 | P4: 20 | Q4: 0 | R4: 0 | S4: 10 | T4: 10 | U4: 0 | V4: =SUM(O4:U4) | W4: =O4*'强度系数说明'!$B$7+P4*'强度系数说明'!$B$8+Q4*'强度系数说明'!$B$9+R4*'强度系数说明'!$B$10+S4*'强度系数说明'!$B$11+T4*'强度系数说明'!$B$12+U4*'强度系数说明'!$B$13 | X4: =SUMPRODUCT((O4:U4>0)*O4:U4) | Y4: 否 | AD4: [{"bonus":{"attack":30,"defense":20},"pieces":2},{"bonus":{"agility":20,"hp":600,"luck":15},"pieces":4}] | AE4: {"agility":10,"defense":20,"hp":420,"luck":10,"set_bonus":[{"bonus":{"attack":30,"defense":20},"pieces":2},{"bonus":{"agility":20,"hp":600,"luck":15},"pieces":4}],"set_description":"春日部防卫队","set_key":"kasukabe_defense_set"} | AF4: data/item_templates.yaml:L2726
A5: 4 | B5: equip_action_beam_glove | C5: 动感光波手套 | D5: weapon | E5: 武器 | F5: equip_weapon | G5: blue | H5: 稀有/蓝 | I5: kasukabe_defense_set | J5: 春日部防卫队 | K5: 模仿动感超人招式制作的手套，挥动时能带出夸张的战斗节奏。 | L5: 7000 | M5: 100 | N5: 是 | O5: 0 | P5: 0 | Q5: 40 | R5: 0 | S5: 15 | T5: 0 | U5: 0 | V5: =SUM(O5:U5) | W5: =O5*'强度系数说明'!$B$7+P5*'强度系数说明'!$B$8+Q5*'强度系数说明'!$B$9+R5*'强度系数说明'!$B$10+S5*'强度系数说明'!$B$11+T5*'强度系数说明'!$B$12+U5*'强度系数说明'!$B$13 | X5: =SUMPRODUCT((O5:U5>0)*O5:U5) | Y5: 否 | AD5: [{"bonus":{"attack":30,"defense":20},"pieces":2},{"bonus":{"agility":20,"hp":600,"luck":15},"pieces":4}] | AE5: {"agility":15,"force":40,"set_bonus":[{"bonus":{"attack":30,"defense":20},"pieces":2},{"bonus":{"agility":20,"hp":600,"luck":15},"pieces":4}],"set_description":"春日部防卫队","set_key":"kasukabe_defense_set"} | AF5: data/item_templates.yaml:L2752
A6: 5 | B6: equip_nohara_pan | C6: 野原家的平底锅 | D6: weapon | E6: 武器 | F6: equip_weapon | G6: blue | H6: 稀有/蓝 | I6: kasukabe_defense_set | J6: 春日部防卫队 | K6: 厨房里磨炼出的实战兵器，攻守兼备，敲起来声势惊人。 | L6: 6800 | M6: 100 | N6: 是 | O6: 180 | P6: 18 | Q6: 36 | R6: 0 | S6: 0 | T6: 0 | U6: 0 | V6: =SUM(O6:U6) | W6: =O6*'强度系数说明'!$B$7+P6*'强度系数说明'!$B$8+Q6*'强度系数说明'!$B$9+R6*'强度系数说明'!$B$10+S6*'强度系数说明'!$B$11+T6*'强度系数说明'!$B$12+U6*'强度系数说明'!$B$13 | X6: =SUMPRODUCT((O6:U6>0)*O6:U6) | Y6: 否 | AD6: [{"bonus":{"attack":30,"defense":20},"pieces":2},{"bonus":{"agility":20,"hp":600,"luck":15},"pieces":4}] | AE6: {"defense":18,"force":36,"hp":180,"set_bonus":[{"bonus":{"attack":30,"defense":20},"pieces":2},{"bonus":{"agility":20,"hp":600,"luck":15},"pieces":4}],"set_description":"春日部防卫队","set_key":"kasukabe_defense_set"} | AF6: data/item_templates.yaml:L2776
A7: 6 | B7: equip_caomao | C7: 斗笠 | D7: helmet | E7: 头盔 | F7: equip_helmet | G7: black | H7: 普通/白 | I7: starter_cloth_set | J7: 一蓑烟雨 | K7: 由棕叶编织而成的宽边帽，可以简单遮蔽风雨。 | L7: 0 | M7: 50 | N7: 否 | O7: 250 | P7: 10 | Q7: 5 | R7: 0 | S7: 0 | T7: 0 | U7: 0 | V7: =SUM(O7:U7) | W7: =O7*'强度系数说明'!$B$7+P7*'强度系数说明'!$B$8+Q7*'强度系数说明'!$B$9+R7*'强度系数说明'!$B$10+S7*'强度系数说明'!$B$11+T7*'强度系数说明'!$B$12+U7*'强度系数说明'!$B$13 | X7: =SUMPRODUCT((O7:U7>0)*O7:U7) | Y7: 否 | AD7: {"bonus":{"force":20,"hp":200,"luck":15,"troop_capacity":20},"pieces":4} | AE7: {"defense":10,"force":5,"hp":250,"set_bonus":{"bonus":{"force":20,"hp":200,"luck":15,"troop_capacity":20},"pieces":4},"set_description":"一蓑烟雨","set_key":"starter_cloth_set"} | AF7: data/item_templates.yaml:L2801
A8: 7 | B8: equip_suoyi | C8: 蓑衣 | D8: armor | E8: 护甲 | F8: equip_armor | G8: black | H8: 普通/白 | I8: starter_cloth_set | J8: 一蓑烟雨 | K8: 以莎草编织而成，劳动人民遮风避雨的必需品。 | L8: 0 | M8: 50 | N8: 否 | O8: 100 | P8: 10 | Q8: 5 | R8: 0 | S8: 5 | T8: 0 | U8: 0 | V8: =SUM(O8:U8) | W8: =O8*'强度系数说明'!$B$7+P8*'强度系数说明'!$B$8+Q8*'强度系数说明'!$B$9+R8*'强度系数说明'!$B$10+S8*'强度系数说明'!$B$11+T8*'强度系数说明'!$B$12+U8*'强度系数说明'!$B$13 | X8: =SUMPRODUCT((O8:U8>0)*O8:U8) | Y8: 否 | AD8: {"bonus":{"force":20,"hp":200,"luck":15,"troop_capacity":20},"pieces":4} | AE8: {"agility":5,"defense":10,"force":5,"hp":100,"set_bonus":{"bonus":{"force":20,"hp":200,"luck":15,"troop_capacity":20},"pieces":4},"set_description":"一蓑烟雨","set_key":"starter_cloth_set"} | AF8: data/item_templates.yaml:L2824
A9: 8 | B9: equip_caoxie | C9: 草鞋 | D9: shoes | E9: 鞋履 | F9: equip_shoes | G9: black | H9: 普通/白 | I9: starter_cloth_set | J9: 一蓑烟雨 | K9: 由稻草编织而成的鞋子，透水但也透气。 | L9: 0 | M9: 50 | N9: 否 | O9: 200 | P9: 5 | Q9: 0 | R9: 0 | S9: 10 | T9: 0 | U9: 0 | V9: =SUM(O9:U9) | W9: =O9*'强度系数说明'!$B$7+P9*'强度系数说明'!$B$8+Q9*'强度系数说明'!$B$9+R9*'强度系数说明'!$B$10+S9*'强度系数说明'!$B$11+T9*'强度系数说明'!$B$12+U9*'强度系数说明'!$B$13 | X9: =SUMPRODUCT((O9:U9>0)*O9:U9) | Y9: 否 | AD9: {"bonus":{"force":20,"hp":200,"luck":15,"troop_capacity":20},"pieces":4} | AE9: {"agility":10,"defense":5,"hp":200,"set_bonus":{"bonus":{"force":20,"hp":200,"luck":15,"troop_capacity":20},"pieces":4},"set_description":"一蓑烟雨","set_key":"starter_cloth_set"} | AF9: data/item_templates.yaml:L2848
A10: 9 | B10: equip_tiejian | C10: 铁剑 | D10: weapon | E10: 武器 | F10: equip_weapon | G10: black | H10: 普通/白 | I10: starter_cloth_set | J10: 一蓑烟雨 | K10: 一柄简朴耐用的铁剑，适合初入江湖之人防身。 | L10: 0 | M10: 50 | N10: 否 | O10: 0 | P10: 5 | Q10: 15 | R10: 0 | S10: 0 | T10: 0 | U10: 0 | V10: =SUM(O10:U10) | W10: =O10*'强度系数说明'!$B$7+P10*'强度系数说明'!$B$8+Q10*'强度系数说明'!$B$9+R10*'强度系数说明'!$B$10+S10*'强度系数说明'!$B$11+T10*'强度系数说明'!$B$12+U10*'强度系数说明'!$B$13 | X10: =SUMPRODUCT((O10:U10>0)*O10:U10) | Y10: 否 | AD10: {"bonus":{"force":20,"hp":200,"luck":15,"troop_capacity":20},"pieces":4} | AE10: {"defense":5,"force":15,"set_bonus":{"bonus":{"force":20,"hp":200,"luck":15,"troop_capacity":20},"pieces":4},"set_description":"一蓑烟雨","set_key":"starter_cloth_set"} | AF10: data/item_templates.yaml:L2871
A11: 10 | B11: equip_bumao | C11: 布帽 | D11: helmet | E11: 头盔 | F11: equip_helmet | G11: black | H11: 普通/白 | K11: 一般老百姓戴的帽子，遮风遮日用。 | L11: 100 | M11: 50 | N11: 是 | O11: 100 | P11: 5 | Q11: 0 | R11: 8 | S11: 5 | T11: 0 | U11: 0 | V11: =SUM(O11:U11) | W11: =O11*'强度系数说明'!$B$7+P11*'强度系数说明'!$B$8+Q11*'强度系数说明'!$B$9+R11*'强度系数说明'!$B$10+S11*'强度系数说明'!$B$11+T11*'强度系数说明'!$B$12+U11*'强度系数说明'!$B$13 | X11: =SUMPRODUCT((O11:U11>0)*O11:U11) | Y11: 是 | Z11: 头盔 | AA11: 1 | AB11: 120 | AC11: {"tong":5} | AE11: {"agility":5,"defense":5,"hp":100,"intellect":8} | AF11: data/item_templates.yaml:L2897; data/forge_equipment.yaml:L2
A12: 11 | B12: equip_niupimao | C12: 牛皮帽 | D12: helmet | E12: 头盔 | F12: equip_helmet | G12: black | H12: 普通/白 | K12: 既能御寒，又能稍微保护脑袋。 | L12: 300 | M12: 50 | N12: 是 | O12: 100 | P12: 10 | Q12: 5 | R12: 0 | S12: 5 | T12: 0 | U12: 0 | V12: =SUM(O12:U12) | W12: =O12*'强度系数说明'!$B$7+P12*'强度系数说明'!$B$8+Q12*'强度系数说明'!$B$9+R12*'强度系数说明'!$B$10+S12*'强度系数说明'!$B$11+T12*'强度系数说明'!$B$12+U12*'强度系数说明'!$B$13 | X12: =SUMPRODUCT((O12:U12>0)*O12:U12) | Y12: 是 | Z12: 头盔 | AA12: 3 | AB12: 180 | AC12: {"tong":10,"xi":5} | AE12: {"agility":5,"defense":10,"force":5,"hp":100} | AF12: data/item_templates.yaml:L2912; data/forge_equipment.yaml:L8
A13: 12 | B13: equip_tieyekui | C13: 铁叶盔 | D13: helmet | E13: 头盔 | F13: equip_helmet | G13: green | H13: 优良/绿 | K13: 有不错的保护效果，但是太过沉重，压着脑袋很难受。 | L13: 800 | M13: 75 | N13: 是 | O13: 150 | P13: 10 | Q13: 15 | R13: 0 | S13: 0 | T13: 0 | U13: 0 | V13: =SUM(O13:U13) | W13: =O13*'强度系数说明'!$B$7+P13*'强度系数说明'!$B$8+Q13*'强度系数说明'!$B$9+R13*'强度系数说明'!$B$10+S13*'强度系数说明'!$B$11+T13*'强度系数说明'!$B$12+U13*'强度系数说明'!$B$13 | X13: =SUMPRODUCT((O13:U13>0)*O13:U13) | Y13: 是 | Z13: 头盔 | AA13: 5 | AB13: 240 | AC13: {"tie":10} | AE13: {"defense":10,"force":15,"hp":150} | AF13: data/item_templates.yaml:L2927; data/forge_equipment.yaml:L15
A14: 13 | B14: equip_yulindin | C14: 鱼鳞顶 | D14: helmet | E14: 头盔 | F14: equip_helmet | G14: green | H14: 优良/绿 | K14: 鱼鳞状的铜片编成，轻便而坚固。 | L14: 1500 | M14: 75 | N14: 是 | O14: 500 | P14: 15 | Q14: 2 | R14: 0 | S14: 5 | T14: 0 | U14: 0 | V14: =SUM(O14:U14) | W14: =O14*'强度系数说明'!$B$7+P14*'强度系数说明'!$B$8+Q14*'强度系数说明'!$B$9+R14*'强度系数说明'!$B$10+S14*'强度系数说明'!$B$11+T14*'强度系数说明'!$B$12+U14*'强度系数说明'!$B$13 | X14: =SUMPRODUCT((O14:U14>0)*O14:U14) | Y14: 是 | Z14: 头盔 | AA14: 7 | AB14: 300 | AC14: {"tie":20} | AE14: {"agility":5,"defense":15,"force":2,"hp":500} | AF14: data/item_templates.yaml:L2941; data/forge_equipment.yaml:L21
A15: 14 | B15: equip_baihongkui | C15: 白虹盔 | D15: helmet | E15: 头盔 | F15: equip_helmet | G15: green | H15: 优良/绿 | K15: 精钢铸就，盔顶白缨飘飘，威武不凡。 | L15: 3000 | M15: 75 | N15: 是 | O15: 200 | P15: 15 | Q15: 5 | R15: 0 | S15: 0 | T15: 0 | U15: 20 | V15: =SUM(O15:U15) | W15: =O15*'强度系数说明'!$B$7+P15*'强度系数说明'!$B$8+Q15*'强度系数说明'!$B$9+R15*'强度系数说明'!$B$10+S15*'强度系数说明'!$B$11+T15*'强度系数说明'!$B$12+U15*'强度系数说明'!$B$13 | X15: =SUMPRODUCT((O15:U15>0)*O15:U15) | Y15: 是 | Z15: 头盔 | AA15: 9 | AB15: 360 | AC15: {"tie":30} | AE15: {"defense":15,"force":5,"hp":200,"troop_capacity":20} | AF15: data/item_templates.yaml:L2956; data/forge_equipment.yaml:L27
A16: 15 | B16: equip_zhubiankui | C16: 竹编盔 | D16: helmet | E16: 头盔 | F16: equip_helmet | G16: black | H16: 普通/白 | K16: 终南山道士所编，取材自千年古竹林，轻巧透气。 | L16: 200 | M16: 50 | N16: 是 | O16: 300 | P16: 15 | Q16: 0 | R16: 0 | S16: 0 | T16: 0 | U16: 0 | V16: =SUM(O16:U16) | W16: =O16*'强度系数说明'!$B$7+P16*'强度系数说明'!$B$8+Q16*'强度系数说明'!$B$9+R16*'强度系数说明'!$B$10+S16*'强度系数说明'!$B$11+T16*'强度系数说明'!$B$12+U16*'强度系数说明'!$B$13 | X16: =SUMPRODUCT((O16:U16>0)*O16:U16) | Y16: 否 | AE16: {"defense":15,"hp":300} | AF16: data/item_templates.yaml:L2971
A17: 16 | B17: equip_yemantoukie | C17: 野蛮头盔 | D17: helmet | E17: 头盔 | F17: equip_helmet | G17: green | H17: 优良/绿 | I17: yeman_set | J17: 野蛮套装 | K17: 北方蛮族的战利品，以兽皮与铁铆拼制，带有异域风格。 | L17: 2000 | M17: 75 | N17: 是 | O17: 150 | P17: 10 | Q17: 20 | R17: 0 | S17: 0 | T17: 0 | U17: 0 | V17: =SUM(O17:U17) | W17: =O17*'强度系数说明'!$B$7+P17*'强度系数说明'!$B$8+Q17*'强度系数说明'!$B$9+R17*'强度系数说明'!$B$10+S17*'强度系数说明'!$B$11+T17*'强度系数说明'!$B$12+U17*'强度系数说明'!$B$13 | X17: =SUMPRODUCT((O17:U17>0)*O17:U17) | Y17: 否 | AD17: {"bonus":{"defense":10,"force":25,"hp":300},"pieces":2} | AE17: {"defense":10,"force":20,"hp":150,"set_bonus":{"bonus":{"defense":10,"force":25,"hp":300},"pieces":2},"set_description":"野蛮套装","set_key":"yeman_set"} | AF17: data/item_templates.yaml:L2986
A18: 17 | B18: equip_huwenkui | C18: 虎纹盔 | D18: helmet | E18: 头盔 | F18: equip_helmet | G18: green | H18: 优良/绿 | K18: 据说是某位虎将的遗物，虎纹威猛，煞气逼人。 | L18: 2500 | M18: 75 | N18: 是 | O18: 220 | P18: 18 | Q18: 15 | R18: 0 | S18: 0 | T18: 0 | U18: 0 | V18: =SUM(O18:U18) | W18: =O18*'强度系数说明'!$B$7+P18*'强度系数说明'!$B$8+Q18*'强度系数说明'!$B$9+R18*'强度系数说明'!$B$10+S18*'强度系数说明'!$B$11+T18*'强度系数说明'!$B$12+U18*'强度系数说明'!$B$13 | X18: =SUMPRODUCT((O18:U18>0)*O18:U18) | Y18: 否 | AE18: {"defense":18,"force":15,"hp":220} | AF18: data/item_templates.yaml:L3007
A19: 18 | B19: equip_baoutoukui | C19: 豹头盔 | D19: helmet | E19: 头盔 | F19: equip_helmet | G19: green | H19: 优良/绿 | K19: 豹首造型的头盔，相传为豹子头林冲年轻时所佩。 | L19: 2800 | M19: 75 | N19: 是 | O19: 200 | P19: 20 | Q19: 0 | R19: 0 | S19: 15 | T19: 0 | U19: 0 | V19: =SUM(O19:U19) | W19: =O19*'强度系数说明'!$B$7+P19*'强度系数说明'!$B$8+Q19*'强度系数说明'!$B$9+R19*'强度系数说明'!$B$10+S19*'强度系数说明'!$B$11+T19*'强度系数说明'!$B$12+U19*'强度系数说明'!$B$13 | X19: =SUMPRODUCT((O19:U19>0)*O19:U19) | Y19: 否 | AE19: {"agility":15,"defense":20,"hp":200} | AF19: data/item_templates.yaml:L3021
A20: 19 | B20: equip_yanlingmao | C20: 雁翎帽 | D20: helmet | E20: 头盔 | F20: equip_helmet | G20: green | H20: 优良/绿 | K20: 以雁翎装饰的轻帽，是江湖侠客间广为流传的款式。 | L20: 2200 | M20: 75 | N20: 是 | O20: 200 | P20: 15 | Q20: 0 | R20: 0 | S20: 15 | T20: 0 | U20: 0 | V20: =SUM(O20:U20) | W20: =O20*'强度系数说明'!$B$7+P20*'强度系数说明'!$B$8+Q20*'强度系数说明'!$B$9+R20*'强度系数说明'!$B$10+S20*'强度系数说明'!$B$11+T20*'强度系数说明'!$B$12+U20*'强度系数说明'!$B$13 | X20: =SUMPRODUCT((O20:U20>0)*O20:U20) | Y20: 否 | AE20: {"agility":15,"defense":15,"hp":200} | AF20: data/item_templates.yaml:L3035
A21: 20 | B21: equip_qingtengguan | C21: 青藤冠 | D21: helmet | E21: 头盔 | F21: equip_helmet | G21: green | H21: 优良/绿 | K21: 以藤蔓与玉扣编织而成，据说出自某位隐居山林的高人之手。 | L21: 2600 | M21: 75 | N21: 是 | O21: 200 | P21: 10 | Q21: 0 | R21: 15 | S21: 0 | T21: 5 | U21: 0 | V21: =SUM(O21:U21) | W21: =O21*'强度系数说明'!$B$7+P21*'强度系数说明'!$B$8+Q21*'强度系数说明'!$B$9+R21*'强度系数说明'!$B$10+S21*'强度系数说明'!$B$11+T21*'强度系数说明'!$B$12+U21*'强度系数说明'!$B$13 | X21: =SUMPRODUCT((O21:U21>0)*O21:U21) | Y21: 否 | AE21: {"defense":10,"hp":200,"intellect":15,"luck":5} | AF21: data/item_templates.yaml:L3049
A22: 21 | B22: equip_xiaoweitoukui | C22: 校尉头盔 | D22: helmet | E22: 头盔 | F22: equip_helmet | G22: blue | H22: 稀有/蓝 | I22: xiaowei_set | J22: 校尉套装 | K22: 军中校尉制式头盔，上有龙纹标识，象征军阶与荣誉。 | L22: 5000 | M22: 100 | N22: 是 | O22: 350 | P22: 20 | Q22: 15 | R22: 0 | S22: 0 | T22: 0 | U22: 20 | V22: =SUM(O22:U22) | W22: =O22*'强度系数说明'!$B$7+P22*'强度系数说明'!$B$8+Q22*'强度系数说明'!$B$9+R22*'强度系数说明'!$B$10+S22*'强度系数说明'!$B$11+T22*'强度系数说明'!$B$12+U22*'强度系数说明'!$B$13 | X22: =SUMPRODUCT((O22:U22>0)*O22:U22) | Y22: 否 | AD22: {"bonus":{"defense":15,"force":40,"hp":360,"troop_capacity":100},"pieces":4} | AE22: {"defense":20,"force":15,"hp":350,"set_bonus":{"bonus":{"defense":15,"force":40,"hp":360,"troop_capacity":100},"pieces":4},"set_description":"校尉套装","set_key":"xiaowei_set","troop_capacity":20} | AF22: data/item_templates.yaml:L3066
A23: 22 | B23: equip_jiaodoushitoukui | C23: 角斗士头盔 | D23: helmet | E23: 头盔 | F23: equip_helmet | G23: blue | H23: 稀有/蓝 | I23: jiaodoushi_set | J23: 角斗士套装 | K23: 角斗场老兵常用的重盔，面甲刻有胜场纹记，兼顾防护与压迫感。 | L23: 6200 | M23: 100 | N23: 是 | O23: 350 | P23: 25 | Q23: 20 | R23: 0 | S23: 0 | T23: 0 | U23: 0 | V23: =SUM(O23:U23) | W23: =O23*'强度系数说明'!$B$7+P23*'强度系数说明'!$B$8+Q23*'强度系数说明'!$B$9+R23*'强度系数说明'!$B$10+S23*'强度系数说明'!$B$11+T23*'强度系数说明'!$B$12+U23*'强度系数说明'!$B$13 | X23: =SUMPRODUCT((O23:U23>0)*O23:U23) | Y23: 否 | AD23: {"bonus":{"agility":15,"defense":10,"force":30,"hp":280},"pieces":4} | AE23: {"defense":25,"force":20,"hp":350,"set_bonus":{"bonus":{"agility":15,"defense":10,"force":30,"hp":280},"pieces":4},"set_description":"角斗士套装","set_key":"jiaodoushi_set"} | AF23: data/item_templates.yaml:L3089
A24: 23 | B24: equip_xuantiekui | C24: 玄铁盔 | D24: helmet | E24: 头盔 | F24: equip_helmet | G24: blue | H24: 稀有/蓝 | K24: 以罕见玄铁锻成，据传耗费了三位铁匠十年心血。 | L24: 6000 | M24: 100 | N24: 是 | O24: 340 | P24: 40 | Q24: 15 | R24: 0 | S24: 0 | T24: 0 | U24: 0 | V24: =SUM(O24:U24) | W24: =O24*'强度系数说明'!$B$7+P24*'强度系数说明'!$B$8+Q24*'强度系数说明'!$B$9+R24*'强度系数说明'!$B$10+S24*'强度系数说明'!$B$11+T24*'强度系数说明'!$B$12+U24*'强度系数说明'!$B$13 | X24: =SUMPRODUCT((O24:U24>0)*O24:U24) | Y24: 否 | AE24: {"defense":40,"force":15,"hp":340} | AF24: data/item_templates.yaml:L3111
A25: 24 | B25: equip_qinglongkui | C25: 青龙盔 | D25: helmet | E25: 头盔 | F25: equip_helmet | G25: blue | H25: 稀有/蓝 | I25: sixiang_set | J25: 四象套装 | K25: 青龙纹路盘绕其上，相传是东方青龙庙镇殿之物。 | L25: 5500 | M25: 100 | N25: 是 | O25: 400 | P25: 20 | Q25: 0 | R25: 22 | S25: 0 | T25: 0 | U25: 0 | V25: =SUM(O25:U25) | W25: =O25*'强度系数说明'!$B$7+P25*'强度系数说明'!$B$8+Q25*'强度系数说明'!$B$9+R25*'强度系数说明'!$B$10+S25*'强度系数说明'!$B$11+T25*'强度系数说明'!$B$12+U25*'强度系数说明'!$B$13 | X25: =SUMPRODUCT((O25:U25>0)*O25:U25) | Y25: 否 | AD25: {"bonus":{"agility":20,"force":35,"hp":360,"intellect":35},"pieces":4} | AE25: {"defense":20,"hp":400,"intellect":22,"set_bonus":{"bonus":{"agility":20,"force":35,"hp":360,"intellect":35},"pieces":4},"set_description":"四象套装","set_key":"sixiang_set"} | AF25: data/item_templates.yaml:L3125
A26: 25 | B26: equip_hantiekui | C26: 寒铁盔 | D26: helmet | E26: 头盔 | F26: equip_helmet | G26: blue | H26: 稀有/蓝 | K26: 以极北寒铁铸就，触之冰凉入骨，常年不受寒侵。 | L26: 6500 | M26: 100 | N26: 是 | O26: 380 | P26: 35 | Q26: 5 | R26: 0 | S26: 0 | T26: 0 | U26: 0 | V26: =SUM(O26:U26) | W26: =O26*'强度系数说明'!$B$7+P26*'强度系数说明'!$B$8+Q26*'强度系数说明'!$B$9+R26*'强度系数说明'!$B$10+S26*'强度系数说明'!$B$11+T26*'强度系数说明'!$B$12+U26*'强度系数说明'!$B$13 | X26: =SUMPRODUCT((O26:U26>0)*O26:U26) | Y26: 否 | AE26: {"defense":35,"force":5,"hp":380} | AF26: data/item_templates.yaml:L3147
A27: 26 | B27: equip_langyakui | C27: 狼牙盔 | D27: helmet | E27: 头盔 | F27: equip_helmet | G27: blue | H27: 稀有/蓝 | K27: 草原狼王的头骨所制，盔缘嵌有狼牙，凶悍异常。 | L27: 5800 | M27: 100 | N27: 是 | O27: 300 | P27: 20 | Q27: 20 | R27: 0 | S27: 15 | T27: 0 | U27: 0 | V27: =SUM(O27:U27) | W27: =O27*'强度系数说明'!$B$7+P27*'强度系数说明'!$B$8+Q27*'强度系数说明'!$B$9+R27*'强度系数说明'!$B$10+S27*'强度系数说明'!$B$11+T27*'强度系数说明'!$B$12+U27*'强度系数说明'!$B$13 | X27: =SUMPRODUCT((O27:U27>0)*O27:U27) | Y27: 否 | AE27: {"agility":15,"defense":20,"force":20,"hp":300} | AF27: data/item_templates.yaml:L3161
A28: 27 | B28: equip_feiyukui | C28: 飞羽盔 | D28: helmet | E28: 头盔 | F28: equip_helmet | G28: blue | H28: 稀有/蓝 | K28: 以百鸟之羽装饰的轻盔，据说曾是某位神箭手的心爱之物。 | L28: 5600 | M28: 100 | N28: 是 | O28: 400 | P28: 15 | Q28: 0 | R28: 0 | S28: 25 | T28: 10 | U28: 0 | V28: =SUM(O28:U28) | W28: =O28*'强度系数说明'!$B$7+P28*'强度系数说明'!$B$8+Q28*'强度系数说明'!$B$9+R28*'强度系数说明'!$B$10+S28*'强度系数说明'!$B$11+T28*'强度系数说明'!$B$12+U28*'强度系数说明'!$B$13 | X28: =SUMPRODUCT((O28:U28>0)*O28:U28) | Y28: 否 | AE28: {"agility":25,"defense":15,"hp":400,"luck":10} | AF28: data/item_templates.yaml:L3176
A29: 28 | B29: equip_yunwenkui | C29: 云纹盔 | D29: helmet | E29: 头盔 | F29: equip_helmet | G29: blue | H29: 稀有/蓝 | K29: 盔面云纹如行云流水，出自名匠"云中子"之手。 | L29: 6200 | M29: 100 | N29: 是 | O29: 300 | P29: 15 | Q29: 0 | R29: 25 | S29: 0 | T29: 10 | U29: 0 | V29: =SUM(O29:U29) | W29: =O29*'强度系数说明'!$B$7+P29*'强度系数说明'!$B$8+Q29*'强度系数说明'!$B$9+R29*'强度系数说明'!$B$10+S29*'强度系数说明'!$B$11+T29*'强度系数说明'!$B$12+U29*'强度系数说明'!$B$13 | X29: =SUMPRODUCT((O29:U29>0)*O29:U29) | Y29: 否 | AE29: {"defense":15,"hp":300,"intellect":25,"luck":10} | AF29: data/item_templates.yaml:L3191
A30: 29 | B30: equip_qilinkui | C30: 麒麟盔 | D30: helmet | E30: 头盔 | F30: equip_helmet | G30: purple | H30: 史诗/紫 | I30: qilin_set | J30: 麒麟套装 | K30: 仿麒麟头颅锻造，相传是某位开国将军的传家之宝。 | L30: 15000 | M30: 150 | N30: 是 | O30: 440 | P30: 33 | Q30: 28 | R30: 3 | S30: 0 | T30: 0 | U30: 0 | V30: =SUM(O30:U30) | W30: =O30*'强度系数说明'!$B$7+P30*'强度系数说明'!$B$8+Q30*'强度系数说明'!$B$9+R30*'强度系数说明'!$B$10+S30*'强度系数说明'!$B$11+T30*'强度系数说明'!$B$12+U30*'强度系数说明'!$B$13 | X30: =SUMPRODUCT((O30:U30>0)*O30:U30) | Y30: 否 | AD30: {"bonus":{"agility":18,"force":38,"hp":420,"luck":30},"pieces":4} | AE30: {"defense":33,"force":28,"hp":440,"intellect":3,"set_bonus":{"bonus":{"agility":18,"force":38,"hp":420,"luck":30},"pieces":4},"set_description":"麒麟套装","set_key":"qilin_set"} | AF30: data/item_templates.yaml:L3208
A31: 30 | B31: equip_fenglingguan | C31: 凤翎冠 | D31: helmet | E31: 头盔 | F31: equip_helmet | G31: purple | H31: 史诗/紫 | I31: fengling_set | J31: 凤翎套装 | K31: 以凤凰翎羽点缀的华冠，曾是后宫贵妃所赐之物。 | L31: 14000 | M31: 150 | N31: 是 | O31: 360 | P31: 21 | Q31: 0 | R31: 32 | S31: 0 | T31: 11 | U31: 0 | V31: =SUM(O31:U31) | W31: =O31*'强度系数说明'!$B$7+P31*'强度系数说明'!$B$8+Q31*'强度系数说明'!$B$9+R31*'强度系数说明'!$B$10+S31*'强度系数说明'!$B$11+T31*'强度系数说明'!$B$12+U31*'强度系数说明'!$B$13 | X31: =SUMPRODUCT((O31:U31>0)*O31:U31) | Y31: 否 | AD31: {"bonus":{"intellect":60,"luck":30},"pieces":3} | AE31: {"defense":21,"hp":360,"intellect":32,"luck":11,"set_bonus":{"bonus":{"intellect":60,"luck":30},"pieces":3},"set_description":"凤翎套装","set_key":"fengling_set"} | AF31: data/item_templates.yaml:L3231
A32: 31 | B32: equip_bawangkui | C32: 霸王盔 | D32: helmet | E32: 头盔 | F32: equip_helmet | G32: purple | H32: 史诗/紫 | K32: 相传为西楚霸王项羽的遗物，气势撼人，威压四方。 | L32: 18000 | M32: 150 | N32: 是 | O32: 500 | P32: 30 | Q32: 35 | R32: 0 | S32: 0 | T32: 0 | U32: 0 | V32: =SUM(O32:U32) | W32: =O32*'强度系数说明'!$B$7+P32*'强度系数说明'!$B$8+Q32*'强度系数说明'!$B$9+R32*'强度系数说明'!$B$10+S32*'强度系数说明'!$B$11+T32*'强度系数说明'!$B$12+U32*'强度系数说明'!$B$13 | X32: =SUMPRODUCT((O32:U32>0)*O32:U32) | Y32: 否 | AE32: {"defense":30,"force":35,"hp":500} | AF32: data/item_templates.yaml:L3252
A33: 32 | B33: equip_xuanwukui | C33: 玄武盔 | D33: helmet | E33: 头盔 | F33: equip_helmet | G33: purple | H33: 史诗/紫 | I33: xuanwu_set | J33: 玄武套装 | K33: 仿玄武之形锻造，背负龟壳纹样，象征长寿与坚固。 | L33: 16000 | M33: 150 | N33: 是 | O33: 545 | P33: 44 | Q33: 10 | R33: 10 | S33: 0 | T33: 0 | U33: 0 | V33: =SUM(O33:U33) | W33: =O33*'强度系数说明'!$B$7+P33*'强度系数说明'!$B$8+Q33*'强度系数说明'!$B$9+R33*'强度系数说明'!$B$10+S33*'强度系数说明'!$B$11+T33*'强度系数说明'!$B$12+U33*'强度系数说明'!$B$13 | X33: =SUMPRODUCT((O33:U33>0)*O33:U33) | Y33: 否 | AD33: {"bonus":{"defense":70,"force":20,"hp":260},"pieces":4} | AE33: {"defense":44,"force":10,"hp":545,"intellect":10,"set_bonus":{"bonus":{"defense":70,"force":20,"hp":260},"pieces":4},"set_description":"玄武套装","set_key":"xuanwu_set"} | AF33: data/item_templates.yaml:L3266
A34: 33 | B34: equip_pojunkui | C34: 破军盔 | D34: helmet | E34: 头盔 | F34: equip_helmet | G34: purple | H34: 史诗/紫 | K34: 破军星位所铸，据传戴者必成一方悍将。 | L34: 15500 | M34: 150 | N34: 是 | O34: 445 | P34: 26 | Q34: 27 | R34: 0 | S34: 15 | T34: 0 | U34: 0 | V34: =SUM(O34:U34) | W34: =O34*'强度系数说明'!$B$7+P34*'强度系数说明'!$B$8+Q34*'强度系数说明'!$B$9+R34*'强度系数说明'!$B$10+S34*'强度系数说明'!$B$11+T34*'强度系数说明'!$B$12+U34*'强度系数说明'!$B$13 | X34: =SUMPRODUCT((O34:U34>0)*O34:U34) | Y34: 否 | AE34: {"agility":15,"defense":26,"force":27,"hp":445} | AF34: data/item_templates.yaml:L3288
A35: 34 | B35: equip_tianjiguan | C35: 天机冠 | D35: helmet | E35: 头盔 | F35: equip_helmet | G35: purple | H35: 史诗/紫 | K35: 以天机门秘法打造，冠中暗藏机括，可察天象变化。 | L35: 14500 | M35: 150 | N35: 是 | O35: 390 | P35: 20 | Q35: 0 | R35: 38 | S35: 0 | T35: 14 | U35: 0 | V35: =SUM(O35:U35) | W35: =O35*'强度系数说明'!$B$7+P35*'强度系数说明'!$B$8+Q35*'强度系数说明'!$B$9+R35*'强度系数说明'!$B$10+S35*'强度系数说明'!$B$11+T35*'强度系数说明'!$B$12+U35*'强度系数说明'!$B$13 | X35: =SUMPRODUCT((O35:U35>0)*O35:U35) | Y35: 否 | AE35: {"defense":20,"hp":390,"intellect":38,"luck":14} | AF35: data/item_templates.yaml:L3303
A36: 35 | B36: equip_longhuangguan | C36: 龙皇冠 | D36: helmet | E36: 头盔 | F36: equip_helmet | G36: orange | H36: 传说/橙 | K36: 相传为远古龙皇遗落人间的宝物，冠身隐有龙吟。 | L36: 50000 | M36: 200 | N36: 是 | O36: 620 | P36: 26 | Q36: 12 | R36: 32 | S36: 0 | T36: 0 | U36: 20 | V36: =SUM(O36:U36) | W36: =O36*'强度系数说明'!$B$7+P36*'强度系数说明'!$B$8+Q36*'强度系数说明'!$B$9+R36*'强度系数说明'!$B$10+S36*'强度系数说明'!$B$11+T36*'强度系数说明'!$B$12+U36*'强度系数说明'!$B$13 | X36: =SUMPRODUCT((O36:U36>0)*O36:U36) | Y36: 否 | AE36: {"defense":26,"force":12,"hp":620,"intellect":32,"troop_capacity":20} | AF36: data/item_templates.yaml:L3320
A37: 36 | B37: equip_diwangkui | C37: 帝王盔 | D37: helmet | E37: 头盔 | F37: equip_helmet | G37: orange | H37: 传说/橙 | K37: 历代帝王御用的铠甲头盔，象征至高无上的权威。 | L37: 48000 | M37: 200 | N37: 是 | O37: 503 | P37: 29 | Q37: 29 | R37: 29 | S37: 0 | T37: 0 | U37: 0 | V37: =SUM(O37:U37) | W37: =O37*'强度系数说明'!$B$7+P37*'强度系数说明'!$B$8+Q37*'强度系数说明'!$B$9+R37*'强度系数说明'!$B$10+S37*'强度系数说明'!$B$11+T37*'强度系数说明'!$B$12+U37*'强度系数说明'!$B$13 | X37: =SUMPRODUCT((O37:U37>0)*O37:U37) | Y37: 否 | AE37: {"defense":29,"force":29,"hp":503,"intellect":29} | AF37: data/item_templates.yaml:L3336
A38: 37 | B38: equip_taixudiguan | C38: 太虚帝冠 | D38: helmet | E38: 头盔 | F38: equip_helmet | G38: orange | H38: 传说/橙 | K38: 传说为太虚剑宗创派祖师所佩，内藏太虚真意。 | L38: 55000 | M38: 200 | N38: 是 | O38: 560 | P38: 30 | Q38: 0 | R38: 34 | S38: 0 | T38: 14 | U38: 0 | V38: =SUM(O38:U38) | W38: =O38*'强度系数说明'!$B$7+P38*'强度系数说明'!$B$8+Q38*'强度系数说明'!$B$9+R38*'强度系数说明'!$B$10+S38*'强度系数说明'!$B$11+T38*'强度系数说明'!$B$12+U38*'强度系数说明'!$B$13 | X38: =SUMPRODUCT((O38:U38>0)*O38:U38) | Y38: 否 | AE38: {"defense":30,"hp":560,"intellect":34,"luck":14} | AF38: data/item_templates.yaml:L3351
A39: 38 | B39: equip_bupao | C39: 布袍 | D39: armor | E39: 护甲 | F39: equip_armor | G39: black | H39: 普通/白 | K39: 普通老百姓穿的衣服，所谓布衣。 | L39: 100 | M39: 50 | N39: 是 | O39: 100 | P39: 8 | Q39: 0 | R39: 10 | S39: 0 | T39: 0 | U39: 0 | V39: =SUM(O39:U39) | W39: =O39*'强度系数说明'!$B$7+P39*'强度系数说明'!$B$8+Q39*'强度系数说明'!$B$9+R39*'强度系数说明'!$B$10+S39*'强度系数说明'!$B$11+T39*'强度系数说明'!$B$12+U39*'强度系数说明'!$B$13 | X39: =SUMPRODUCT((O39:U39>0)*O39:U39) | Y39: 是 | Z39: 护甲 | AA39: 1 | AB39: 120 | AC39: {"tong":5} | AE39: {"defense":8,"hp":100,"intellect":10} | AF39: data/item_templates.yaml:L3370; data/forge_equipment.yaml:L33
A40: 39 | B40: equip_shengpijia | C40: 生皮甲 | D40: armor | E40: 护甲 | F40: equip_armor | G40: black | H40: 普通/白 | K40: 没经过硝制的动物皮做成的护甲，防御力很弱。 | L40: 300 | M40: 50 | N40: 是 | O40: 200 | P40: 15 | Q40: 5 | R40: 0 | S40: 0 | T40: 0 | U40: 0 | V40: =SUM(O40:U40) | W40: =O40*'强度系数说明'!$B$7+P40*'强度系数说明'!$B$8+Q40*'强度系数说明'!$B$9+R40*'强度系数说明'!$B$10+S40*'强度系数说明'!$B$11+T40*'强度系数说明'!$B$12+U40*'强度系数说明'!$B$13 | X40: =SUMPRODUCT((O40:U40>0)*O40:U40) | Y40: 是 | Z40: 护甲 | AA40: 3 | AB40: 180 | AC40: {"tong":10,"xi":5} | AE40: {"defense":15,"force":5,"hp":200} | AF40: data/item_templates.yaml:L3384; data/forge_equipment.yaml:L39
...

Sheet 强度系数说明
A1: 装备属性与强度系数口径
A3: 数据来源 | B3: data/item_templates.yaml；tests/test_item_template_equipment_balance.py；gameplay/services/virtual_player_core/virtual_assets.py
A4: 使用说明 | B4: “装备总表”中的基础强度评分使用固定平衡测试公式；动态候选权重不是固定装备值，必须结合成长阶段、角色适配和门客属性。
A6: 属性 | B6: 基础系数 | C6: 计算贡献 | D6: 代码口径 | E6: 备注
A7: 生命 | B7: =1/54 | C7: 生命 × 系数 | D7: hp / 54.0 | E7: 生命折算为有效强度
A8: 防御 | B8: 1 | C8: 防御 × 系数 | D8: defense
A9: 武力 | B9: 1 | C9: 武力 × 系数 | D9: force
A10: 智力 | B10: 1 | C10: 智力 × 系数 | D10: intellect
A11: 敏捷 | B11: 1 | C11: 敏捷 × 系数 | D11: agility
A12: 运势 | B12: 1.2 | C12: 运势 × 系数 | D12: luck * 1.2 | E12: 运势权重高于普通属性
A13: 带兵上限 | B13: =1/2 | C13: 带兵上限 × 系数 | D13: troop_capacity / 2.0
A15: 稀有度跨档平均强度最低提升阈值 | B15: 1.1 | C15: 代码常量 MIN_RARITY_SCORE_RATIO | D15: 部位稀有度汇总中的提升系数以此阈值核对
A18: 动态候选权重（虚拟玩家装备候选选择）
A19: 项目 | B19: 公式/数值 | C19: 说明 | D19: 代码来源 | E19: 是否装备固定值
A20: 装备候选基础 Power | B20: attack_bonus + defense_bonus + Σ(max(extra_stat, 0)) | C20: 当前 ItemTemplate 同步到 GearTemplate 时 attack_bonus、defense_bonus 默认均为 0，因此本表 X 列为直接属性非负和。 | D20: virtual_assets.py:361-369 | E20: 是
A21: 成长阶段系数 | B21: 1 + MIN(2, growth_stage / 20) | C21: 随虚拟玩家成长阶段变化，最高额外增加 2.0。 | D21: virtual_assets.py:371 | E21: 否
A22: 角色适配系数 | B22: 1.35（适配）/ 1.00（不适配） | C22: 是否符合门客偏好角色。 | D22: virtual_assets.py:372 | E22: 否
A23: 门客属性系数 | B23: 1 + guest_power / 1000 | C23: guest_power 为门客武力、智力、防御、敏捷等属性汇总。 | D23: virtual_assets.py:373-376 | E23: 否
A24: 动态候选权重 | B24: Power × 成长阶段系数 × 角色适配系数 × 门客属性系数 | C24: 同一件装备在不同虚拟玩家/门客上下文中会不同，不能在装备表中写成唯一固定系数。 | D24: virtual_assets.py:378 | E24: 否
A28: 装备总表评分公式 | B28: 生命/54 + 防御 + 武力 + 智力 + 敏捷 + 运势×1.2 + 带兵上限/2
A29: 注意 | B29: 该固定评分用于装备平衡排序/稀有度跨档检查，不等同于战斗中的最终门客战力；套装效果也未并入单件基础评分。

Sheet 部位稀有度汇总
A1: 部位 × 稀有度强度核对
A3: 说明 | B3: 平均强度、跨档提升系数均通过公式引用“装备总表”；空组合显示为空，不参与比较。
A4: 部位代码 | B4: 部位 | C4: 稀有度代码 | D4: 稀有度 | E4: 装备数量 | F4: 平均基础强度 | G4: 最低 | H4: 最高 | I4: 上一档平均 | J4: 提升系数 | K4: 阈值核对
A5: helmet | B5: 头盔 | C5: black | D5: 普通/白 | E5: =COUNTIFS('装备总表'!$D$2:$D$263,$A5,'装备总表'!$G$2:$G$263,$C5) | F5: =IF($E5=0,"",SUMIFS('装备总表'!$W$2:$W$263,'装备总表'!$D$2:$D$263,$A5,'装备总表'!$G$2:$G$263,$C5)/$E5) | G5: =IF($E5=0,"",MINIFS('装备总表'!$W$2:$W$263,'装备总表'!$D$2:$D$263,$A5,'装备总表'!$G$2:$G$263,$C5)) | H5: =IF($E5=0,"",MAXIFS('装备总表'!$W$2:$W$263,'装备总表'!$D$2:$D$263,$A5,'装备总表'!$G$2:$G$263,$C5)) | J5: =IF(OR($I5="",$I5=0),"",$F5/$I5) | K5: =IF($J5="","",IF($J5>='强度系数说明'!$B$15,"通过","低于阈值"))
A6: helmet | B6: 头盔 | C6: green | D6: 优良/绿 | E6: =COUNTIFS('装备总表'!$D$2:$D$263,$A6,'装备总表'!$G$2:$G$263,$C6) | F6: =IF($E6=0,"",SUMIFS('装备总表'!$W$2:$W$263,'装备总表'!$D$2:$D$263,$A6,'装备总表'!$G$2:$G$263,$C6)/$E6) | G6: =IF($E6=0,"",MINIFS('装备总表'!$W$2:$W$263,'装备总表'!$D$2:$D$263,$A6,'装备总表'!$G$2:$G$263,$C6)) | H6: =IF($E6=0,"",MAXIFS('装备总表'!$W$2:$W$263,'装备总表'!$D$2:$D$263,$A6,'装备总表'!$G$2:$G$263,$C6)) | I6: =IF(OR($A6<>$A5,$E5=0),"",$F5) | J6: =IF(OR($I6="",$I6=0),"",$F6/$I6) | K6: =IF($J6="","",IF($J6>='强度系数说明'!$B$15,"通过","低于阈值"))
A7: helmet | B7: 头盔 | C7: blue | D7: 稀有/蓝 | E7: =COUNTIFS('装备总表'!$D$2:$D$263,$A7,'装备总表'!$G$2:$G$263,$C7) | F7: =IF($E7=0,"",SUMIFS('装备总表'!$W$2:$W$263,'装备总表'!$D$2:$D$263,$A7,'装备总表'!$G$2:$G$263,$C7)/$E7) | G7: =IF($E7=0,"",MINIFS('装备总表'!$W$2:$W$263,'装备总表'!$D$2:$D$263,$A7,'装备总表'!$G$2:$G$263,$C7)) | H7: =IF($E7=0,"",MAXIFS('装备总表'!$W$2:$W$263,'装备总表'!$D$2:$D$263,$A7,'装备总表'!$G$2:$G$263,$C7)) | I7: =IF(OR($A7<>$A6,$E6=0),"",$F6) | J7: =IF(OR($I7="",$I7=0),"",$F7/$I7) | K7: =IF($J7="","",IF($J7>='强度系数说明'!$B$15,"通过","低于阈值"))
A8: helmet | B8: 头盔 | C8: purple | D8: 史诗/紫 | E8: =COUNTIFS('装备总表'!$D$2:$D$263,$A8,'装备总表'!$G$2:$G$263,$C8) | F8: =IF($E8=0,"",SUMIFS('装备总表'!$W$2:$W$263,'装备总表'!$D$2:$D$263,$A8,'装备总表'!$G$2:$G$263,$C8)/$E8) | G8: =IF($E8=0,"",MINIFS('装备总表'!$W$2:$W$263,'装备总表'!$D$2:$D$263,$A8,'装备总表'!$G$2:$G$263,$C8)) | H8: =IF($E8=0,"",MAXIFS('装备总表'!$W$2:$W$263,'装备总表'!$D$2:$D$263,$A8,'装备总表'!$G$2:$G$263,$C8)) | I8: =IF(OR($A8<>$A7,$E7=0),"",$F7) | J8: =IF(OR($I8="",$I8=0),"",$F8/$I8) | K8: =IF($J8="","",IF($J8>='强度系数说明'!$B$15,"通过","低于阈值"))
A9: helmet | B9: 头盔 | C9: orange | D9: 传说/橙 | E9: =COUNTIFS('装备总表'!$D$2:$D$263,$A9,'装备总表'!$G$2:$G$263,$C9) | F9: =IF($E9=0,"",SUMIFS('装备总表'!$W$2:$W$263,'装备总表'!$D$2:$D$263,$A9,'装备总表'!$G$2:$G$263,$C9)/$E9) | G9: =IF($E9=0,"",MINIFS('装备总表'!$W$2:$W$263,'装备总表'!$D$2:$D$263,$A9,'装备总表'!$G$2:$G$263,$C9)) | H9: =IF($E9=0,"",MAXIFS('装备总表'!$W$2:$W$263,'装备总表'!$D$2:$D$263,$A9,'装备总表'!$G$2:$G$263,$C9)) | I9: =IF(OR($A9<>$A8,$E8=0),"",$F8) | J9: =IF(OR($I9="",$I9=0),"",$F9/$I9) | K9: =IF($J9="","",IF($J9>='强度系数说明'!$B$15,"通过","低于阈值"))
A10: armor | B10: 护甲 | C10: black | D10: 普通/白 | E10: =COUNTIFS('装备总表'!$D$2:$D$263,$A10,'装备总表'!$G$2:$G$263,$C10) | F10: =IF($E10=0,"",SUMIFS('装备总表'!$W$2:$W$263,'装备总表'!$D$2:$D$263,$A10,'装备总表'!$G$2:$G$263,$C10)/$E10) | G10: =IF($E10=0,"",MINIFS('装备总表'!$W$2:$W$263,'装备总表'!$D$2:$D$263,$A10,'装备总表'!$G$2:$G$263,$C10)) | H10: =IF($E10=0,"",MAXIFS('装备总表'!$W$2:$W$263,'装备总表'!$D$2:$D$263,$A10,'装备总表'!$G$2:$G$263,$C10)) | I10: =IF(OR($A10<>$A9,$E9=0),"",$F9) | J10: =IF(OR($I10="",$I10=0),"",$F10/$I10) | K10: =IF($J10="","",IF($J10>='强度系数说明'!$B$15,"通过","低于阈值"))
A11: armor | B11: 护甲 | C11: green | D11: 优良/绿 | E11: =COUNTIFS('装备总表'!$D$2:$D$263,$A11,'装备总表'!$G$2:$G$263,$C11) | F11: =IF($E11=0,"",SUMIFS('装备总表'!$W$2:$W$263,'装备总表'!$D$2:$D$263,$A11,'装备总表'!$G$2:$G$263,$C11)/$E11) | G11: =IF($E11=0,"",MINIFS('装备总表'!$W$2:$W$263,'装备总表'!$D$2:$D$263,$A11,'装备总表'!$G$2:$G$263,$C11)) | H11: =IF($E11=0,"",MAXIFS('装备总表'!$W$2:$W$263,'装备总表'!$D$2:$D$263,$A11,'装备总表'!$G$2:$G$263,$C11)) | I11: =IF(OR($A11<>$A10,$E10=0),"",$F10) | J11: =IF(OR($I11="",$I11=0),"",$F11/$I11) | K11: =IF($J11="","",IF($J11>='强度系数说明'!$B$15,"通过","低于阈值"))
A12: armor | B12: 护甲 | C12: blue | D12: 稀有/蓝 | E12: =COUNTIFS('装备总表'!$D$2:$D$263,$A12,'装备总表'!$G$2:$G$263,$C12) | F12: =IF($E12=0,"",SUMIFS('装备总表'!$W$2:$W$263,'装备总表'!$D$2:$D$263,$A12,'装备总表'!$G$2:$G$263,$C12)/$E12) | G12: =IF($E12=0,"",MINIFS('装备总表'!$W$2:$W$263,'装备总表'!$D$2:$D$263,$A12,'装备总表'!$G$2:$G$263,$C12)) | H12: =IF($E12=0,"",MAXIFS('装备总表'!$W$2:$W$263,'装备总表'!$D$2:$D$263,$A12,'装备总表'!$G$2:$G$263,$C12)) | I12: =IF(OR($A12<>$A11,$E11=0),"",$F11) | J12: =IF(OR($I12="",$I12=0),"",$F12/$I12) | K12: =IF($J12="","",IF($J12>='强度系数说明'!$B$15,"通过","低于阈值"))
A13: armor | B13: 护甲 | C13: purple | D13: 史诗/紫 | E13: =COUNTIFS('装备总表'!$D$2:$D$263,$A13,'装备总表'!$G$2:$G$263,$C13) | F13: =IF($E13=0,"",SUMIFS('装备总表'!$W$2:$W$263,'装备总表'!$D$2:$D$263,$A13,'装备总表'!$G$2:$G$263,$C13)/$E13) | G13: =IF($E13=0,"",MINIFS('装备总表'!$W$2:$W$263,'装备总表'!$D$2:$D$263,$A13,'装备总表'!$G$2:$G$263,$C13)) | H13: =IF($E13=0,"",MAXIFS('装备总表'!$W$2:$W$263,'装备总表'!$D$2:$D$263,$A13,'装备总表'!$G$2:$G$263,$C13)) | I13: =IF(OR($A13<>$A12,$E12=0),"",$F12) | J13: =IF(OR($I13="",$I13=0),"",$F13/$I13) | K13: =IF($J13="","",IF($J13>='强度系数说明'!$B$15,"通过","低于阈值"))
A14: armor | B14: 护甲 | C14: orange | D14: 传说/橙 | E14: =COUNTIFS('装备总表'!$D$2:$D$263,$A14,'装备总表'!$G$2:$G$263,$C14) | F14: =IF($E14=0,"",SUMIFS('装备总表'!$W$2:$W$263,'装备总表'!$D$2:$D$263,$A14,'装备总表'!$G$2:$G$263,$C14)/$E14) | G14: =IF($E14=0,"",MINIFS('装备总表'!$W$2:$W$263,'装备总表'!$D$2:$D$263,$A14,'装备总表'!$G$2:$G$263,$C14)) | H14: =IF($E14=0,"",MAXIFS('装备总表'!$W$2:$W$263,'装备总表'!$D$2:$D$263,$A14,'装备总表'!$G$2:$G$263,$C14)) | I14: =IF(OR($A14<>$A13,$E13=0),"",$F13) | J14: =IF(OR($I14="",$I14=0),"",$F14/$I14) | K14: =IF($J14="","",IF($J14>='强度系数说明'!$B$15,"通过","低于阈值"))
A15: shoes | B15: 鞋履 | C15: black | D15: 普通/白 | E15: =COUNTIFS('装备总表'!$D$2:$D$263,$A15,'装备总表'!$G$2:$G$263,$C15) | F15: =IF($E15=0,"",SUMIFS('装备总表'!$W$2:$W$263,'装备总表'!$D$2:$D$263,$A15,'装备总表'!$G$2:$G$263,$C15)/$E15) | G15: =IF($E15=0,"",MINIFS('装备总表'!$W$2:$W$263,'装备总表'!$D$2:$D$263,$A15,'装备总表'!$G$2:$G$263,$C15)) | H15: =IF($E15=0,"",MAXIFS('装备总表'!$W$2:$W$263,'装备总表'!$D$2:$D$263,$A15,'装备总表'!$G$2:$G$263,$C15)) | I15: =IF(OR($A15<>$A14,$E14=0),"",$F14) | J15: =IF(OR($I15="",$I15=0),"",$F15/$I15) | K15: =IF($J15="","",IF($J15>='强度系数说明'!$B$15,"通过","低于阈值"))
A16: shoes | B16: 鞋履 | C16: green | D16: 优良/绿 | E16: =COUNTIFS('装备总表'!$D$2:$D$263,$A16,'装备总表'!$G$2:$G$263,$C16) | F16: =IF($E16=0,"",SUMIFS('装备总表'!$W$2:$W$263,'装备总表'!$D$2:$D$263,$A16,'装备总表'!$G$2:$G$263,$C16)/$E16) | G16: =IF($E16=0,"",MINIFS('装备总表'!$W$2:$W$263,'装备总表'!$D$2:$D$263,$A16,'装备总表'!$G$2:$G$263,$C16)) | H16: =IF($E16=0,"",MAXIFS('装备总表'!$W$2:$W$263,'装备总表'!$D$2:$D$263,$A16,'装备总表'!$G$2:$G$263,$C16)) | I16: =IF(OR($A16<>$A15,$E15=0),"",$F15) | J16: =IF(OR($I16="",$I16=0),"",$F16/$I16) | K16: =IF($J16="","",IF($J16>='强度系数说明'!$B$15,"通过","低于阈值"))
A17: shoes | B17: 鞋履 | C17: blue | D17: 稀有/蓝 | E17: =COUNTIFS('装备总表'!$D$2:$D$263,$A17,'装备总表'!$G$2:$G$263,$C17) | F17: =IF($E17=0,"",SUMIFS('装备总表'!$W$2:$W$263,'装备总表'!$D$2:$D$263,$A17,'装备总表'!$G$2:$G$263,$C17)/$E17) | G17: =IF($E17=0,"",MINIFS('装备总表'!$W$2:$W$263,'装备总表'!$D$2:$D$263,$A17,'装备总表'!$G$2:$G$263,$C17)) | H17: =IF($E17=0,"",MAXIFS('装备总表'!$W$2:$W$263,'装备总表'!$D$2:$D$263,$A17,'装备总表'!$G$2:$G$263,$C17)) | I17: =IF(OR($A17<>$A16,$E16=0),"",$F16) | J17: =IF(OR($I17="",$I17=0),"",$F17/$I17) | K17: =IF($J17="","",IF($J17>='强度系数说明'!$B$15,"通过","低于阈值"))
... A39: device | B39: 器械 | C39: orange | D39: 传说/橙 | E39: =COUNTIFS('装备总表'!$D$2:$D$263,$A39,'装备总表'!$G$2:$G$263,$C39) | F39: =IF($E39=0,"",SUMIFS('装备总表'!$W$2:$W$263,'装备总表'!$D$2:$D$263,$A39,'装备总表'!$G$2:$G$263,$C39)/$E39) | G39: =IF($E39=0,"",MINIFS('装备总表'!$W$2:$W$263,'装备总表'!$D$2:$D$263,$A39,'装备总表'!$G$2:$G$263,$C39)) | H39: =IF($E39=0,"",MAXIFS('装备总表'!$W$2:$W$263,'装备总表'!$D$2:$D$263,$A39,'装备总表'!$G$2:$G$263,$C39)) | I39: =IF(OR($A39<>$A38,$E38=0),"",$F38) | J39: =IF(OR($I39="",$I39=0),"",$F39/$I39) | K39: =IF($J39="","",IF($J39>='强度系数说明'!$B$15,"通过","低于阈值"))

Sheet 套装效果
A1: 装备套装效果明细
A3: 说明 | B3: 套装效果从 item_templates.yaml 的 effect_payload.set_bonus 拆分；基础单件强度评分不包含套装效果。
A4: 套装key | B4: 套装描述 | C4: 需要件数 | D4: 攻击 | E4: 防御 | F4: 生命 | G4: 武力 | H4: 智力 | I4: 敏捷 | J4: 运势 | K4: 带兵上限 | L4: 套装效果(JSON) | M4: 装备数量 | N4: 涉及装备key
A5: kasukabe_defense_set | B5: 春日部防卫队 | C5: 2 | D5: 30 | E5: 20 | F5: 0 | G5: 0 | H5: 0 | I5: 0 | J5: 0 | K5: 0 | L5: {"attack":30,"defense":20} | M5: 5 | N5: equip_action_mask, equip_shiro_leash, equip_kasukabe_satchel, equip_action_beam_glove, equip_nohara_pan
A6: kasukabe_defense_set | B6: 春日部防卫队 | C6: 4 | D6: 0 | E6: 0 | F6: 600 | G6: 0 | H6: 0 | I6: 20 | J6: 15 | K6: 0 | L6: {"agility":20,"hp":600,"luck":15} | M6: 5 | N6: equip_action_mask, equip_shiro_leash, equip_kasukabe_satchel, equip_action_beam_glove, equip_nohara_pan
A7: starter_cloth_set | B7: 一蓑烟雨 | C7: 4 | D7: 0 | E7: 0 | F7: 200 | G7: 20 | H7: 0 | I7: 0 | J7: 15 | K7: 20 | L7: {"force":20,"hp":200,"luck":15,"troop_capacity":20} | M7: 4 | N7: equip_caomao, equip_suoyi, equip_caoxie, equip_tiejian
A8: yeman_set | B8: 野蛮套装 | C8: 2 | D8: 0 | E8: 10 | F8: 300 | G8: 25 | H8: 0 | I8: 0 | J8: 0 | K8: 0 | L8: {"defense":10,"force":25,"hp":300} | M8: 2 | N8: equip_yemantoukie, equip_yemankandao
A9: xiaowei_set | B9: 校尉套装 | C9: 4 | D9: 0 | E9: 15 | F9: 360 | G9: 40 | H9: 0 | I9: 0 | J9: 0 | K9: 100 | L9: {"defense":15,"force":40,"hp":360,"troop_capacity":100} | M9: 4 | N9: equip_xiaoweitoukui, equip_xiaoweikaijia, equip_xiaoweichangxue, equip_xiaoweichangjian
A10: jiaodoushi_set | B10: 角斗士套装 | C10: 4 | D10: 0 | E10: 10 | F10: 280 | G10: 30 | H10: 0 | I10: 15 | J10: 0 | K10: 0 | L10: {"agility":15,"defense":10,"force":30,"hp":280} | M10: 4 | N10: equip_jiaodoushitoukui, equip_jiaodoushixiongjia, equip_jiaodoushizhixue, equip_jiaodoushizhichui
A11: sixiang_set | B11: 四象套装 | C11: 4 | D11: 0 | E11: 0 | F11: 360 | G11: 35 | H11: 35 | I11: 20 | J11: 0 | K11: 0 | L11: {"agility":20,"force":35,"hp":360,"intellect":35} | M11: 4 | N11: equip_qinglongkui, equip_qinglongjia, equip_qinglongxue, equip_qinglongdao
A12: qilin_set | B12: 麒麟套装 | C12: 4 | D12: 0 | E12: 0 | F12: 420 | G12: 38 | H12: 0 | I12: 18 | J12: 30 | K12: 0 | L12: {"agility":18,"force":38,"hp":420,"luck":30} | M12: 5 | N12: equip_qilinkui, equip_qilinjia, equip_qilinxue, equip_qilindao, equip_qilinzui
A13: fengling_set | B13: 凤翎套装 | C13: 3 | D13: 0 | E13: 0 | F13: 0 | G13: 0 | H13: 60 | I13: 0 | J13: 30 | K13: 0 | L13: {"intellect":60,"luck":30} | M13: 3 | N13: equip_fenglingguan, equip_fenglingshan, equip_fenghuangyu
A14: xuanwu_set | B14: 玄武套装 | C14: 4 | D14: 0 | E14: 70 | F14: 260 | G14: 20 | H14: 0 | I14: 0 | J14: 0 | K14: 0 | L14: {"defense":70,"force":20,"hp":260} | M14: 4 | N14: equip_xuanwukui, equip_xuanwujia, equip_xuanwuxue, equip_xuanwuchui
A15: nichang_set | B15: 霓裳 | C15: 3 | D15: 0 | E15: 0 | F15: 150 | G15: 0 | H15: 20 | I15: 10 | J15: 15 | K15: 0 | L15: {"agility":10,"hp":150,"intellect":20,"luck":15} | M15: 3 | N15: equip_nichangyuyi, equip_nichangwuxie, equip_nichangjian
A16: huxian_set | B16: 狐仙套装 | C16: 3 | D16: 0 | E16: 0 | F16: 280 | G16: 0 | H16: 64 | I16: 0 | J16: 18 | K16: 0 | L16: {"hp":280,"intellect":64,"luck":18} | M16: 3 | N16: equip_huxianpao, equip_huxianxie, equip_huxianjian

Sheet 核对摘要
A1: 装备属性核对摘要
A3: 生成时间 | B3: 2026-08-22 17:23:51 +0800
A4: 装备数据源 | B4: data/item_templates.yaml（当前工作区）
A5: 锻造数据源 | B5: data/forge_equipment.yaml（当前工作区）
A7: 核对指标
A8: 指标 | B8: 结果 | C8: 核对说明
A9: 装备总数 | B9: =COUNTA('装备总表'!$B$2:$B$263) | C9: 应覆盖 item_templates.yaml 中全部 effect_type=equip_* 的模板
A10: 可锻造装备数 | B10: =COUNTIF('装备总表'!$Y$2:$Y$263,"是") | C10: 仅统计存在 forge_equipment.yaml 配置的装备
A11: 套装效果条目数 | B11: =COUNTA('套装效果'!$A$5:$A$16) | C11: 按套装阈值拆行，不是套装数量
A12: 基础强度最低值 | B12: =MIN('装备总表'!$W$2:$W$263) | C12: 固定评分公式结果
A13: 基础强度最高值 | B13: =MAX('装备总表'!$W$2:$W$263) | C13: 固定评分公式结果
A14: 基础强度平均值 | B14: =AVERAGE('装备总表'!$W$2:$W$263) | C14: 固定评分公式结果
A17: 重点口径
A18: 1. 装备总表的基础强度评分是当前装备平衡测试使用的固定公式，不是最终战斗战力。
A19: 2. 动态候选 Power 是虚拟玩家装备候选选择的静态输入；动态候选权重还依赖成长阶段、角色适配和门客属性。
A20: 3. 套装效果单独列出，未混入单件基础强度评分，便于分别核对。
A21: 4. 本表由当前工作区 YAML 重新生成，未沿用已有 reports/equipment_catalog.xlsx 的历史属性值。
