Workbook

Sheet 任务列表
A1: 序号 | B1: 任务key | C1: 任务名称 | D1: 难度 | E1: 战斗类型 | F1: 防守任务 | G1: 仅门客 | H1: 每日次数 | I1: 配置基础耗时秒 | J1: 开放星期 | K1: 进入消耗 | L1: 敌方门客数 | M1: 敌方护院总数 | N1: 掉落明细数 | O1: 固定项数 | P1: 概率项数 | Q1: 任务分类 | R1: 每周次数(帮会) | S1: 任务卡每日上限 | T1: 任务描述 | U1: 敌方统一科技等级 | V1: 敌方门客等级 | W1: 敌方门客属性加成 | X1: 固定奖励摘要 | Y1: 随机奖励摘要 | Z1: 显示排序配置 | AA1: 启用状态 | AB1: 推荐门客数(帮会) | AC1: 数据来源 | AD1: 进入消耗(JSON) | AE1: 敌方科技(JSON) | AF1: 原始任务配置(JSON) | AG1: 发起行动点消耗 | AH1: 奖励接收方
A2: 1 | B2: mid_autumn_moon_palace_trial | C2: 广寒宫试炼 | D2: 中级 | E2: task1 | F2: 否 | G2: 否 | H2: 3 | I2: 1800 | J2: 周二、周四、周六、周日 | K2: 无 | L2: =SUMIFS(敌方阵容!$F$2:$F$258,敌方阵容!$A$2:$A$258,B2,敌方阵容!$D$2:$D$258,"门客") -> 3 | M2: =SUMIFS(敌方阵容!$F$2:$F$258,敌方阵容!$A$2:$A$258,B2,敌方阵容!$D$2:$D$258,"护院") -> 800 | N2: =COUNTIF(任务掉落明细!$B$2:$B$66,B2) -> 2 | O2: =COUNTIFS(任务掉落明细!$B$2:$B$66,B2,任务掉落明细!$X$2:$X$66,1) -> 2 | P2: =COUNTIFS(任务掉落明细!$B$2:$B$66,B2,任务掉落明细!$X$2:$X$66,"<1") -> 0 | Q2: 个人任务 | S2: 5 | T2: 中秋将近，广寒宫外的月桂忽然枝叶疯长，遮蔽月华，连玉兔捣药的石臼也被散落的桂枝掩埋。吴刚日夜挥斧仍无法遏止异变，嫦娥只得向人间庄园主发出月宫请帖。 受邀者需穿过桂影迷阵，协助玉兔收集药材，并通过吴刚与嫦娥设下的月宫试炼。完成试炼者可带回月饼，也有机会获得三位月宫门客留下的召唤卷轴。 | U2: 7 | V2: 60 | W2: 0.12 | X2: 银两×40000；广寒宫试炼宝箱×1 | Y2: 开箱奖励及概率见宝箱奖励明细 | Z2: 1000 | AA2: 按配置导入 | AC2: data/mission_templates.yaml:mid_autumn_moon_palace_trial | AD2: {} | AE2: {"level":7,"guest_level":60,"guest_bonus":0.12} | AF2: {"key":"mid_autumn_moon_palace_trial","name":"广寒宫试炼","difficulty":"intermediate","available_weekdays":[2,4,6,7],"description":"中秋将近，广寒宫外的月桂忽然枝叶疯长，遮蔽月华，连玉兔捣药的石臼也被散落的桂枝掩埋。吴刚日夜挥斧仍无法遏止异变，嫦娥只得向人间庄园主发出月宫请帖。\n\n受邀者需穿过桂影迷阵，协助玉兔收集药材，并通过吴刚与嫦娥设下的月宫试炼。完成试炼者可带回月饼，也有机会获得三位月宫门客留下的召唤卷轴。\n","battle_type":"task1","base_travel_time":1800,"enemy_guests":[{"key":"myth_moon_jade_rabbit","label":"玉兔"},{"key":"myth_moon_wu_gang","label":"吴刚"},{"key":"hist_xianqin_0413","label":"嫦娥"}],"enemy_troops":{"quan_wang":300,"jian_hao":300,"divine_archer":200},"enemy_technology":{"level":7,"guest_level":60,"guest_bonus":0.12},"drop_table":{"silver":40000,"mission_chest_mid_autumn_moon_palace_trial":1},"daily_limit":3} | AG2: 10 | AH2: 挑战者庄园
A3: 2 | B3: kasukabe_daisakusen | C3: 春日部大作战 | D3: 中级 | E3: task1 | F3: 否 | G3: 否 | H3: 3 | I3: 1800 | J3: 周二、周四、周六、周日 | K3: 无 | L3: =SUMIFS(敌方阵容!$F$2:$F$258,敌方阵容!$A$2:$A$258,B3,敌方阵容!$D$2:$D$258,"门客") -> 5 | M3: =SUMIFS(敌方阵容!$F$2:$F$258,敌方阵容!$A$2:$A$258,B3,敌方阵容!$D$2:$D$258,"护院") -> 800 | N3: =COUNTIF(任务掉落明细!$B$2:$B$66,B3) -> 2 | O3: =COUNTIFS(任务掉落明细!$B$2:$B$66,B3,任务掉落明细!$X$2:$X$66,1) -> 2 | P3: =COUNTIFS(任务掉落明细!$B$2:$B$66,B3,任务掉落明细!$X$2:$X$66,"<1") -> 0 | Q3: 个人任务 | S3: 5 | T3: 庄园附近突然出现一支自称“春日部防卫队”的神秘队伍。他们本是追查被妖怪夺走的神奇蜡笔，却不慎把庄园周边画成了临时游乐战场：粮仓墙上长出大象鼻子，演武场地面变成蹦床，护院巡逻路线也被涂鸦迷宫搅得七零八落。 为了平息这场哭笑不得的混乱，庄主需要进入春日部游乐战场，突破玩具机关、恶作剧陷阱和防卫队试炼，击败被蜡笔力量影响的涂鸦大魔王，回收“小新的蜡笔”。集齐150个蜡笔后，可在仓库中招募紫色武门客「蜡笔小新」。 | U3: 7 | V3: 60 | W3: 0.12 | X3: 银两×40000；春日部大作战宝箱×1 | Y3: 开箱奖励及概率见宝箱奖励明细 | Z3: 1000 | AA3: 按配置导入 | AC3: data/mission_templates.yaml:kasukabe_daisakusen | AD3: {} | AE3: {"level":7,"guest_level":60,"guest_bonus":0.12} | AF3: {"key":"kasukabe_daisakusen","name":"春日部大作战","difficulty":"intermediate","available_weekdays":[2,4,6,7],"description":"庄园附近突然出现一支自称“春日部防卫队”的神秘队伍。他们本是追查被妖怪夺走的神奇蜡笔，却不慎把庄园周边画成了临时游乐战场：粮仓墙上长出大象鼻子，演武场地面变成蹦床，护院巡逻路线也被涂鸦迷宫搅得七零八落。\n\n为了平息这场哭笑不得的混乱，庄主需要进入春日部游乐战场，突破玩具机关、恶作剧陷阱和防卫队试炼，击败被蜡笔力量影响的涂鸦大魔王，回收“小新的蜡笔”。集齐150个蜡笔后，可在仓库中招募紫色武门客「蜡笔小新」。\n","battle_type":"task1","enemy_guests":[{"key":"task_kasukabe_patrol_captain","label":"春日部巡逻队长"},{"key":"task_kasukabe_toy_crocodile","label":"玩具机关鳄鱼"},{"key":"task_kasukabe_defense_member","label":"迷路的防卫队员"},{"key":"task_kasukabe_crayon_clone","label":"蜡笔恶作剧分身"},{"key":"task_kasukabe_doodle_boss","label":"涂鸦大魔王"}],"enemy_troops":{"quan_wang":300,"archer":300,"dao_ba":200},"enemy_technology":{"level":7,"guest_level":60,"guest_bonus":0.12},"drop_table":{"silver":40000,"mission_chest_kasukabe_daisakusen":1},"daily_limit":3} | AG3: 10 | AH3: 挑战者庄园
A4: 3 | B4: huashan_lunjian | C4: 华山论贱 | D4: 初级 | E4: task1 | F4: 否 | G4: 是 | H4: 3 | I4: 1800 | J4: 每日开放 | K4: 无 | L4: =SUMIFS(敌方阵容!$F$2:$F$258,敌方阵容!$A$2:$A$258,B4,敌方阵容!$D$2:$D$258,"门客") -> 4 | M4: =SUMIFS(敌方阵容!$F$2:$F$258,敌方阵容!$A$2:$A$258,B4,敌方阵容!$D$2:$D$258,"护院") -> 0 | N4: =COUNTIF(任务掉落明细!$B$2:$B$66,B4) -> 2 | O4: =COUNTIFS(任务掉落明细!$B$2:$B$66,B4,任务掉落明细!$X$2:$X$66,1) -> 2 | P4: =COUNTIFS(任务掉落明细!$B$2:$B$66,B4,任务掉落明细!$X$2:$X$66,"<1") -> 0 | Q4: 个人任务 | S4: 5 | T4: 中原大地，经过无数年的风吹雨打，各大贱派均元气大伤，数百年的休养调整使各大贱客高手知耻后勇，不断创新各种贱术秘籍，停办经年的贱客比武大赛将顺应民意在华山之巅重新开启，各路英雄贱客可在此大展身手，争当新一届人见人爱、花见花开的贱客之王，在此和谐社会留下自己奋斗的印记。 | U4: 2 | V4: 12 | W4: 0 | X4: 银两×8000；华山论贱宝箱×1 | Y4: 开箱奖励及概率见宝箱奖励明细 | Z4: 2 | AA4: 按配置导入 | AC4: data/mission_templates.yaml:huashan_lunjian | AD4: {} | AE4: {"level":2,"guest_level":12,"guest_bonus":0} | AF4: {"key":"huashan_lunjian","name":"华山论贱","display_order":2,"difficulty":"junior","description":"中原大地，经过无数年的风吹雨打，各大贱派均元气大伤，数百年的休养调整使各大贱客高手知耻后勇，不断创新各种贱术秘籍，停办经年的贱客比武大赛将顺应民意在华山之巅重新开启，各路英雄贱客可在此大展身手，争当新一届人见人爱、花见花开的贱客之王，在此和谐社会留下自己奋斗的印记。\n","battle_type":"task1","guest_only":true,"enemy_guests":[{"key":"task_huashan_jianwang","label":"贱王之王"},{"key":"task_huashan_jianjing","label":"顶级贱精"},{"key":"task_huashan_jianjing","label":"顶级贱精"},{"key":"task_huashan_audience_a","label":"观众甲"}],"enemy_technology":{"level":2,"guest_level":12,"guest_bonus":0},"drop_table":{"silver":8000,"mission_chest_huashan_lunjian":1},"daily_limit":3} | AG4: 10 | AH4: 挑战者庄园
A5: 4 | B5: wagangzhai_nixi | C5: 瓦岗寨的逆袭 | D5: 中级 | E5: task1 | F5: 是 | G5: 否 | H5: 3 | I5: 1800 | J5: 每日开放 | K5: 无 | L5: =SUMIFS(敌方阵容!$F$2:$F$258,敌方阵容!$A$2:$A$258,B5,敌方阵容!$D$2:$D$258,"门客") -> 6 | M5: =SUMIFS(敌方阵容!$F$2:$F$258,敌方阵容!$A$2:$A$258,B5,敌方阵容!$D$2:$D$258,"护院") -> 2400 | N5: =COUNTIF(任务掉落明细!$B$2:$B$66,B5) -> 2 | O5: =COUNTIFS(任务掉落明细!$B$2:$B$66,B5,任务掉落明细!$X$2:$X$66,1) -> 2 | P5: =COUNTIFS(任务掉落明细!$B$2:$B$66,B5,任务掉落明细!$X$2:$X$66,"<1") -> 0 | Q5: 个人任务 | S5: 5 | T5: 在上一次广大庄园主联手扫荡瓦岗寨时，正值瓦岗五虎出门执行任务，翟让和程咬金输的并不服气，为了证明瓦岗寨的实力，翟让率领瓦岗五虎"秦叔宝"、"单雄信"、"王伯当"、"罗成"、"程咬金"携山寨喽啰兵600人亲自上各庄园寻衅……这一次的战场变成了您的庄园，请加强防御设施，让您的门客和护院准备好迎接战斗洗礼。 | U5: 10 | V5: 100 | W5: 0.3 | X5: 银两×40000；瓦岗寨的逆袭宝箱×1 | Y5: 开箱奖励及概率见宝箱奖励明细 | Z5: 7 | AA5: 按配置导入 | AC5: data/mission_templates.yaml:wagangzhai_nixi | AD5: {} | AE5: {"level":10,"guest_level":100,"guest_bonus":0.3} | AF5: {"key":"wagangzhai_nixi","name":"瓦岗寨的逆袭","difficulty":"intermediate","description":"在上一次广大庄园主联手扫荡瓦岗寨时，正值瓦岗五虎出门执行任务，翟让和程咬金输的并不服气，为了证明瓦岗寨的实力，翟让率领瓦岗五虎\"秦叔宝\"、\"单雄信\"、\"王伯当\"、\"罗成\"、\"程咬金\"携山寨喽啰兵600人亲自上各庄园寻衅……这一次的战场变成了您的庄园，请加强防御设施，让您的门客和护院准备好迎接战斗洗礼。\n","battle_type":"task1","is_defense":true,"display_order":7,"enemy_guests":[{"key":"hist_suitang_0162_zhairang","skills":["tangseng_sermon"]},{"key":"hero_qin_shubao","skills":["brahma_true_fire"]},"hist_suitang_0164_shanxiongxin","hist_suitang_0165_wangbodang","hero_luo_cheng","hero_cheng_yaojin"],"enemy_technology":{"level":10,"guest_level":100,"guest_bonus":0.3},"enemy_troops":{"arrow_god":800,"quan_sheng":800,"qiang_wang":800},"drop_table":{"silver":40000,"mission_chest_wagangzhai_nixi":1},"base_travel_time":1800,"daily_limit":3} | AG5: 10 | AH5: 挑战者庄园
A6: 5 | B6: jingyanggang | C6: 景阳冈 | D6: 初级 | E6: task1 | F6: 否 | G6: 是 | H6: 3 | I6: 1800 | J6: 每日开放 | K6: 无 | L6: =SUMIFS(敌方阵容!$F$2:$F$258,敌方阵容!$A$2:$A$258,B6,敌方阵容!$D$2:$D$258,"门客") -> 1 | M6: =SUMIFS(敌方阵容!$F$2:$F$258,敌方阵容!$A$2:$A$258,B6,敌方阵容!$D$2:$D$258,"护院") -> 0 | N6: =COUNTIF(任务掉落明细!$B$2:$B$66,B6) -> 2 | O6: =COUNTIFS(任务掉落明细!$B$2:$B$66,B6,任务掉落明细!$X$2:$X$66,1) -> 2 | P6: =COUNTIFS(任务掉落明细!$B$2:$B$66,B6,任务掉落明细!$X$2:$X$66,"<1") -> 0 | Q6: 个人任务 | S6: 5 | T6: 景阳冈上有只吊睛白额大虫伤害人命，官府多次派猎户擒捉未果，往客商人只能在巳午未三个时辰结伴过冈，其馀时分，及单身客人，不能过冈，恐被伤害性命。 | U6: 3 | V6: 15 | W6: 0.02 | X6: 银两×7000；景阳冈宝箱×1 | Y6: 开箱奖励及概率见宝箱奖励明细 | Z6: 1 | AA6: 按配置导入 | AC6: data/mission_templates.yaml:jingyanggang | AD6: {} | AE6: {"level":3,"guest_level":15,"guest_bonus":0.02} | AF6: {"key":"jingyanggang","name":"景阳冈","display_order":1,"difficulty":"junior","description":"景阳冈上有只吊睛白额大虫伤害人命，官府多次派猎户擒捉未果，往客商人只能在巳午未三个时辰结伴过冈，其馀时分，及单身客人，不能过冈，恐被伤害性命。\n","battle_type":"task1","guest_only":true,"enemy_guests":[{"key":"task_jingyang_tiger","label":"猛虎"}],"enemy_technology":{"level":3,"guest_level":15,"guest_bonus":0.02},"drop_table":{"silver":7000,"mission_chest_jingyanggang":1},"daily_limit":3} | AG6: 10 | AH6: 挑战者庄园
A7: 6 | B7: wulongshan | C7: 乌龙山 | D7: 初级 | E7: task1 | F7: 否 | G7: 否 | H7: 3 | I7: 1800 | J7: 每日开放 | K7: 无 | L7: =SUMIFS(敌方阵容!$F$2:$F$258,敌方阵容!$A$2:$A$258,B7,敌方阵容!$D$2:$D$258,"门客") -> 2 | M7: =SUMIFS(敌方阵容!$F$2:$F$258,敌方阵容!$A$2:$A$258,B7,敌方阵容!$D$2:$D$258,"护院") -> 200 | N7: =COUNTIF(任务掉落明细!$B$2:$B$66,B7) -> 2 | O7: =COUNTIFS(任务掉落明细!$B$2:$B$66,B7,任务掉落明细!$X$2:$X$66,1) -> 2 | P7: =COUNTIFS(任务掉落明细!$B$2:$B$66,B7,任务掉落明细!$X$2:$X$66,"<1") -> 0 | Q7: 个人任务 | S7: 5 | T7: 湘黔边界的乌龙山鲜少人迹，这里盘聚着一帮强盗将那里作为他们的大本营。他们借这乱世之际四处行凶，烧杀凌掠无恶不作，种种罪行令人发指。由于此帮强盗行迹过于放肆导致朝野上下为之震动，朝廷号召各方能人尽快歼灭这帮流寇。 | U7: 4 | V7: 20 | W7: 0.04 | X7: 银两×15000；乌龙山宝箱×1 | Y7: 开箱奖励及概率见宝箱奖励明细 | Z7: 4 | AA7: 按配置导入 | AC7: data/mission_templates.yaml:wulongshan | AD7: {} | AE7: {"level":4,"guest_level":20,"guest_bonus":0.04} | AF7: {"key":"wulongshan","name":"乌龙山","difficulty":"junior","display_order":4,"description":"湘黔边界的乌龙山鲜少人迹，这里盘聚着一帮强盗将那里作为他们的大本营。他们借这乱世之际四处行凶，烧杀凌掠无恶不作，种种罪行令人发指。由于此帮强盗行迹过于放肆导致朝野上下为之震动，朝廷号召各方能人尽快歼灭这帮流寇。\n","battle_type":"task1","enemy_guests":[{"key":"task_wulong_bandit_chief_zuanshanbao","label":"钻山豹"},{"key":"task_wulong_bandit_chief_zuoshandiao","label":"座山雕"}],"enemy_technology":{"level":4,"guest_level":20,"guest_bonus":0.04},"enemy_troops":{"qiang_ke":200},"drop_table":{"silver":15000,"mission_chest_wulongshan":1},"daily_limit":3} | AG7: 10 | AH7: 挑战者庄园
A8: 7 | B8: wagangzhai | C8: 瓦岗寨 | D8: 初级 | E8: task1 | F8: 否 | G8: 否 | H8: 3 | I8: 1800 | J8: 每日开放 | K8: 无 | L8: =SUMIFS(敌方阵容!$F$2:$F$258,敌方阵容!$A$2:$A$258,B8,敌方阵容!$D$2:$D$258,"门客") -> 2 | M8: =SUMIFS(敌方阵容!$F$2:$F$258,敌方阵容!$A$2:$A$258,B8,敌方阵容!$D$2:$D$258,"护院") -> 400 | N8: =COUNTIF(任务掉落明细!$B$2:$B$66,B8) -> 2 | O8: =COUNTIFS(任务掉落明细!$B$2:$B$66,B8,任务掉落明细!$X$2:$X$66,1) -> 2 | P8: =COUNTIFS(任务掉落明细!$B$2:$B$66,B8,任务掉落明细!$X$2:$X$66,"<1") -> 0 | Q8: 个人任务 | S8: 5 | T8: 瓦岗寨原来的寨主翟让被程咬金击败后让出寨主之位，程咬金自号"大魔国混世魔王"，并带领瓦岗军四处出门踢馆打劫，引得各地庄园主怨声在道，大家决定联手打击瓦岗寨，维护和保障各庄园的和平与稳定。 | U8: 5 | V8: 35 | W8: 0.1 | X8: 银两×20000；瓦岗寨宝箱×1 | Y8: 开箱奖励及概率见宝箱奖励明细 | Z8: 5 | AA8: 按配置导入 | AC8: data/mission_templates.yaml:wagangzhai | AD8: {} | AE8: {"level":5,"guest_level":35,"guest_bonus":0.1} | AF8: {"key":"wagangzhai","name":"瓦岗寨","difficulty":"junior","display_order":5,"description":"瓦岗寨原来的寨主翟让被程咬金击败后让出寨主之位，程咬金自号\"大魔国混世魔王\"，并带领瓦岗军四处出门踢馆打劫，引得各地庄园主怨声在道，大家决定联手打击瓦岗寨，维护和保障各庄园的和平与稳定。\n","battle_type":"task1","enemy_guests":["hero_cheng_yaojin","hist_suitang_0162_zhairang"],"enemy_troops":{"jian_xia":400},"enemy_technology":{"level":5,"guest_level":35,"guest_bonus":0.1},"drop_table":{"silver":20000,"mission_chest_wagangzhai":1},"daily_limit":3} | AG8: 10 | AH8: 挑战者庄园
A9: 8 | B9: fugui_shanzhuang | C9: 富贵山庄 | D9: 初级 | E9: task1 | F9: 否 | G9: 是 | H9: 3 | I9: 1800 | J9: 每日开放 | K9: 无 | L9: =SUMIFS(敌方阵容!$F$2:$F$258,敌方阵容!$A$2:$A$258,B9,敌方阵容!$D$2:$D$258,"门客") -> 1 | M9: =SUMIFS(敌方阵容!$F$2:$F$258,敌方阵容!$A$2:$A$258,B9,敌方阵容!$D$2:$D$258,"护院") -> 0 | N9: =COUNTIF(任务掉落明细!$B$2:$B$66,B9) -> 2 | O9: =COUNTIFS(任务掉落明细!$B$2:$B$66,B9,任务掉落明细!$X$2:$X$66,1) -> 2 | P9: =COUNTIFS(任务掉落明细!$B$2:$B$66,B9,任务掉落明细!$X$2:$X$66,"<1") -> 0 | Q9: 个人任务 | S9: 5 | T9: 富贵山庄，其美甲天下、其富可敌国，庄主张富贵更是好客之人，但凡江湖有难，他都不遗余力伸出援助之手，解人燃眉。故被人予以"雪中炭"之美名。江湖多有时运不济、怀才不遇的落魄之士，若想求得张庄主帮助，必先证明自己才识。在接受庄主考验后，若能得到庄主赏识，则日后必荣禄相授。 | U9: 3 | V9: 40 | W9: 0.05 | X9: 银两×14000；富贵山庄宝箱×1 | Y9: 开箱奖励及概率见宝箱奖励明细 | Z9: 3 | AA9: 按配置导入 | AC9: data/mission_templates.yaml:fugui_shanzhuang | AD9: {} | AE9: {"level":3,"guest_level":40,"guest_bonus":0.05} | AF9: {"key":"fugui_shanzhuang","name":"富贵山庄","difficulty":"junior","display_order":3,"description":"富贵山庄，其美甲天下、其富可敌国，庄主张富贵更是好客之人，但凡江湖有难，他都不遗余力伸出援助之手，解人燃眉。故被人予以\"雪中炭\"之美名。江湖多有时运不济、怀才不遇的落魄之士，若想求得张庄主帮助，必先证明自己才识。在接受庄主考验后，若能得到庄主赏识，则日后必荣禄相授。\n","battle_type":"task1","guest_only":true,"enemy_guests":[{"key":"task_fugui_instructor","label":"武师教头"}],"enemy_technology":{"level":3,"guest_level":40,"guest_bonus":0.05},"drop_table":{"silver":14000,"mission_chest_fugui_shanzhuang":1},"daily_limit":3} | AG9: 10 | AH9: 挑战者庄园
A10: 9 | B10: shizipo_heidian | C10: 十字坡黑店 | D10: 中级 | E10: task1 | F10: 否 | G10: 否 | H10: 3 | I10: 1800 | J10: 每日开放 | K10: 无 | L10: =SUMIFS(敌方阵容!$F$2:$F$258,敌方阵容!$A$2:$A$258,B10,敌方阵容!$D$2:$D$258,"门客") -> 2 | M10: =SUMIFS(敌方阵容!$F$2:$F$258,敌方阵容!$A$2:$A$258,B10,敌方阵容!$D$2:$D$258,"护院") -> 700 | N10: =COUNTIF(任务掉落明细!$B$2:$B$66,B10) -> 2 | O10: =COUNTIFS(任务掉落明细!$B$2:$B$66,B10,任务掉落明细!$X$2:$X$66,1) -> 2 | P10: =COUNTIFS(任务掉落明细!$B$2:$B$66,B10,任务掉落明细!$X$2:$X$66,"<1") -> 0 | Q10: 个人任务 | S10: 5 | T10: 孙二娘和张青在十字坡开酒店，常用蒙汗药蒙翻过往行人。他们将行人杀死后，大块好肉当作黄牛肉卖，零碎小肉，做馅包馒头。江湖有传言说："大树十字坡，客人谁敢那里过？肥的切做馒头馅，瘦的却丢去填河。" | U10: 6 | V10: 70 | W10: 0.1 | X10: 银两×30000；十字坡黑店宝箱×1 | Y10: 开箱奖励及概率见宝箱奖励明细 | Z10: 5 | AA10: 按配置导入 | AC10: data/mission_templates.yaml:shizipo_heidian | AD10: {} | AE10: {"level":6,"guest_level":70,"guest_bonus":0.1} | AF10: {"key":"shizipo_heidian","name":"十字坡黑店","difficulty":"intermediate","display_order":5,"description":"孙二娘和张青在十字坡开酒店，常用蒙汗药蒙翻过往行人。他们将行人杀死后，大块好肉当作黄牛肉卖，零碎小肉，做馅包馒头。江湖有传言说：\"大树十字坡，客人谁敢那里过？肥的切做馒头馅，瘦的却丢去填河。\"\n","battle_type":"task1","enemy_guests":[{"key":"task_shizipo_sun_erniang","label":"孙二娘"},{"key":"task_shizipo_zhang_qing","label":"张青"}],"enemy_troops":{"quan_wang":300,"divine_archer":300,"dao_ba":100},"enemy_technology":{"level":6,"guest_level":70,"guest_bonus":0.1},"drop_table":{"silver":30000,"mission_chest_shizipo_heidian":1},"daily_limit":3} | AG10: 10 | AH10: 挑战者庄园
A11: 10 | B11: shanhaiguan | C11: 山海关 | D11: 中级 | E11: task1 | F11: 否 | G11: 否 | H11: 3 | I11: 1800 | J11: 每日开放 | K11: 无 | L11: =SUMIFS(敌方阵容!$F$2:$F$258,敌方阵容!$A$2:$A$258,B11,敌方阵容!$D$2:$D$258,"门客") -> 2 | M11: =SUMIFS(敌方阵容!$F$2:$F$258,敌方阵容!$A$2:$A$258,B11,敌方阵容!$D$2:$D$258,"护院") -> 1500 | N11: =COUNTIF(任务掉落明细!$B$2:$B$66,B11) -> 2 | O11: =COUNTIFS(任务掉落明细!$B$2:$B$66,B11,任务掉落明细!$X$2:$X$66,1) -> 2 | P11: =COUNTIFS(任务掉落明细!$B$2:$B$66,B11,任务掉落明细!$X$2:$X$66,"<1") -> 0 | Q11: 个人任务 | S11: 5 | T11: 山海关所在的河西走廊是华北通向东北的咽喉地带，是一座及其重要的军事重镇，主要防御外族势力的入侵。吴三桂作为镇守山海关的大将，居然意图勾结外族势力，入侵中原。 | U11: 7 | V11: 70 | W11: 0.18 | X11: 银两×40000；山海关宝箱×1 | Y11: 开箱奖励及概率见宝箱奖励明细 | Z11: 6 | AA11: 按配置导入 | AC11: data/mission_templates.yaml:shanhaiguan | AD11: {} | AE11: {"level":7,"guest_level":70,"guest_bonus":0.18} | AF11: {"key":"shanhaiguan","name":"山海关","difficulty":"intermediate","display_order":6,"description":"山海关所在的河西走廊是华北通向东北的咽喉地带，是一座及其重要的军事重镇，主要防御外族势力的入侵。吴三桂作为镇守山海关的大将，居然意图勾结外族势力，入侵中原。\n","battle_type":"task1","enemy_guests":["hist_mingqing_0230","hist_mingqing_0054"],"enemy_troops":{"jian_sheng":500,"quan_wang":500,"qiang_ba":500},"enemy_technology":{"level":7,"guest_level":70,"guest_bonus":0.18},"drop_table":{"silver":40000,"mission_chest_shanhaiguan":1},"daily_limit":3} | AG11: 10 | AH11: 挑战者庄园
A12: 11 | B12: shiren_daochang | C12: 十人道场 | D12: 中级 | E12: task1 | F12: 否 | G12: 否 | H12: 3 | I12: 1800 | J12: 每日开放 | K12: 无 | L12: =SUMIFS(敌方阵容!$F$2:$F$258,敌方阵容!$A$2:$A$258,B12,敌方阵容!$D$2:$D$258,"门客") -> 10 | M12: =SUMIFS(敌方阵容!$F$2:$F$258,敌方阵容!$A$2:$A$258,B12,敌方阵容!$D$2:$D$258,"护院") -> 0 | N12: =COUNTIF(任务掉落明细!$B$2:$B$66,B12) -> 2 | O12: =COUNTIFS(任务掉落明细!$B$2:$B$66,B12,任务掉落明细!$X$2:$X$66,1) -> 2 | P12: =COUNTIFS(任务掉落明细!$B$2:$B$66,B12,任务掉落明细!$X$2:$X$66,"<1") -> 0 | Q12: 个人任务 | S12: 5 | T12: 十人道场是春秋世界初级试炼之地，由恶人谷十大恶人驻守。只要能击败十大恶人，通过试炼，就能极速提升门客的等级和能力。 | U12: 6 | V12: 55 | W12: 0.08 | X12: 银两×20000；十人道场宝箱×1 | Y12: 开箱奖励及概率见宝箱奖励明细 | Z12: 3 | AA12: 按配置导入 | AC12: data/mission_templates.yaml:shiren_daochang | AD12: {} | AE12: {"level":6,"guest_level":55,"guest_bonus":0.08} | AF12: {"key":"shiren_daochang","name":"十人道场","difficulty":"intermediate","display_order":3,"description":"十人道场是春秋世界初级试炼之地，由恶人谷十大恶人驻守。只要能击败十大恶人，通过试炼，就能极速提升门客的等级和能力。\n","battle_type":"task1","enemy_guests":["hero_du_sha","hero_li_dazui","hero_hahaer","hero_tu_jiaojiao","hero_yin_jiuyou",{"key":"task_shiren_xiaomimi","label":"萧咪咪"},{"key":"task_shiren_xuanyuansanguang","label":"轩辕三光"},{"key":"task_shiren_tiezhan","label":"铁战"},"hero_bai_kaixin",{"key":"task_shiren_luoshixiongdi","label":"罗氏兄弟"}],"enemy_technology":{"level":6,"guest_level":55,"guest_bonus":0.08},"drop_table":{"silver":20000,"mission_chest_shiren_daochang":1},"daily_limit":3} | AG12: 10 | AH12: 挑战者庄园
A13: 12 | B13: jiguanshou_chuxian | C13: 机关兽初现 | D13: 初级 | E13: task1 | F13: 否 | G13: 否 | H13: 2 | I13: 1800 | J13: 每日开放 | K13: 无 | L13: =SUMIFS(敌方阵容!$F$2:$F$258,敌方阵容!$A$2:$A$258,B13,敌方阵容!$D$2:$D$258,"门客") -> 8 | M13: =SUMIFS(敌方阵容!$F$2:$F$258,敌方阵容!$A$2:$A$258,B13,敌方阵容!$D$2:$D$258,"护院") -> 0 | N13: =COUNTIF(任务掉落明细!$B$2:$B$66,B13) -> 2 | O13: =COUNTIFS(任务掉落明细!$B$2:$B$66,B13,任务掉落明细!$X$2:$X$66,1) -> 2 | P13: =COUNTIFS(任务掉落明细!$B$2:$B$66,B13,任务掉落明细!$X$2:$X$66,"<1") -> 0 | Q13: 个人任务 | S13: 1 | T13: 乔家村以制做灵活轻巧、栩栩如生的「机械猫」闻名于天下。「机械猫」又称之为「钟离猫」，相传是墨家子弟孙钟离路过此地时，时逢村中鼠患肆虐，为清除鼠患取当地木材仿猫型制成。经历代乔家村民不断改良，「机械猫」以生具灵性、精巧无比，并作用于生活各用途中。某日乔家村第一铁匠乔大牛家中被盗，八只刚制成的「机械猫」见房门未锁，逃离乔家村。随后，逃离的八只「机械猫」开始在乔家村附近肆虐作恶，搞得乔家村民苦不堪言。 | U13: 7 | V13: 35 | W13: 0.12 | X13: 银两×24000；机关兽初现宝箱×1 | Y13: 开箱奖励及概率见宝箱奖励明细 | Z13: 7 | AA13: 按配置导入 | AC13: data/mission_templates.yaml:jiguanshou_chuxian | AD13: {} | AE13: {"level":7,"guest_level":35,"guest_bonus":0.12} | AF13: {"key":"jiguanshou_chuxian","name":"机关兽初现","difficulty":"junior","display_order":7,"description":"乔家村以制做灵活轻巧、栩栩如生的「机械猫」闻名于天下。「机械猫」又称之为「钟离猫」，相传是墨家子弟孙钟离路过此地时，时逢村中鼠患肆虐，为清除鼠患取当地木材仿猫型制成。经历代乔家村民不断改良，「机械猫」以生具灵性、精巧无比，并作用于生活各用途中。某日乔家村第一铁匠乔大牛家中被盗，八只刚制成的「机械猫」见房门未锁，逃离乔家村。随后，逃离的八只「机械猫」开始在乔家村附近肆虐作恶，搞得乔家村民苦不堪言。\n","battle_type":"task1","enemy_guests":[{"key":"task_mechanism_cat","label":"改装机械猫"},{"key":"task_mechanism_cat","label":"改装机械猫"},{"key":"task_mechanism_cat","label":"改装机械猫"},{"key":"task_mechanism_cat","label":"改装机械猫"},{"key":"task_mechanism_cat","label":"改装机械猫"},{"key":"task_mechanism_cat","label":"改装机械猫"},{"key":"task_mechanism_cat","label":"改装机械猫"},{"key":"task_mechanism_cat","label":"改装机械猫"}],"enemy_technology":{"level":7,"guest_level":35,"guest_bonus":0.12},"drop_table":{"silver":24000,"mission_chest_jiguanshou_chuxian":1},"daily_limit":2,"mission_card_daily_limit":1} | AG13: 10 | AH13: 挑战者庄园
... A33: 32 | B33: baimenlou_mingyun_jueze | C33: 飞将浮沉录：白门楼命运抉择 | D33: 高级 | E33: task1 | F33: 否 | G33: 否 | H33: 1 | I33: 2700 | J33: 每日开放 | K33: 虎牢关战旗×1 | L33: =SUMIFS(敌方阵容!$F$2:$F$258,敌方阵容!$A$2:$A$258,B33,敌方阵容!$D$2:$D$258,"门客") -> 5 | M33: =SUMIFS(敌方阵容!$F$2:$F$258,敌方阵容!$A$2:$A$258,B33,敌方阵容!$D$2:$D$258,"护院") -> 7800 | N33: =COUNTIF(任务掉落明细!$B$2:$B$66,B33) -> 2 | O33: =COUNTIFS(任务掉落明细!$B$2:$B$66,B33,任务掉落明细!$X$2:$X$66,1) -> 2 | P33: =COUNTIFS(任务掉落明细!$B$2:$B$66,B33,任务掉落明细!$X$2:$X$66,"<1") -> 0 | Q33: 个人任务 | S33: 5 | T33: 虎牢关战旗染血之后，曹军围住下邳，白门楼成了吕布最后的落脚处。高顺在整军，张辽在寻找退路，陈宫在推演一条不必投降的路，臧霸守着最后的旧部；而吕布仍相信，只要再给他一次冲阵的机会，天下就还没有真正决定谁会输。 然而江湖传闻，白门楼风声最紧时，总有一张没有落款的招贤帖在暗中流转。若它最终落到有缘人手中，史书上那句“吕布死于白门楼”未必还能照抄，城楼之下或许会多出一位改旗易帜的绝世猛将；只是新东家能不能压住他的脾气，就要看庄园主自己的本事了。 进入此关需要消耗一面「虎牢关战旗」。庄园主须击破吕布、高顺、张辽、陈宫与臧霸的合围，替这段乱世故事写下最后一笔。 | U33: 10 | V33: 100 | W33: 0.8 | X33: 银两×180000；白门楼宝箱×1 | Y33: 开箱奖励及概率见宝箱奖励明细 | Z33: 1003 | AA33: 按配置导入 | AC33: data/mission_templates.yaml:baimenlou_mingyun_jueze | AD33: {"hulao_war_banner":1} | AE33: {"level":10,"guest_level":100,"guest_bonus":0.8} | AF33: {"key":"baimenlou_mingyun_jueze","name":"飞将浮沉录：白门楼命运抉择","display_order":1003,"difficulty":"advanced","description":"虎牢关战旗染血之后，曹军围住下邳，白门楼成了吕布最后的落脚处。高顺在整军，张辽在寻找退路，陈宫在推演一条不必投降的路，臧霸守着最后的旧部；而吕布仍相信，只要再给他一次冲阵的机会，天下就还没有真正决定谁会输。\n\n然而江湖传闻，白门楼风声最紧时，总有一张没有落款的招贤帖在暗中流转。若它最终落到有缘人手中，史书上那句“吕布死于白门楼”未必还能照抄，城楼之下或许会多出一位改旗易帜的绝世猛将；只是新东家能不能压住他的脾气，就要看庄园主自己的本事了。\n\n进入此关需要消耗一面「虎牢关战旗」。庄园主须击破吕布、高顺、张辽、陈宫与臧霸的合围，替这段乱世故事写下最后一笔。\n","battle_type":"task1","entry_cost":{"hulao_war_banner":1},"enemy_guests":[{"key":"task_baimenlou_lvbu","label":"吕布"},{"key":"task_baimenlou_gaoshun","label":"高顺"},{"key":"task_baimenlou_zhangliao","label":"张辽"},{"key":"task_baimenlou_chengong","label":"陈宫"},{"key":"task_baimenlou_zangba","label":"臧霸"}],"enemy_troops":{"dao_sheng":1800,"qiang_wang":1700,"jian_sheng":1600,"quan_sheng":1200,"arrow_god":1500},"enemy_technology":{"level":10,"guest_level":100,"guest_bonus":0.8},"drop_table":{"silver":180000,"mission_chest_baimenlou_mingyun_jueze":1},"base_travel_time":2700,"daily_limit":1} | AG33: 10 | AH33: 挑战者庄园
A34: 33 | B34: guild_patrol_alpha | C34: 夜袭乌鳞寨 | D34: 初级 | E34: troop | F34: 否 | G34: 否 | I34: 1500 | J34: 每日开放 | K34: 无 | L34: =SUMIFS(敌方阵容!$F$2:$F$258,敌方阵容!$A$2:$A$258,B34,敌方阵容!$D$2:$D$258,"门客") -> 12 | M34: =SUMIFS(敌方阵容!$F$2:$F$258,敌方阵容!$A$2:$A$258,B34,敌方阵容!$D$2:$D$258,"护院") -> 2610 | N34: =COUNTIF(任务掉落明细!$B$2:$B$66,B34) -> 1 | O34: =COUNTIFS(任务掉落明细!$B$2:$B$66,B34,任务掉落明细!$X$2:$X$66,1) -> 1 | P34: =COUNTIFS(任务掉落明细!$B$2:$B$66,B34,任务掉落明细!$X$2:$X$66,"<1") -> 0 | Q34: 帮会任务 | R34: 3 | T34: 近来北郊商道一入子夜便灯火尽灭，往返车队不是失了骡马，便是天明后只剩翻倒车辙。帮中弟子顺着断箭、碎缰和半截焦木一路摸到山坳，才看见乌鳞寨早把谷口修成了连环哨卡，拒马、暗哨与巡夜火把一层压着一层。 寨中人白日敛迹，夜里却轮番下山掠货，惯会先放小股人手引人追击，再借山路弯口突然合围。若想把这条商线重新打通，不能只顾着往前压，还得有人盯住两翼伏兵，免得主力刚进谷口，退路便先被人摸黑截断。 | U34: 7 | V34: 88 | W34: 0.36 | X34: 红宝石×96（帮会仓库） | Y34: 无 | Z34: 10 | AA34: 是 | AB34: 10 | AC34: data/guild_mission_templates.yaml:L9 | AD34: {} | AE34: {"level":7,"guest_level":88,"guest_bonus":0.36} | AF34: {"key":"guild_patrol_alpha","name":"夜袭乌鳞寨","description":"近来北郊商道一入子夜便灯火尽灭，往返车队不是失了骡马，便是天明后只剩翻倒车辙。帮中弟子顺着断箭、碎缰和半截焦木一路摸到山坳，才看见乌鳞寨早把谷口修成了连环哨卡，拒马、暗哨与巡夜火把一层压着一层。\n\n寨中人白日敛迹，夜里却轮番下山掠货，惯会先放小股人手引人追击，再借山路弯口突然合围。若想把这条商线重新打通，不能只顾着往前压，还得有人盯住两翼伏兵，免得主力刚进谷口，退路便先被人摸黑截断。\n","difficulty":"junior","task_type":"troop","base_duration_seconds":1500,"ruby_reward":96,"weekly_limit":3,"recommended_guest_count":10,"allow_troops":true,"enemy_guests":[{"template_key":"guild_wulinzhai_zhai_zhu"},{"template_key":"guild_wulinzhai_junshi"},{"template_key":"guild_wulinzhai_night_watch"},{"template_key":"guild_wulinzhai_blade_ambusher"},{"template_key":"guild_wulinzhai_blade_ambusher"},{"template_key":"guild_wulinzhai_blade_ambusher"},{"template_key":"guild_wulinzhai_torch_archer"},{"template_key":"guild_wulinzhai_torch_archer"},{"template_key":"guild_wulinzhai_torch_archer"},{"template_key":"guild_wulinzhai_path_scout"},{"template_key":"guild_wulinzhai_minion"},{"template_key":"guild_wulinzhai_minion"}],"enemy_troops":{"qiang_hao":760,"jian_hao":700,"fast_archer":650,"dao_jie":500},"enemy_technology":{"level":7,"guest_level":88,"guest_bonus":0.36},"is_active":true,"sort_weight":10} | AH34: 帮会仓库
A35: 34 | B35: guild_supply_escort | C35: 血旗镖局风云 | D35: 中级 | E35: troop | F35: 否 | G35: 否 | I35: 2100 | J35: 每日开放 | K35: 无 | L35: =SUMIFS(敌方阵容!$F$2:$F$258,敌方阵容!$A$2:$A$258,B35,敌方阵容!$D$2:$D$258,"门客") -> 16 | M35: =SUMIFS(敌方阵容!$F$2:$F$258,敌方阵容!$A$2:$A$258,B35,敌方阵容!$D$2:$D$258,"护院") -> 4100 | N35: =COUNTIF(任务掉落明细!$B$2:$B$66,B35) -> 1 | O35: =COUNTIFS(任务掉落明细!$B$2:$B$66,B35,任务掉落明细!$X$2:$X$66,1) -> 1 | P35: =COUNTIFS(任务掉落明细!$B$2:$B$66,B35,任务掉落明细!$X$2:$X$66,"<1") -> 0 | Q35: 帮会任务 | R35: 3 | T35: 血旗镖局表面替各路商号押送金银药材，暗地里却替人收账、截货、买命，沿河几个渡口最近都挂上了他们的旗。凡是不肯交路银的商队，不是半夜改道，就是第二天只剩散落河滩的箱板和染血车帘，连船家都开始装聋作哑，不敢多问一句。 探子送回的消息说，这支人马不像寻常匪帮，各车之间号令极严，前阵短弓压路，中段刀枪护箱，尾队还留着专门断后的老手。真打起来，他们未必急着和你硬换，只会边退边拖，把人一步步拽进最窄最乱的那段河道。 | U35: 10 | V35: 102 | W35: 0.62 | X35: 红宝石×168（帮会仓库） | Y35: 无 | Z35: 20 | AA35: 是 | AB35: 14 | AC35: data/guild_mission_templates.yaml:L47 | AD35: {} | AE35: {"level":10,"guest_level":102,"guest_bonus":0.62} | AF35: {"key":"guild_supply_escort","name":"血旗镖局风云","description":"血旗镖局表面替各路商号押送金银药材，暗地里却替人收账、截货、买命，沿河几个渡口最近都挂上了他们的旗。凡是不肯交路银的商队，不是半夜改道，就是第二天只剩散落河滩的箱板和染血车帘，连船家都开始装聋作哑，不敢多问一句。\n\n探子送回的消息说，这支人马不像寻常匪帮，各车之间号令极严，前阵短弓压路，中段刀枪护箱，尾队还留着专门断后的老手。真打起来，他们未必急着和你硬换，只会边退边拖，把人一步步拽进最窄最乱的那段河道。\n","difficulty":"intermediate","task_type":"troop","base_duration_seconds":2100,"ruby_reward":168,"weekly_limit":3,"recommended_guest_count":14,"allow_troops":true,"enemy_guests":[{"template_key":"guild_bloodflag_head_escort"},{"template_key":"guild_bloodflag_deputy_escort"},{"template_key":"guild_bloodflag_rearguard_veteran"},{"template_key":"guild_bloodflag_blade_guard"},{"template_key":"guild_bloodflag_blade_guard"},{"template_key":"guild_bloodflag_blade_guard"},{"template_key":"guild_bloodflag_blade_guard"},{"template_key":"guild_bloodflag_bow_guard"},{"template_key":"guild_bloodflag_bow_guard"},{"template_key":"guild_bloodflag_bow_guard"},{"template_key":"guild_bloodflag_bow_guard"},{"template_key":"guild_bloodflag_pathfinder"},{"template_key":"guild_bloodflag_pathfinder"},{"template_key":"guild_bloodflag_escort_master"},{"template_key":"guild_bloodflag_escort_master"},{"template_key":"guild_bloodflag_escort_master"}],"enemy_troops":{"qiang_ba":1180,"jian_hao":980,"divine_archer":1080,"quan_wang":860},"enemy_technology":{"level":10,"guest_level":102,"guest_bonus":0.62},"is_active":true,"sort_weight":20} | AH35: 帮会仓库
A36: 35 | B36: guild_blackwind_assault | C36: 黑风关总攻 | D36: 高级 | E36: troop | F36: 否 | G36: 否 | I36: 3000 | J36: 每日开放 | K36: 无 | L36: =SUMIFS(敌方阵容!$F$2:$F$258,敌方阵容!$A$2:$A$258,B36,敌方阵容!$D$2:$D$258,"门客") -> 22 | M36: =SUMIFS(敌方阵容!$F$2:$F$258,敌方阵容!$A$2:$A$258,B36,敌方阵容!$D$2:$D$258,"护院") -> 6680 | N36: =COUNTIF(任务掉落明细!$B$2:$B$66,B36) -> 1 | O36: =COUNTIFS(任务掉落明细!$B$2:$B$66,B36,任务掉落明细!$X$2:$X$66,1) -> 1 | P36: =COUNTIFS(任务掉落明细!$B$2:$B$66,B36,任务掉落明细!$X$2:$X$66,"<1") -> 0 | Q36: 帮会任务 | R36: 3 | T36: 黑风关原是旧时军镇咽喉，多年废弃后反被各路亡命和旧军头子修成了铁桶。关前壕沟是新翻的，拒马、滚木和石垒顺着山口一层层铺开，城头昼夜轮火不熄；前几次探路的人才看见墙影里箭光一闪，山道上就已经响起调兵铜哨。 更麻烦的是，关内粮械齐备，轮守之人熟悉军阵，能把外墙、甬道和内寨连成一口气。若真要把黑风关从地图上抹去，便不是冲开一道门那么简单，而是要顶着连番反扑一路杀到关楼，把还在运转的整座堡寨硬生生拆开。 | U36: 12 | V36: 108 | W36: 0.96 | X36: 红宝石×288（帮会仓库） | Y36: 无 | Z36: 30 | AA36: 是 | AB36: 18 | AC36: data/guild_mission_templates.yaml:L89 | AD36: {} | AE36: {"level":12,"guest_level":108,"guest_bonus":0.96} | AF36: {"key":"guild_blackwind_assault","name":"黑风关总攻","description":"黑风关原是旧时军镇咽喉，多年废弃后反被各路亡命和旧军头子修成了铁桶。关前壕沟是新翻的，拒马、滚木和石垒顺着山口一层层铺开，城头昼夜轮火不熄；前几次探路的人才看见墙影里箭光一闪，山道上就已经响起调兵铜哨。\n\n更麻烦的是，关内粮械齐备，轮守之人熟悉军阵，能把外墙、甬道和内寨连成一口气。若真要把黑风关从地图上抹去，便不是冲开一道门那么简单，而是要顶着连番反扑一路杀到关楼，把还在运转的整座堡寨硬生生拆开。\n","difficulty":"advanced","task_type":"troop","base_duration_seconds":3000,"ruby_reward":288,"weekly_limit":3,"recommended_guest_count":18,"allow_troops":true,"enemy_guests":[{"template_key":"guild_blackwind_gate_general"},{"template_key":"guild_blackwind_gate_overseer"},{"template_key":"guild_blackwind_iron_guard"},{"template_key":"guild_blackwind_iron_guard"},{"template_key":"guild_blackwind_iron_guard"},{"template_key":"guild_blackwind_bow_captain"},{"template_key":"guild_blackwind_bow_captain"},{"template_key":"guild_blackwind_bow_captain"},{"template_key":"guild_blackwind_assault_blade"},{"template_key":"guild_blackwind_assault_blade"},{"template_key":"guild_blackwind_assault_blade"},{"template_key":"guild_blackwind_assault_blade"},{"template_key":"guild_blackwind_assault_blade"},{"template_key":"guild_blackwind_patrol_captain"},{"template_key":"guild_blackwind_patrol_captain"},{"template_key":"guild_blackwind_guard_soldier"},{"template_key":"guild_blackwind_guard_soldier"},{"template_key":"guild_blackwind_guard_soldier"},{"template_key":"guild_blackwind_spear_soldier"},{"template_key":"guild_blackwind_spear_soldier"},{"template_key":"guild_blackwind_spear_soldier"},{"template_key":"guild_blackwind_spear_soldier"}],"enemy_troops":{"qiang_wang":1700,"jian_sheng":1450,"arrow_god":1620,"quan_sheng":980,"dao_sheng":930},"enemy_technology":{"level":12,"guest_level":108,"guest_bonus":0.96},"is_active":true,"sort_weight":30} | AH36: 帮会仓库

Sheet 任务掉落明细
A1: 序号 | B1: 任务key | C1: 任务名称 | D1: 难度 | E1: 战斗类型 | F1: 防守任务 | G1: 仅门客 | H1: 每日次数 | I1: 配置基础耗时秒 | J1: 开放星期 | K1: 进入消耗 | L1: 掉落类型 | M1: 掉落配置key | N1: 实际掉落key | O1: 实际掉落名称 | P1: 物品类型 | Q1: 稀有度 | R1: 掉落/随机池触发概率 | S1: 数量 | T1: 池内权重 | U1: 是否选择池 | V1: 原始配置 | W1: 池内权重合计 | X1: 单项实际掉落概率 | Y1: 单次胜利期望数量 | Z1: 任务分类 | AA1: 每周次数(帮会) | AB1: 奖励接收方 | AC1: 发奖条件 | AD1: 数据来源
A2: 1 | B2: mid_autumn_moon_palace_trial | C2: 广寒宫试炼 | D2: 中级 | E2: task1 | F2: 否 | G2: 否 | H2: 3 | I2: 1800 | J2: 周二、周四、周六、周日 | K2: 无 | L2: 固定掉落 | M2: silver | N2: silver | O2: 银两 | P2: 资源 | Q2: 资源 | R2: 1 | S2: 40000 | U2: 否 | V2: 40000 | X2: =R2 -> 1 | Y2: =X2*S2 -> 40000 | Z2: 个人任务 | AB2: 挑战者庄园 | AC2: 玩家胜利、非撤退，任务返程/防守结算；宝箱内容另见宝箱奖励明细 | AD2: data/mission_templates.yaml:mid_autumn_moon_palace_trial.drop_table.silver
A3: 2 | B3: mid_autumn_moon_palace_trial | C3: 广寒宫试炼 | D3: 中级 | E3: task1 | F3: 否 | G3: 否 | H3: 3 | I3: 1800 | J3: 周二、周四、周六、周日 | K3: 无 | L3: 固定掉落 | M3: mission_chest_mid_autumn_moon_palace_trial | N3: mission_chest_mid_autumn_moon_palace_trial | O3: 广寒宫试炼宝箱 | P3: loot_box | Q3: blue | R3: 1 | S3: 1 | U3: 否 | V3: 1 | X3: =R3 -> 1 | Y3: =X3*S3 -> 1 | Z3: 个人任务 | AB3: 挑战者庄园 | AC3: 玩家胜利、非撤退，任务返程/防守结算；宝箱内容另见宝箱奖励明细 | AD3: data/mission_templates.yaml:mid_autumn_moon_palace_trial.drop_table.mission_chest_mid_autumn_moon_palace_trial
A4: 3 | B4: kasukabe_daisakusen | C4: 春日部大作战 | D4: 中级 | E4: task1 | F4: 否 | G4: 否 | H4: 3 | I4: 1800 | J4: 周二、周四、周六、周日 | K4: 无 | L4: 固定掉落 | M4: silver | N4: silver | O4: 银两 | P4: 资源 | Q4: 资源 | R4: 1 | S4: 40000 | U4: 否 | V4: 40000 | X4: =R4 -> 1 | Y4: =X4*S4 -> 40000 | Z4: 个人任务 | AB4: 挑战者庄园 | AC4: 玩家胜利、非撤退，任务返程/防守结算；宝箱内容另见宝箱奖励明细 | AD4: data/mission_templates.yaml:kasukabe_daisakusen.drop_table.silver
A5: 4 | B5: kasukabe_daisakusen | C5: 春日部大作战 | D5: 中级 | E5: task1 | F5: 否 | G5: 否 | H5: 3 | I5: 1800 | J5: 周二、周四、周六、周日 | K5: 无 | L5: 固定掉落 | M5: mission_chest_kasukabe_daisakusen | N5: mission_chest_kasukabe_daisakusen | O5: 春日部大作战宝箱 | P5: loot_box | Q5: blue | R5: 1 | S5: 1 | U5: 否 | V5: 1 | X5: =R5 -> 1 | Y5: =X5*S5 -> 1 | Z5: 个人任务 | AB5: 挑战者庄园 | AC5: 玩家胜利、非撤退，任务返程/防守结算；宝箱内容另见宝箱奖励明细 | AD5: data/mission_templates.yaml:kasukabe_daisakusen.drop_table.mission_chest_kasukabe_daisakusen
A6: 5 | B6: huashan_lunjian | C6: 华山论贱 | D6: 初级 | E6: task1 | F6: 否 | G6: 是 | H6: 3 | I6: 1800 | J6: 每日开放 | K6: 无 | L6: 固定掉落 | M6: silver | N6: silver | O6: 银两 | P6: 资源 | Q6: 资源 | R6: 1 | S6: 8000 | U6: 否 | V6: 8000 | X6: =R6 -> 1 | Y6: =X6*S6 -> 8000 | Z6: 个人任务 | AB6: 挑战者庄园 | AC6: 玩家胜利、非撤退，任务返程/防守结算；宝箱内容另见宝箱奖励明细 | AD6: data/mission_templates.yaml:huashan_lunjian.drop_table.silver
A7: 6 | B7: huashan_lunjian | C7: 华山论贱 | D7: 初级 | E7: task1 | F7: 否 | G7: 是 | H7: 3 | I7: 1800 | J7: 每日开放 | K7: 无 | L7: 固定掉落 | M7: mission_chest_huashan_lunjian | N7: mission_chest_huashan_lunjian | O7: 华山论贱宝箱 | P7: loot_box | Q7: green | R7: 1 | S7: 1 | U7: 否 | V7: 1 | X7: =R7 -> 1 | Y7: =X7*S7 -> 1 | Z7: 个人任务 | AB7: 挑战者庄园 | AC7: 玩家胜利、非撤退，任务返程/防守结算；宝箱内容另见宝箱奖励明细 | AD7: data/mission_templates.yaml:huashan_lunjian.drop_table.mission_chest_huashan_lunjian
A8: 7 | B8: wagangzhai_nixi | C8: 瓦岗寨的逆袭 | D8: 中级 | E8: task1 | F8: 是 | G8: 否 | H8: 3 | I8: 1800 | J8: 每日开放 | K8: 无 | L8: 固定掉落 | M8: silver | N8: silver | O8: 银两 | P8: 资源 | Q8: 资源 | R8: 1 | S8: 40000 | U8: 否 | V8: 40000 | X8: =R8 -> 1 | Y8: =X8*S8 -> 40000 | Z8: 个人任务 | AB8: 挑战者庄园 | AC8: 玩家胜利、非撤退，任务返程/防守结算；宝箱内容另见宝箱奖励明细 | AD8: data/mission_templates.yaml:wagangzhai_nixi.drop_table.silver
A9: 8 | B9: wagangzhai_nixi | C9: 瓦岗寨的逆袭 | D9: 中级 | E9: task1 | F9: 是 | G9: 否 | H9: 3 | I9: 1800 | J9: 每日开放 | K9: 无 | L9: 固定掉落 | M9: mission_chest_wagangzhai_nixi | N9: mission_chest_wagangzhai_nixi | O9: 瓦岗寨的逆袭宝箱 | P9: loot_box | Q9: blue | R9: 1 | S9: 1 | U9: 否 | V9: 1 | X9: =R9 -> 1 | Y9: =X9*S9 -> 1 | Z9: 个人任务 | AB9: 挑战者庄园 | AC9: 玩家胜利、非撤退，任务返程/防守结算；宝箱内容另见宝箱奖励明细 | AD9: data/mission_templates.yaml:wagangzhai_nixi.drop_table.mission_chest_wagangzhai_nixi
A10: 9 | B10: jingyanggang | C10: 景阳冈 | D10: 初级 | E10: task1 | F10: 否 | G10: 是 | H10: 3 | I10: 1800 | J10: 每日开放 | K10: 无 | L10: 固定掉落 | M10: silver | N10: silver | O10: 银两 | P10: 资源 | Q10: 资源 | R10: 1 | S10: 7000 | U10: 否 | V10: 7000 | X10: =R10 -> 1 | Y10: =X10*S10 -> 7000 | Z10: 个人任务 | AB10: 挑战者庄园 | AC10: 玩家胜利、非撤退，任务返程/防守结算；宝箱内容另见宝箱奖励明细 | AD10: data/mission_templates.yaml:jingyanggang.drop_table.silver
A11: 10 | B11: jingyanggang | C11: 景阳冈 | D11: 初级 | E11: task1 | F11: 否 | G11: 是 | H11: 3 | I11: 1800 | J11: 每日开放 | K11: 无 | L11: 固定掉落 | M11: mission_chest_jingyanggang | N11: mission_chest_jingyanggang | O11: 景阳冈宝箱 | P11: loot_box | Q11: green | R11: 1 | S11: 1 | U11: 否 | V11: 1 | X11: =R11 -> 1 | Y11: =X11*S11 -> 1 | Z11: 个人任务 | AB11: 挑战者庄园 | AC11: 玩家胜利、非撤退，任务返程/防守结算；宝箱内容另见宝箱奖励明细 | AD11: data/mission_templates.yaml:jingyanggang.drop_table.mission_chest_jingyanggang
A12: 11 | B12: wulongshan | C12: 乌龙山 | D12: 初级 | E12: task1 | F12: 否 | G12: 否 | H12: 3 | I12: 1800 | J12: 每日开放 | K12: 无 | L12: 固定掉落 | M12: silver | N12: silver | O12: 银两 | P12: 资源 | Q12: 资源 | R12: 1 | S12: 15000 | U12: 否 | V12: 15000 | X12: =R12 -> 1 | Y12: =X12*S12 -> 15000 | Z12: 个人任务 | AB12: 挑战者庄园 | AC12: 玩家胜利、非撤退，任务返程/防守结算；宝箱内容另见宝箱奖励明细 | AD12: data/mission_templates.yaml:wulongshan.drop_table.silver
A13: 12 | B13: wulongshan | C13: 乌龙山 | D13: 初级 | E13: task1 | F13: 否 | G13: 否 | H13: 3 | I13: 1800 | J13: 每日开放 | K13: 无 | L13: 固定掉落 | M13: mission_chest_wulongshan | N13: mission_chest_wulongshan | O13: 乌龙山宝箱 | P13: loot_box | Q13: green | R13: 1 | S13: 1 | U13: 否 | V13: 1 | X13: =R13 -> 1 | Y13: =X13*S13 -> 1 | Z13: 个人任务 | AB13: 挑战者庄园 | AC13: 玩家胜利、非撤退，任务返程/防守结算；宝箱内容另见宝箱奖励明细 | AD13: data/mission_templates.yaml:wulongshan.drop_table.mission_chest_wulongshan
... A63: 62 | B63: baimenlou_mingyun_jueze | C63: 飞将浮沉录：白门楼命运抉择 | D63: 高级 | E63: task1 | F63: 否 | G63: 否 | H63: 1 | I63: 2700 | J63: 每日开放 | K63: 虎牢关战旗×1 | L63: 固定掉落 | M63: mission_chest_baimenlou_mingyun_jueze | N63: mission_chest_baimenlou_mingyun_jueze | O63: 白门楼宝箱 | P63: loot_box | Q63: purple | R63: 1 | S63: 1 | U63: 否 | V63: 1 | X63: =R63 -> 1 | Y63: =X63*S63 -> 1 | Z63: 个人任务 | AB63: 挑战者庄园 | AC63: 玩家胜利、非撤退，任务返程/防守结算；宝箱内容另见宝箱奖励明细 | AD63: data/mission_templates.yaml:baimenlou_mingyun_jueze.drop_table.mission_chest_baimenlou_mingyun_jueze
A64: 63 | B64: guild_patrol_alpha | C64: 夜袭乌鳞寨 | D64: 初级 | E64: troop | F64: 否 | G64: 否 | I64: 1500 | J64: 每日开放 | K64: 无 | L64: 帮会固定奖励 | M64: red_ruby | N64: red_ruby | O64: 红宝石 | P64: 资源 | Q64: 稀有/蓝 | R64: 1 | S64: 96 | U64: 否 | V64: 96 | X64: =R64 -> 1 | Y64: =X64*S64 -> 96 | Z64: 帮会任务 | AA64: 3 | AB64: 帮会仓库 | AC64: 帮会任务胜利（attacker），非撤退，结算发放 | AD64: data/guild_mission_templates.yaml:L9:ruby_reward
A65: 64 | B65: guild_supply_escort | C65: 血旗镖局风云 | D65: 中级 | E65: troop | F65: 否 | G65: 否 | I65: 2100 | J65: 每日开放 | K65: 无 | L65: 帮会固定奖励 | M65: red_ruby | N65: red_ruby | O65: 红宝石 | P65: 资源 | Q65: 稀有/蓝 | R65: 1 | S65: 168 | U65: 否 | V65: 168 | X65: =R65 -> 1 | Y65: =X65*S65 -> 168 | Z65: 帮会任务 | AA65: 3 | AB65: 帮会仓库 | AC65: 帮会任务胜利（attacker），非撤退，结算发放 | AD65: data/guild_mission_templates.yaml:L47:ruby_reward
A66: 65 | B66: guild_blackwind_assault | C66: 黑风关总攻 | D66: 高级 | E66: troop | F66: 否 | G66: 否 | I66: 3000 | J66: 每日开放 | K66: 无 | L66: 帮会固定奖励 | M66: red_ruby | N66: red_ruby | O66: 红宝石 | P66: 资源 | Q66: 稀有/蓝 | R66: 1 | S66: 288 | U66: 否 | V66: 288 | X66: =R66 -> 1 | Y66: =X66*S66 -> 288 | Z66: 帮会任务 | AA66: 3 | AB66: 帮会仓库 | AC66: 帮会任务胜利（attacker），非撤退，结算发放 | AD66: data/guild_mission_templates.yaml:L89:ruby_reward

Sheet 掉落物反查
A1: 物品key | B1: 物品名称 | C1: 物品类型 | D1: 稀有度 | E1: 任务key | F1: 任务名称 | G1: 掉落类型 | H1: 单项实际掉落概率 | I1: 数量 | J1: 掉落配置key | K1: 任务分类 | L1: 奖励接收方 | M1: 单次胜利期望数量 | N1: 数据来源
A2: silver | B2: 银两 | C2: 资源 | D2: 资源 | E2: mid_autumn_moon_palace_trial | F2: 广寒宫试炼 | G2: 固定掉落 | H2: ='任务掉落明细'!X2 -> 1 | I2: 40000 | J2: silver | K2: 个人任务 | L2: 挑战者庄园 | M2: ='任务掉落明细'!Y2 -> 40000 | N2: data/mission_templates.yaml:mid_autumn_moon_palace_trial.drop_table.silver
A3: mission_chest_mid_autumn_moon_palace_trial | B3: 广寒宫试炼宝箱 | C3: loot_box | D3: blue | E3: mid_autumn_moon_palace_trial | F3: 广寒宫试炼 | G3: 固定掉落 | H3: ='任务掉落明细'!X3 -> 1 | I3: 1 | J3: mission_chest_mid_autumn_moon_palace_trial | K3: 个人任务 | L3: 挑战者庄园 | M3: ='任务掉落明细'!Y3 -> 1 | N3: data/mission_templates.yaml:mid_autumn_moon_palace_trial.drop_table.mission_chest_mid_autumn_moon_palace_trial
A4: silver | B4: 银两 | C4: 资源 | D4: 资源 | E4: kasukabe_daisakusen | F4: 春日部大作战 | G4: 固定掉落 | H4: ='任务掉落明细'!X4 -> 1 | I4: 40000 | J4: silver | K4: 个人任务 | L4: 挑战者庄园 | M4: ='任务掉落明细'!Y4 -> 40000 | N4: data/mission_templates.yaml:kasukabe_daisakusen.drop_table.silver
A5: mission_chest_kasukabe_daisakusen | B5: 春日部大作战宝箱 | C5: loot_box | D5: blue | E5: kasukabe_daisakusen | F5: 春日部大作战 | G5: 固定掉落 | H5: ='任务掉落明细'!X5 -> 1 | I5: 1 | J5: mission_chest_kasukabe_daisakusen | K5: 个人任务 | L5: 挑战者庄园 | M5: ='任务掉落明细'!Y5 -> 1 | N5: data/mission_templates.yaml:kasukabe_daisakusen.drop_table.mission_chest_kasukabe_daisakusen
A6: silver | B6: 银两 | C6: 资源 | D6: 资源 | E6: huashan_lunjian | F6: 华山论贱 | G6: 固定掉落 | H6: ='任务掉落明细'!X6 -> 1 | I6: 8000 | J6: silver | K6: 个人任务 | L6: 挑战者庄园 | M6: ='任务掉落明细'!Y6 -> 8000 | N6: data/mission_templates.yaml:huashan_lunjian.drop_table.silver
A7: mission_chest_huashan_lunjian | B7: 华山论贱宝箱 | C7: loot_box | D7: green | E7: huashan_lunjian | F7: 华山论贱 | G7: 固定掉落 | H7: ='任务掉落明细'!X7 -> 1 | I7: 1 | J7: mission_chest_huashan_lunjian | K7: 个人任务 | L7: 挑战者庄园 | M7: ='任务掉落明细'!Y7 -> 1 | N7: data/mission_templates.yaml:huashan_lunjian.drop_table.mission_chest_huashan_lunjian
A8: silver | B8: 银两 | C8: 资源 | D8: 资源 | E8: wagangzhai_nixi | F8: 瓦岗寨的逆袭 | G8: 固定掉落 | H8: ='任务掉落明细'!X8 -> 1 | I8: 40000 | J8: silver | K8: 个人任务 | L8: 挑战者庄园 | M8: ='任务掉落明细'!Y8 -> 40000 | N8: data/mission_templates.yaml:wagangzhai_nixi.drop_table.silver
A9: mission_chest_wagangzhai_nixi | B9: 瓦岗寨的逆袭宝箱 | C9: loot_box | D9: blue | E9: wagangzhai_nixi | F9: 瓦岗寨的逆袭 | G9: 固定掉落 | H9: ='任务掉落明细'!X9 -> 1 | I9: 1 | J9: mission_chest_wagangzhai_nixi | K9: 个人任务 | L9: 挑战者庄园 | M9: ='任务掉落明细'!Y9 -> 1 | N9: data/mission_templates.yaml:wagangzhai_nixi.drop_table.mission_chest_wagangzhai_nixi
A10: silver | B10: 银两 | C10: 资源 | D10: 资源 | E10: jingyanggang | F10: 景阳冈 | G10: 固定掉落 | H10: ='任务掉落明细'!X10 -> 1 | I10: 7000 | J10: silver | K10: 个人任务 | L10: 挑战者庄园 | M10: ='任务掉落明细'!Y10 -> 7000 | N10: data/mission_templates.yaml:jingyanggang.drop_table.silver
A11: mission_chest_jingyanggang | B11: 景阳冈宝箱 | C11: loot_box | D11: green | E11: jingyanggang | F11: 景阳冈 | G11: 固定掉落 | H11: ='任务掉落明细'!X11 -> 1 | I11: 1 | J11: mission_chest_jingyanggang | K11: 个人任务 | L11: 挑战者庄园 | M11: ='任务掉落明细'!Y11 -> 1 | N11: data/mission_templates.yaml:jingyanggang.drop_table.mission_chest_jingyanggang
A12: silver | B12: 银两 | C12: 资源 | D12: 资源 | E12: wulongshan | F12: 乌龙山 | G12: 固定掉落 | H12: ='任务掉落明细'!X12 -> 1 | I12: 15000 | J12: silver | K12: 个人任务 | L12: 挑战者庄园 | M12: ='任务掉落明细'!Y12 -> 15000 | N12: data/mission_templates.yaml:wulongshan.drop_table.silver
A13: mission_chest_wulongshan | B13: 乌龙山宝箱 | C13: loot_box | D13: green | E13: wulongshan | F13: 乌龙山 | G13: 固定掉落 | H13: ='任务掉落明细'!X13 -> 1 | I13: 1 | J13: mission_chest_wulongshan | K13: 个人任务 | L13: 挑战者庄园 | M13: ='任务掉落明细'!Y13 -> 1 | N13: data/mission_templates.yaml:wulongshan.drop_table.mission_chest_wulongshan
... A66: red_ruby | B66: 红宝石 | C66: 资源 | D66: 稀有/蓝 | E66: guild_blackwind_assault | F66: 黑风关总攻 | G66: 帮会固定奖励 | H66: ='任务掉落明细'!X66 -> 1 | I66: 288 | J66: red_ruby | K66: 帮会任务 | L66: 帮会仓库 | M66: ='任务掉落明细'!Y66 -> 288 | N66: data/guild_mission_templates.yaml:L89:ruby_reward

Sheet 敌方阵容
A1: 任务key | B1: 任务名称 | C1: 任务分类 | D1: 单位类型 | E1: 单位key | F1: 数量 | G1: 单位名称 | H1: 门客技能 | I1: 统一科技等级 | J1: 门客等级 | K1: 门客属性加成 | L1: 数据来源 | M1: 原始单位配置(JSON)
A2: mid_autumn_moon_palace_trial | B2: 广寒宫试炼 | C2: 个人任务 | D2: 门客 | E2: myth_moon_jade_rabbit | F2: 1 | G2: 玉兔 | H2: 使用模板默认技能 | I2: 7 | J2: 60 | K2: 0.12 | L2: data/mission_templates.yaml:L139:enemy_guests | M2: {"key":"myth_moon_jade_rabbit","label":"玉兔"}
A3: mid_autumn_moon_palace_trial | B3: 广寒宫试炼 | C3: 个人任务 | D3: 门客 | E3: myth_moon_wu_gang | F3: 1 | G3: 吴刚 | H3: 使用模板默认技能 | I3: 7 | J3: 60 | K3: 0.12 | L3: data/mission_templates.yaml:L139:enemy_guests | M3: {"key":"myth_moon_wu_gang","label":"吴刚"}
A4: mid_autumn_moon_palace_trial | B4: 广寒宫试炼 | C4: 个人任务 | D4: 门客 | E4: hist_xianqin_0413 | F4: 1 | G4: 嫦娥 | H4: 使用模板默认技能 | I4: 7 | J4: 60 | K4: 0.12 | L4: data/mission_templates.yaml:L139:enemy_guests | M4: {"key":"hist_xianqin_0413","label":"嫦娥"}
A5: mid_autumn_moon_palace_trial | B5: 广寒宫试炼 | C5: 个人任务 | D5: 护院 | E5: quan_wang | F5: 300 | G5: 拳王 | I5: 7 | L5: data/mission_templates.yaml:L139:enemy_troops | M5: {"quan_wang":300}
A6: mid_autumn_moon_palace_trial | B6: 广寒宫试炼 | C6: 个人任务 | D6: 护院 | E6: jian_hao | F6: 300 | G6: 剑豪 | I6: 7 | L6: data/mission_templates.yaml:L139:enemy_troops | M6: {"jian_hao":300}
A7: mid_autumn_moon_palace_trial | B7: 广寒宫试炼 | C7: 个人任务 | D7: 护院 | E7: divine_archer | F7: 200 | G7: 神箭手 | I7: 7 | L7: data/mission_templates.yaml:L139:enemy_troops | M7: {"divine_archer":200}
A8: kasukabe_daisakusen | B8: 春日部大作战 | C8: 个人任务 | D8: 门客 | E8: task_kasukabe_patrol_captain | F8: 1 | G8: 春日部巡逻队长 | H8: 使用模板默认技能 | I8: 7 | J8: 60 | K8: 0.12 | L8: data/mission_templates.yaml:L206:enemy_guests | M8: {"key":"task_kasukabe_patrol_captain","label":"春日部巡逻队长"}
A9: kasukabe_daisakusen | B9: 春日部大作战 | C9: 个人任务 | D9: 门客 | E9: task_kasukabe_toy_crocodile | F9: 1 | G9: 玩具机关鳄鱼 | H9: 使用模板默认技能 | I9: 7 | J9: 60 | K9: 0.12 | L9: data/mission_templates.yaml:L206:enemy_guests | M9: {"key":"task_kasukabe_toy_crocodile","label":"玩具机关鳄鱼"}
A10: kasukabe_daisakusen | B10: 春日部大作战 | C10: 个人任务 | D10: 门客 | E10: task_kasukabe_defense_member | F10: 1 | G10: 迷路的防卫队员 | H10: 使用模板默认技能 | I10: 7 | J10: 60 | K10: 0.12 | L10: data/mission_templates.yaml:L206:enemy_guests | M10: {"key":"task_kasukabe_defense_member","label":"迷路的防卫队员"}
A11: kasukabe_daisakusen | B11: 春日部大作战 | C11: 个人任务 | D11: 门客 | E11: task_kasukabe_crayon_clone | F11: 1 | G11: 蜡笔恶作剧分身 | H11: 使用模板默认技能 | I11: 7 | J11: 60 | K11: 0.12 | L11: data/mission_templates.yaml:L206:enemy_guests | M11: {"key":"task_kasukabe_crayon_clone","label":"蜡笔恶作剧分身"}
A12: kasukabe_daisakusen | B12: 春日部大作战 | C12: 个人任务 | D12: 门客 | E12: task_kasukabe_doodle_boss | F12: 1 | G12: 涂鸦大魔王 | H12: 使用模板默认技能 | I12: 7 | J12: 60 | K12: 0.12 | L12: data/mission_templates.yaml:L206:enemy_guests | M12: {"key":"task_kasukabe_doodle_boss","label":"涂鸦大魔王"}
A13: kasukabe_daisakusen | B13: 春日部大作战 | C13: 个人任务 | D13: 护院 | E13: quan_wang | F13: 300 | G13: 拳王 | I13: 7 | L13: data/mission_templates.yaml:L206:enemy_troops | M13: {"quan_wang":300}
A14: kasukabe_daisakusen | B14: 春日部大作战 | C14: 个人任务 | D14: 护院 | E14: archer | F14: 300 | G14: 弓箭手 | I14: 7 | L14: data/mission_templates.yaml:L206:enemy_troops | M14: {"archer":300}
A15: kasukabe_daisakusen | B15: 春日部大作战 | C15: 个人任务 | D15: 护院 | E15: dao_ba | F15: 200 | G15: 刀霸 | I15: 7 | L15: data/mission_templates.yaml:L206:enemy_troops | M15: {"dao_ba":200}
A16: huashan_lunjian | B16: 华山论贱 | C16: 个人任务 | D16: 门客 | E16: task_huashan_jianwang | F16: 1 | G16: 贱王之王 | H16: 使用模板默认技能 | I16: 2 | J16: 12 | K16: 0 | L16: data/mission_templates.yaml:L287:enemy_guests | M16: {"key":"task_huashan_jianwang","label":"贱王之王"}
A17: huashan_lunjian | B17: 华山论贱 | C17: 个人任务 | D17: 门客 | E17: task_huashan_jianjing | F17: 1 | G17: 顶级贱精 | H17: 使用模板默认技能 | I17: 2 | J17: 12 | K17: 0 | L17: data/mission_templates.yaml:L287:enemy_guests | M17: {"key":"task_huashan_jianjing","label":"顶级贱精"}
A18: huashan_lunjian | B18: 华山论贱 | C18: 个人任务 | D18: 门客 | E18: task_huashan_jianjing | F18: 1 | G18: 顶级贱精 | H18: 使用模板默认技能 | I18: 2 | J18: 12 | K18: 0 | L18: data/mission_templates.yaml:L287:enemy_guests | M18: {"key":"task_huashan_jianjing","label":"顶级贱精"}
A19: huashan_lunjian | B19: 华山论贱 | C19: 个人任务 | D19: 门客 | E19: task_huashan_audience_a | F19: 1 | G19: 观众甲 | H19: 使用模板默认技能 | I19: 2 | J19: 12 | K19: 0 | L19: data/mission_templates.yaml:L287:enemy_guests | M19: {"key":"task_huashan_audience_a","label":"观众甲"}
A20: wagangzhai_nixi | B20: 瓦岗寨的逆袭 | C20: 个人任务 | D20: 门客 | E20: hist_suitang_0162_zhairang | F20: 1 | G20: 翟让 | H20: 唐僧说禅 | I20: 10 | J20: 100 | K20: 0.3 | L20: data/mission_templates.yaml:L326:enemy_guests | M20: {"key":"hist_suitang_0162_zhairang","skills":["tangseng_sermon"]}
A21: wagangzhai_nixi | B21: 瓦岗寨的逆袭 | C21: 个人任务 | D21: 门客 | E21: hero_qin_shubao | F21: 1 | G21: 秦叔宝 | H21: 梵天真火 | I21: 10 | J21: 100 | K21: 0.3 | L21: data/mission_templates.yaml:L326:enemy_guests | M21: {"key":"hero_qin_shubao","skills":["brahma_true_fire"]}
A22: wagangzhai_nixi | B22: 瓦岗寨的逆袭 | C22: 个人任务 | D22: 门客 | E22: hist_suitang_0164_shanxiongxin | F22: 1 | G22: 单雄信 | H22: 使用模板默认技能 | I22: 10 | J22: 100 | K22: 0.3 | L22: data/mission_templates.yaml:L326:enemy_guests | M22: "hist_suitang_0164_shanxiongxin"
A23: wagangzhai_nixi | B23: 瓦岗寨的逆袭 | C23: 个人任务 | D23: 门客 | E23: hist_suitang_0165_wangbodang | F23: 1 | G23: 王伯当 | H23: 使用模板默认技能 | I23: 10 | J23: 100 | K23: 0.3 | L23: data/mission_templates.yaml:L326:enemy_guests | M23: "hist_suitang_0165_wangbodang"
A24: wagangzhai_nixi | B24: 瓦岗寨的逆袭 | C24: 个人任务 | D24: 门客 | E24: hero_luo_cheng | F24: 1 | G24: 罗成 | H24: 使用模板默认技能 | I24: 10 | J24: 100 | K24: 0.3 | L24: data/mission_templates.yaml:L326:enemy_guests | M24: "hero_luo_cheng"
A25: wagangzhai_nixi | B25: 瓦岗寨的逆袭 | C25: 个人任务 | D25: 门客 | E25: hero_cheng_yaojin | F25: 1 | G25: 程咬金 | H25: 使用模板默认技能 | I25: 10 | J25: 100 | K25: 0.3 | L25: data/mission_templates.yaml:L326:enemy_guests | M25: "hero_cheng_yaojin"
A26: wagangzhai_nixi | B26: 瓦岗寨的逆袭 | C26: 个人任务 | D26: 护院 | E26: arrow_god | F26: 800 | G26: 箭神 | I26: 10 | L26: data/mission_templates.yaml:L326:enemy_troops | M26: {"arrow_god":800}
A27: wagangzhai_nixi | B27: 瓦岗寨的逆袭 | C27: 个人任务 | D27: 护院 | E27: quan_sheng | F27: 800 | G27: 拳圣 | I27: 10 | L27: data/mission_templates.yaml:L326:enemy_troops | M27: {"quan_sheng":800}
A28: wagangzhai_nixi | B28: 瓦岗寨的逆袭 | C28: 个人任务 | D28: 护院 | E28: qiang_wang | F28: 800 | G28: 枪王 | I28: 10 | L28: data/mission_templates.yaml:L326:enemy_troops | M28: {"qiang_wang":800}
A29: jingyanggang | B29: 景阳冈 | C29: 个人任务 | D29: 门客 | E29: task_jingyang_tiger | F29: 1 | G29: 猛虎 | H29: 使用模板默认技能 | I29: 3 | J29: 15 | K29: 0.02 | L29: data/mission_templates.yaml:L379:enemy_guests | M29: {"key":"task_jingyang_tiger","label":"猛虎"}
A30: wulongshan | B30: 乌龙山 | C30: 个人任务 | D30: 门客 | E30: task_wulong_bandit_chief_zuanshanbao | F30: 1 | G30: 钻山豹 | H30: 使用模板默认技能 | I30: 4 | J30: 20 | K30: 0.04 | L30: data/mission_templates.yaml:L408:enemy_guests | M30: {"key":"task_wulong_bandit_chief_zuanshanbao","label":"钻山豹"}
A31: wulongshan | B31: 乌龙山 | C31: 个人任务 | D31: 门客 | E31: task_wulong_bandit_chief_zuoshandiao | F31: 1 | G31: 座山雕 | H31: 使用模板默认技能 | I31: 4 | J31: 20 | K31: 0.04 | L31: data/mission_templates.yaml:L408:enemy_guests | M31: {"key":"task_wulong_bandit_chief_zuoshandiao","label":"座山雕"}
A32: wulongshan | B32: 乌龙山 | C32: 个人任务 | D32: 护院 | E32: qiang_ke | F32: 200 | G32: 枪客 | I32: 4 | L32: data/mission_templates.yaml:L408:enemy_troops | M32: {"qiang_ke":200}
A33: wagangzhai | B33: 瓦岗寨 | C33: 个人任务 | D33: 门客 | E33: hero_cheng_yaojin | F33: 1 | G33: 程咬金 | H33: 使用模板默认技能 | I33: 5 | J33: 35 | K33: 0.1 | L33: data/mission_templates.yaml:L444:enemy_guests | M33: "hero_cheng_yaojin"
A34: wagangzhai | B34: 瓦岗寨 | C34: 个人任务 | D34: 门客 | E34: hist_suitang_0162_zhairang | F34: 1 | G34: 翟让 | H34: 使用模板默认技能 | I34: 5 | J34: 35 | K34: 0.1 | L34: data/mission_templates.yaml:L444:enemy_guests | M34: "hist_suitang_0162_zhairang"
A35: wagangzhai | B35: 瓦岗寨 | C35: 个人任务 | D35: 护院 | E35: jian_xia | F35: 400 | G35: 剑侠 | I35: 5 | L35: data/mission_templates.yaml:L444:enemy_troops | M35: {"jian_xia":400}
A36: fugui_shanzhuang | B36: 富贵山庄 | C36: 个人任务 | D36: 门客 | E36: task_fugui_instructor | F36: 1 | G36: 武师教头 | H36: 使用模板默认技能 | I36: 3 | J36: 40 | K36: 0.05 | L36: data/mission_templates.yaml:L482:enemy_guests | M36: {"key":"task_fugui_instructor","label":"武师教头"}
A37: shizipo_heidian | B37: 十字坡黑店 | C37: 个人任务 | D37: 门客 | E37: task_shizipo_sun_erniang | F37: 1 | G37: 孙二娘 | H37: 使用模板默认技能 | I37: 6 | J37: 70 | K37: 0.1 | L37: data/mission_templates.yaml:L514:enemy_guests | M37: {"key":"task_shizipo_sun_erniang","label":"孙二娘"}
A38: shizipo_heidian | B38: 十字坡黑店 | C38: 个人任务 | D38: 门客 | E38: task_shizipo_zhang_qing | F38: 1 | G38: 张青 | H38: 使用模板默认技能 | I38: 6 | J38: 70 | K38: 0.1 | L38: data/mission_templates.yaml:L514:enemy_guests | M38: {"key":"task_shizipo_zhang_qing","label":"张青"}
A39: shizipo_heidian | B39: 十字坡黑店 | C39: 个人任务 | D39: 护院 | E39: quan_wang | F39: 300 | G39: 拳王 | I39: 6 | L39: data/mission_templates.yaml:L514:enemy_troops | M39: {"quan_wang":300}
A40: shizipo_heidian | B40: 十字坡黑店 | C40: 个人任务 | D40: 护院 | E40: divine_archer | F40: 300 | G40: 神箭手 | I40: 6 | L40: data/mission_templates.yaml:L514:enemy_troops | M40: {"divine_archer":300}
...

Sheet 页面展示配置
A1: 任务key | B1: 任务名称 | C1: 物品key | D1: 物品名称 | E1: 原始展示值(JSON) | F1: 用途说明 | G1: 数据来源

Sheet 动态奖励规则
A1: 适用范围 | B1: 奖励规则 | C1: 物品key/取值来源 | D1: 奖励物品 | E1: 计算口径 | F1: 数量说明 | G1: 发奖条件 | H1: 代码来源
A2: 改版前已有散装奖励战报（不含任务宝箱） | B2: 经验果：阵亡护院 | C2: experience_fruit | D2: 经验果 | E2: 双方阵亡护院数量×该兵种招募基准秒数/3600×0.1求和；排除门客及城防单位 | F2: 与阵亡门客贡献合并后向下取整，无固定保底数量 | G2: 玩家一方胜利，非撤退，返程结算 | H2: gameplay/services/battle_salvage.py:_calculate_troop_exp_fruit；gameplay/services/missions_impl/finalization_helpers.py:build_mission_drops_with_salvage
A3: 改版前已有散装奖励战报（不含任务宝箱） | B3: 经验果：阵亡门客 | C3: experience_fruit | D3: 经验果 | E3: 双方remaining_hp=0的门客：等级×稀有度倍率×初始血量/最大血量×0.05求和 | F3: 与阵亡护院贡献合并后向下取整；稀有度倍率见PVPConstants.RARITY_EXP_MULTIPLIER | G3: 玩家一方胜利，非撤退，返程结算 | H3: gameplay/services/battle_salvage.py:_member_exp_fruit；gameplay/constants.py:PVPConstants.RARITY_EXP_MULTIPLIER
A4: 改版前已有散装奖励战报（不含任务宝箱） | B4: 己方阵亡护院装备回收 | C4: 取己方兵种recruit.equipment | D4: 己方兵种招募装备 | E4: 仅己方阵亡护院；每名阵亡护院、每件招募装备独立以20%概率回收1件 | F4: 依实际己方兵种、阵亡数量及战报种子计算；未作为固定配置池写入掉落明细 | G4: 玩家一方胜利，非撤退，返程结算 | H4: gameplay/services/battle_salvage.py:_calculate_equipment_recovery；gameplay/constants.py:PVPConstants.EQUIPMENT_RECOVERY_CHANCE
A5: 全部帮会任务 | B5: 无个人战损回收奖励 | E5: auto_reward=False，仅确定发放配置红宝石至帮会仓库 | F5: 不将战报预览掉落解释为参与者收益 | G5: 帮会胜利后结算 | H5: guilds/services/guild_missions.py:finalize_guild_mission_run
A6: 32新版个人任务 | B6: 经验与装备统一收入宝箱 | C6: 对应mission_chest_* | D6: 宝箱内容 | E6: 按每箱配置发奖；不再额外散发战损经验/装备 | F6: 见宝箱养成预算 | G6: 胜利非撤退得箱；玩家仓库开启 | H6: gameplay/services/missions_impl/finalization_helpers.py；gameplay/services/inventory/use.py

Sheet 统计
A1: 统计项 | B1: 值
A2: 个人任务数 | B2: =COUNTIF(任务列表!$Q$2:$Q$36,"个人任务") -> 32
A3: 帮会任务数 | B3: =COUNTIF(任务列表!$Q$2:$Q$36,"帮会任务") -> 3
A4: 任务总数 | B4: =COUNTA(任务列表!B2:B36) -> 35
A5: 奖励掉落明细行数 | B5: =COUNTA(任务掉落明细!B2:B66) -> 65
A6: 初级任务数 | B6: =COUNTIF(任务列表!$D$2:$D$36,"初级") -> 9
A7: 中级任务数 | B7: =COUNTIF(任务列表!$D$2:$D$36,"中级") -> 11
A8: 高级任务数 | B8: =COUNTIF(任务列表!$D$2:$D$36,"高级") -> 15
A9: 生成时间 | B9: 2026-10-01
A10: 数据范围 | B10: 当前工作区配置，未读取运行中数据库；含全部个人任务及帮会任务。

Sheet 字段说明
A1: 字段/Sheet | B1: 说明
A2: 任务列表 | B2: 每行一个任务。每日次数适用于个人任务，每周次数适用于每帮会每个任务模板；空白表示不适用。
A3: 奖励掉落范围 | B3: 新版个人任务直接发银两与宝箱；内部奖励见新增宝箱奖励明细。旧战报回收见动态奖励规则。帮会公共红宝石机制保留。
A4: 发奖条件 | B4: 个人任务必须玩家一方胜利、非撤退，在返程结算发奖；防守玩家为defender，普通出征为attacker。
A5: 帮会奖励 | B5: 帮会任务胜利后红宝石进入帮会仓库，参与者不会因此直接获得同数量红宝石。当前任务结算未发现额外个人贡献度或个人物品奖励。
A6: 随机池 | B6: 一个池触发后按候选权重随机选一项；权重不是概率。明细将每个候选展开，实际概率及期望数量通过Excel公式计算。
A7: 同物品多条掉落 | B7: 每个drop_table条目独立判定并累加；例如广寒宫月饼存在保底与多个额外概率档，不应将这些档位当作互斥奖励。
A8: 页面展示配置 | B8: probability_drop_table仅影响页面展示，单独列页保留原始值；不参与实际奖励或期望数量计算。guaranteed_drops是页面生成变量，非另一张发奖配置表。
A9: 实际概率 | B9: 仅表示一次胜利后对应条目的配置层发放概率，不包含挑战胜率或开放日期。不同条目的期望数量可相加，但至少获得一件的概率不能简单相加。
A10: 基础耗时 | B10: 个人base_travel_time未填按导入默认1800秒；进攻用于单程修正后再加返程，防守使用一次基准。实际受敏捷及时间倍率影响，不将配置秒数宣称实际耗时。帮会base_duration_seconds受时间倍率缩放，无额外返程。
A11: 发起消耗 | B11: 个人任务每次发起扣10行动点，另消耗entry_cost中的库存物品；行动点列与入场物品列分别展示。帮会任务行动点列为空，不套用个人任务规则。
A12: 个人任务默认值 | B12: daily_limit=3，mission_card_daily_limit=5，display_order=1000，guest_only=False，is_defense=False；未填available_weekdays表示每日开放。
... A18: 规则核对代码 | B18: common/utils/loot.py；gameplay/management/commands/load_mission_templates.py；gameplay/services/missions_impl/finalize_command.py；guilds/services/guild_missions.py。

Sheet 宝箱奖励明细
A1: 任务key | B1: 任务名称 | C1: 宝箱key | D1: 宝箱名称 | E1: 奖励组 | F1: 物品key | G1: 物品名称 | H1: 品质 | I1: 类型 | J1: 组命中概率 | K1: 池内权重 | L1: 权重合计 | M1: 最少数量 | N1: 最多数量 | O1: 单项实际概率 | P1: 平均数量 | Q1: 每箱期望数量 | R1: 单件经验(小时) | S1: 每箱经验期望(小时) | T1: 所需锻造等级 | U1: 图纸产物 | V1: 配置来源
A2: mid_autumn_moon_palace_trial | B2: 广寒宫试炼 | C2: mission_chest_mid_autumn_moon_palace_trial | D2: 广寒宫试炼宝箱 | E2: 必得 | F2: experience_fruit | G2: 经验果 | H2: green | I2: experience_items | J2: 1 | K2: 1 | L2: 1 | M2: 20 | N2: 20 | O2: =J2*K2/L2 -> 1 | P2: =(M2+N2)/2 -> 20 | Q2: =O2*P2 -> 20 | R2: 1 | S2: =Q2*R2 -> 20 | V2: data/item_templates.yaml:mission_chest_mid_autumn_moon_palace_trial.effect_payload
A3: mid_autumn_moon_palace_trial | B3: 广寒宫试炼 | C3: mission_chest_mid_autumn_moon_palace_trial | D3: 广寒宫试炼宝箱 | E3: 必得 | F3: mid_autumn_mooncake | G3: 月饼 | H3: green | I3: loot_box | J3: 1 | K3: 1 | L3: 1 | M3: 1 | N3: 1 | O3: =J3*K3/L3 -> 1 | P3: =(M3+N3)/2 -> 1 | Q3: =O3*P3 -> 1 | R3: 0 | S3: =Q3*R3 -> 0 | V3: data/item_templates.yaml:mission_chest_mid_autumn_moon_palace_trial.effect_payload
A4: mid_autumn_moon_palace_trial | B4: 广寒宫试炼 | C4: mission_chest_mid_autumn_moon_palace_trial | D4: 广寒宫试炼宝箱 | E4: 必得 | F4: buxuedan | G4: 补血丹 | H4: black | I4: medicine | J4: 1 | K4: 1 | L4: 1 | M4: 2 | N4: 2 | O4: =J4*K4/L4 -> 1 | P4: =(M4+N4)/2 -> 2 | Q4: =O4*P4 -> 2 | R4: 0 | S4: =Q4*R4 -> 0 | V4: data/item_templates.yaml:mission_chest_mid_autumn_moon_palace_trial.effect_payload
A5: mid_autumn_moon_palace_trial | B5: 广寒宫试炼 | C5: mission_chest_mid_autumn_moon_palace_trial | D5: 广寒宫试炼宝箱 | E5: mid_autumn_mooncake_bonus_1 | F5: mid_autumn_mooncake | G5: 月饼 | H5: green | I5: loot_box | J5: 0.55 | K5: 1 | L5: 1 | M5: 1 | N5: 1 | O5: =J5*K5/L5 -> 0.55 | P5: =(M5+N5)/2 -> 1 | Q5: =O5*P5 -> 0.55 | R5: 0 | S5: =Q5*R5 -> 0 | V5: data/item_templates.yaml:mission_chest_mid_autumn_moon_palace_trial.effect_payload
A6: mid_autumn_moon_palace_trial | B6: 广寒宫试炼 | C6: mission_chest_mid_autumn_moon_palace_trial | D6: 广寒宫试炼宝箱 | E6: mid_autumn_mooncake_bonus_2 | F6: mid_autumn_mooncake | G6: 月饼 | H6: green | I6: loot_box | J6: 0.25 | K6: 1 | L6: 1 | M6: 2 | N6: 2 | O6: =J6*K6/L6 -> 0.25 | P6: =(M6+N6)/2 -> 2 | Q6: =O6*P6 -> 0.5 | R6: 0 | S6: =Q6*R6 -> 0 | V6: data/item_templates.yaml:mission_chest_mid_autumn_moon_palace_trial.effect_payload
A7: mid_autumn_moon_palace_trial | B7: 广寒宫试炼 | C7: mission_chest_mid_autumn_moon_palace_trial | D7: 广寒宫试炼宝箱 | E7: mid_autumn_mooncake_bonus_4 | F7: mid_autumn_mooncake | G7: 月饼 | H7: green | I7: loot_box | J7: 0.08 | K7: 1 | L7: 1 | M7: 4 | N7: 4 | O7: =J7*K7/L7 -> 0.08 | P7: =(M7+N7)/2 -> 4 | Q7: =O7*P7 -> 0.32 | R7: 0 | S7: =Q7*R7 -> 0 | V7: data/item_templates.yaml:mission_chest_mid_autumn_moon_palace_trial.effect_payload
A8: mid_autumn_moon_palace_trial | B8: 广寒宫试炼 | C8: mission_chest_mid_autumn_moon_palace_trial | D8: 广寒宫试炼宝箱 | E8: mid_autumn_mooncake_bonus_10 | F8: mid_autumn_mooncake | G8: 月饼 | H8: green | I8: loot_box | J8: 0.015 | K8: 1 | L8: 1 | M8: 10 | N8: 10 | O8: =J8*K8/L8 -> 0.015 | P8: =(M8+N8)/2 -> 10 | Q8: =O8*P8 -> 0.15 | R8: 0 | S8: =Q8*R8 -> 0 | V8: data/item_templates.yaml:mission_chest_mid_autumn_moon_palace_trial.effect_payload
A9: mid_autumn_moon_palace_trial | B9: 广寒宫试炼 | C9: mission_chest_mid_autumn_moon_palace_trial | D9: 广寒宫试炼宝箱 | E9: jade_rabbit_summon_scroll | F9: jade_rabbit_summon_scroll | G9: 玉兔召唤卷轴 | H9: green | I9: tool | J9: 0.08 | K9: 1 | L9: 1 | M9: 1 | N9: 1 | O9: =J9*K9/L9 -> 0.08 | P9: =(M9+N9)/2 -> 1 | Q9: =O9*P9 -> 0.08 | R9: 0 | S9: =Q9*R9 -> 0 | V9: data/item_templates.yaml:mission_chest_mid_autumn_moon_palace_trial.effect_payload
A10: mid_autumn_moon_palace_trial | B10: 广寒宫试炼 | C10: mission_chest_mid_autumn_moon_palace_trial | D10: 广寒宫试炼宝箱 | E10: wu_gang_summon_scroll | F10: wu_gang_summon_scroll | G10: 吴刚召唤卷轴 | H10: blue | I10: tool | J10: 0.05 | K10: 1 | L10: 1 | M10: 1 | N10: 1 | O10: =J10*K10/L10 -> 0.05 | P10: =(M10+N10)/2 -> 1 | Q10: =O10*P10 -> 0.05 | R10: 0 | S10: =Q10*R10 -> 0 | V10: data/item_templates.yaml:mission_chest_mid_autumn_moon_palace_trial.effect_payload
A11: mid_autumn_moon_palace_trial | B11: 广寒宫试炼 | C11: mission_chest_mid_autumn_moon_palace_trial | D11: 广寒宫试炼宝箱 | E11: chang_e_summon_scroll | F11: chang_e_summon_scroll | G11: 嫦娥召唤卷轴 | H11: purple | I11: tool | J11: 0.03 | K11: 1 | L11: 1 | M11: 1 | N11: 1 | O11: =J11*K11/L11 -> 0.03 | P11: =(M11+N11)/2 -> 1 | Q11: =O11*P11 -> 0.03 | R11: 0 | S11: =Q11*R11 -> 0 | V11: data/item_templates.yaml:mission_chest_mid_autumn_moon_palace_trial.effect_payload
A12: kasukabe_daisakusen | B12: 春日部大作战 | C12: mission_chest_kasukabe_daisakusen | D12: 春日部大作战宝箱 | E12: 必得 | F12: experience_fruit | G12: 经验果 | H12: green | I12: experience_items | J12: 1 | K12: 1 | L12: 1 | M12: 77 | N12: 77 | O12: =J12*K12/L12 -> 1 | P12: =(M12+N12)/2 -> 77 | Q12: =O12*P12 -> 77 | R12: 1 | S12: =Q12*R12 -> 77 | V12: data/item_templates.yaml:mission_chest_kasukabe_daisakusen.effect_payload
A13: kasukabe_daisakusen | B13: 春日部大作战 | C13: mission_chest_kasukabe_daisakusen | D13: 春日部大作战宝箱 | E13: 必得 | F13: kasukabe_crayon | G13: 小新的蜡笔 | H13: blue | I13: tool | J13: 1 | K13: 1 | L13: 1 | M13: 1 | N13: 1 | O13: =J13*K13/L13 -> 1 | P13: =(M13+N13)/2 -> 1 | Q13: =O13*P13 -> 1 | R13: 0 | S13: =Q13*R13 -> 0 | V13: data/item_templates.yaml:mission_chest_kasukabe_daisakusen.effect_payload
... A115: shanhaiguan | B115: 山海关 | C115: mission_chest_shanhaiguan | D115: 山海关宝箱 | E115: shanhaiguan_skill_book_random | F115: book_last_chance_revival | G115: 《绝处逢生》秘术 | H115: blue | I115: skill_book | J115: 0.09 | K115: 4 | L115: 9 | M115: 1 | N115: 1 | O115: =J115*K115/L115 -> 0.04 | P115: =(M115+N115)/2 -> 1 | Q115: =O115*P115 -> 0.04 | R115: 0 | S115: =Q115*R115 -> 0 | V115: data/item_templates.yaml:mission_chest_shanhaiguan.effect_payload
A116: shanhaiguan | B116: 山海关 | C116: mission_chest_shanhaiguan | D116: 山海关宝箱 | E116: blueprint_xiaowei_set | F116: blueprint_xiaoweitoukie | G116: 校尉头盔图纸 | H116: blue | I116: tool | J116: 0.35 | K116: 1 | L116: 4 | M116: 1 | N116: 1 | O116: =J116*K116/L116 -> 0.0875 | P116: =(M116+N116)/2 -> 1 | Q116: =O116*P116 -> 0.0875 | R116: 0 | S116: =Q116*R116 -> 0 | T116: 5 | U116: 校尉头盔 | V116: data/item_templates.yaml:mission_chest_shanhaiguan.effect_payload
A117: shanhaiguan | B117: 山海关 | C117: mission_chest_shanhaiguan | D117: 山海关宝箱 | E117: blueprint_xiaowei_set | F117: blueprint_xiaoweikaijia | G117: 校尉铠甲图纸 | H117: blue | I117: tool | J117: 0.35 | K117: 1 | L117: 4 | M117: 1 | N117: 1 | O117: =J117*K117/L117 -> 0.0875 | P117: =(M117+N117)/2 -> 1 | Q117: =O117*P117 -> 0.0875 | R117: 0 | S117: =Q117*R117 -> 0 | T117: 5 | U117: 校尉铠甲 | V117: data/item_templates.yaml:mission_chest_shanhaiguan.effect_payload
A118: shanhaiguan | B118: 山海关 | C118: mission_chest_shanhaiguan | D118: 山海关宝箱 | E118: blueprint_xiaowei_set | F118: blueprint_xiaoweichangxue | G118: 校尉长靴图纸 | H118: blue | I118: tool | J118: 0.35 | K118: 1 | L118: 4 | M118: 1 | N118: 1 | O118: =J118*K118/L118 -> 0.0875 | P118: =(M118+N118)/2 -> 1 | Q118: =O118*P118 -> 0.0875 | R118: 0 | S118: =Q118*R118 -> 0 | T118: 5 | U118: 校尉长靴 | V118: data/item_templates.yaml:mission_chest_shanhaiguan.effect_payload
A119: shanhaiguan | B119: 山海关 | C119: mission_chest_shanhaiguan | D119: 山海关宝箱 | E119: blueprint_xiaowei_set | F119: blueprint_xiaoweichangjian | G119: 校尉长剑图纸 | H119: blue | I119: tool | J119: 0.35 | K119: 1 | L119: 4 | M119: 1 | N119: 1 | O119: =J119*K119/L119 -> 0.0875 | P119: =(M119+N119)/2 -> 1 | Q119: =O119*P119 -> 0.0875 | R119: 0 | S119: =Q119*R119 -> 0 | T119: 5 | U119: 校尉长剑 | V119: data/item_templates.yaml:mission_chest_shanhaiguan.effect_payload
A120: shanhaiguan | B120: 山海关 | C120: mission_chest_shanhaiguan | D120: 山海关宝箱 | E120: 守关坐骑 | F120: equip_zhaoyeyushizi | G120: 照夜玉狮子 | H120: blue | I120: equip_mount | J120: 0.35 | K120: 15 | L120: 35 | M120: 1 | N120: 1 | O120: =J120*K120/L120 -> 0.15 | P120: =(M120+N120)/2 -> 1 | Q120: =O120*P120 -> 0.15 | R120: 0 | S120: =Q120*R120 -> 0 | V120: data/item_templates.yaml:mission_chest_shanhaiguan.effect_payload
A121: shanhaiguan | B121: 山海关 | C121: mission_chest_shanhaiguan | D121: 山海关宝箱 | E121: 守关坐骑 | F121: equip_zhuidian | G121: 追电 | H121: blue | I121: equip_mount | J121: 0.35 | K121: 10 | L121: 35 | M121: 1 | N121: 1 | O121: =J121*K121/L121 -> 0.1 | P121: =(M121+N121)/2 -> 1 | Q121: =O121*P121 -> 0.1 | R121: 0 | S121: =Q121*R121 -> 0 | V121: data/item_templates.yaml:mission_chest_shanhaiguan.effect_payload
A122: shanhaiguan | B122: 山海关 | C122: mission_chest_shanhaiguan | D122: 山海关宝箱 | E122: 守关坐骑 | F122: equip_bailongju | G122: 白龙驹 | H122: blue | I122: equip_mount | J122: 0.35 | K122: 8 | L122: 35 | M122: 1 | N122: 1 | O122: =J122*K122/L122 -> 0.08 | P122: =(M122+N122)/2 -> 1 | Q122: =O122*P122 -> 0.08 | R122: 0 | S122: =Q122*R122 -> 0 | V122: data/item_templates.yaml:mission_chest_shanhaiguan.effect_payload
