Workbook

Sheet 结论与建议
A1: 建筑与科技升级时长/消耗分析与落地方案
A2: 本版建筑与个人技术统一采用总预算归一化 + 逐级增长系数；首级可支付性看基础底线与曲线，不设置末级/首级固定倍数。建筑当前逐级统计与科技当前逐级统计分别提供逐级时间、银两及资源累计值；本轮个人技术全部按新预算公式落地。
A4: 一、公式结论
A5: 为什么不用单一指数 | B5: 单一 base × growth^level 会让末级占比随等级数快速放大；为了追总目标反复硬调 base/growth，且初始银两少时首级可能不可支付。
A6: 新公式 | B6: 每级=基础底线 +（总预算-基础底线×升级次数）×POWER(逐级增长系数,升级序号)/权重总和。
A7: 可控性 | B7: 总时长/总银两由预算直接控制；逐级增长系数控制相邻级增幅。农田等基础建筑用较缓系数保护新手期，长线建筑按解锁阶段审查。
A8: 兼容性 | B8: 所有当前个人技术均使用新预算曲线；帮会科技仍按原离散成本并即时完成。
A9: 横向依据 | B9: 成熟建设类游戏普遍提供逐级升级明细与区间合计，速度加成独立于基础时间；本方案把可审计性落到配置公式中。
A11: 二、目标建筑验收（新公式）
A12: 对象 | B12: 目标时间(天) | C12: 建议时间(天) | D12: 目标银两 | E12: 建议银两 | F12: 结论
A13: ='优化测算'!$C$5 | B13: ='优化测算'!$D$5 | C13: ='优化测算'!$E$5 | D13: ='优化测算'!$G$5 | E13: ='优化测算'!$H$5 | F13: ='优化测算'!$J$5
A14: ='优化测算'!$C$6 | B14: ='优化测算'!$D$6 | C14: ='优化测算'!$E$6 | D14: ='优化测算'!$G$6 | E14: ='优化测算'!$H$6 | F14: ='优化测算'!$J$6
A15: ='优化测算'!$C$7 | B15: ='优化测算'!$D$7 | C15: ='优化测算'!$E$7 | D15: ='优化测算'!$G$7 | E15: ='优化测算'!$H$7 | F15: ='优化测算'!$J$7
A16: ='优化测算'!$C$8 | B16: ='优化测算'!$D$8 | C16: ='优化测算'!$E$8 | D16: ='优化测算'!$G$8 | E16: ='优化测算'!$H$8 | F16: ='优化测算'!$J$8
A17: ='优化测算'!$C$9 | B17: ='优化测算'!$D$9 | C17: ='优化测算'!$E$9 | D17: ='优化测算'!$G$9 | E17: ='优化测算'!$H$9 | F17: ='优化测算'!$J$9
A18: ='优化测算'!$C$10 | B18: ='优化测算'!$D$10 | C18: ='优化测算'!$E$10 | D18: ='优化测算'!$G$10 | E18: ='优化测算'!$H$10 | F18: ='优化测算'!$J$10
A19: ='优化测算'!$C$11 | B19: ='优化测算'!$D$11 | C19: ='优化测算'!$E$11 | D19: ='优化测算'!$G$11 | E19: ='优化测算'!$H$11 | F19: ='优化测算'!$J$11
A20: ='优化测算'!$C$12 | B20: ='优化测算'!$D$12 | C20: ='优化测算'!$E$12 | D20: ='优化测算'!$G$12 | E20: ='优化测算'!$H$12 | F20: ='优化测算'!$J$12
A21: ='优化测算'!$C$13 | B21: ='优化测算'!$D$13 | C21: ='优化测算'!$E$13 | D21: ='优化测算'!$G$13 | E21: ='优化测算'!$H$13 | F21: ='优化测算'!$J$13
A22: ='优化测算'!$C$14 | B22: ='优化测算'!$D$14 | C22: ='优化测算'!$E$14 | D22: ='优化测算'!$G$14 | E22: ='优化测算'!$H$14 | F22: ='优化测算'!$J$14
A23: ='优化测算'!$C$15 | B23: ='优化测算'!$D$15 | C23: ='优化测算'!$E$15 | D23: ='优化测算'!$G$15 | E23: ='优化测算'!$H$15 | F23: ='优化测算'!$J$15
A24: ='优化测算'!$C$16 | B24: ='优化测算'!$D$16 | C24: ='优化测算'!$E$16 | D24: ='优化测算'!$G$16 | E24: ='优化测算'!$H$16 | F24: ='优化测算'!$J$16
A25: ='优化测算'!$C$17 | B25: ='优化测算'!$D$17 | C25: ='优化测算'!$E$17 | D25: ='优化测算'!$G$17 | E25: ='优化测算'!$H$17 | F25: ='优化测算'!$J$17
A26: ='优化测算'!$C$18 | B26: ='优化测算'!$D$18 | C26: ='优化测算'!$E$18 | D26: ='优化测算'!$G$18 | E26: ='优化测算'!$H$18 | F26: ='优化测算'!$J$18
A27: ='优化测算'!$C$19 | B27: ='优化测算'!$D$19 | C27: ='优化测算'!$E$19 | D27: ='优化测算'!$G$19 | E27: ='优化测算'!$H$19 | F27: ='优化测算'!$J$19
A28: ='优化测算'!$C$20 | B28: ='优化测算'!$D$20 | C28: ='优化测算'!$E$20 | D28: ='优化测算'!$G$20 | E28: ='优化测算'!$H$20 | F28: ='优化测算'!$J$20
A29: ='优化测算'!$C$21 | B29: ='优化测算'!$D$21 | C29: ='优化测算'!$E$21 | D29: ='优化测算'!$G$21 | E29: ='优化测算'!$H$21 | F29: ='优化测算'!$J$21
A30: ='优化测算'!$C$22 | B30: ='优化测算'!$D$22 | C30: ='优化测算'!$E$22 | D30: ='优化测算'!$G$22 | E30: ='优化测算'!$H$22 | F30: ='优化测算'!$J$22
A31: ='优化测算'!$C$23 | B31: ='优化测算'!$D$23 | C31: ='优化测算'!$E$23 | D31: ='优化测算'!$G$23 | E31: ='优化测算'!$H$23 | F31: ='优化测算'!$J$23
A32: ='优化测算'!$C$24 | B32: ='优化测算'!$D$24 | C32: ='优化测算'!$E$24 | D32: ='优化测算'!$G$24 | E32: ='优化测算'!$H$24 | F32: ='优化测算'!$J$24
A33: ='优化测算'!$C$25 | B33: ='优化测算'!$D$25 | C33: ='优化测算'!$E$25 | D33: ='优化测算'!$G$25 | E33: ='优化测算'!$H$25 | F33: ='优化测算'!$J$25
A36: 三、落地注意事项
A37: 1. 新字段需要先执行迁移0181，再在确认数据窗口后执行 python manage.py load_building_templates，同步已有 BuildingType 数据。
A38: 2. 实际入口仍会叠加建筑学成本减免、祠堂缩时和 GAME_TIME_MULTIPLIER；Excel展示原始配置预算，便于审数。
A39: 3. 两条建筑队列影响玩家实际完成周期，但不改变单级成本/时长预算公式。

Sheet 参数与公式
A1: 参数与公式｜当前升级系统口径
A2: 建筑和个人技术统一采用总预算归一化曲线；当前技术配置全部走新预算公式。帮会科技仍为扣除资源后即时完成。
A4: 参数 | B4: 当前值 | C4: 单位 | D4: 来源/规则 | E4: 说明
A5: 全局时间倍率 | B5: 1 | C5: 倍 | D5: .env / config/settings/base.py | E5: 实际倒计时 = 游戏内耗时 ÷ 倍率
A6: 建筑并行升级上限 | B6: 2 | C6: 个 | D6: gameplay/constants.py | E6: 同一庄园同时最多2个建筑升级
A7: 个人技术并行升级上限 | B7: 2 | C7: 个 | D7: gameplay/constants.py | E7: 同一庄园同时最多2个个人技术升级
A8: 建筑升级行动力消耗 | B8: 20 | C8: 点/次 | D8: gameplay/services/action_points.py | E8: 普通玩家建筑升级入口消耗
A9: 建筑基准起始等级 | B9: 1 | C9: 级 | D9: gameplay/models/manor.py | E9: Building 默认等级为1
A10: 个人技术基准起始等级 | B10: 0 | C10: 级 | D10: gameplay/models/progression.py | E10: PlayerTechnology 默认等级为0
A11: 帮会科技升级时长 | B11: 0 | C11: 秒/次 | D11: guilds/services/technology.py | E11: 资源扣除后即时升1级
A12: 祠堂最高等级 | B12: 5 | C12: 级 | D12: gameplay/constants.py | E12: 祠堂等级5时达到最大建筑缩时
A13: 祠堂每级缩短建筑时间 | B13: 0.05 | C13: %/级 | D13: gameplay/models/manor.py | E13: 实际为 max(0, 祠堂等级-1) × 5%
A14: 祠堂5级总缩短 | B14: =(B12-1)*B13 | C14: % | D14: gameplay/models/manor.py | E14: 公式单元格；5级为20%
A15: 建筑学最高等级 | B15: 10 | C15: 级 | D15: data/technology_templates.yaml | E15: 建筑学 effect_per_level=5%，最高10级
A16: 建筑学每级成本减免 | B16: 0.05 | C16: %/级 | D16: data/technology_templates.yaml | E16: 建筑成本实际按 ceil(base_cost×(1-减免))
A17: 建筑学10级总成本减免 | B17: =B15*B16 | C17: % | D17: gameplay/services/manor/core.py | E17: 公式单元格；10级为50%
A18: 个人技术默认基础时长 | B18: 60 | C18: 秒 | D18: gameplay/models/progression.py | E18: 模板缺少 base_time 时的默认值
A19: 个人技术默认时长曲线 | B19: 1.08 | C19: 倍 | D19: gameplay/services/technology_rules.py | E19: 仅作为缺失配置时的新公式安全默认值；当前技术均有明确曲线
A20: 个人技术默认成本曲线 | B20: 1.15 | C20: 倍 | D20: gameplay/services/technology_rules.py | E20: 仅作为缺失配置时的新公式安全默认值；当前技术均有明确曲线
A21: 每日秒数 | B21: 86400 | C21: 秒/天 | D21: 本表换算常量 | E21: 建筑累计时长按配置游戏秒数统计
A24: 系统 | B24: 当前代码公式 | C24: Excel等价表达 | D24: 代码位置 | E24: 平衡含义
A25: 建筑时长（预算模式优先） | B25: 预算>0：按总时长预算分配；否则 ceil(base_time × time_growth ^ 当前等级) | C25: Excel表达式：基础底线 + 剩余预算×POWER(逐级增长系数,升级序号)/权重总和 | D25: gameplay/models/manor.py::Building.next_level_duration | E25: 总时长可控；首级与相邻级增幅可审计
A26: 建筑成本（预算模式优先） | B26: 每种资源预算>0：按资源总成本预算分配；否则 ceil(base_cost × cost_growth ^ 当前等级) | C26: Excel表达式：基础底线 + 剩余预算×POWER(逐级增长系数,升级序号)/权重总和 | D26: gameplay/models/manor.py::Building.next_level_cost | E26: 银两/粮食分别控制总预算
A27: 建筑实际时长 | B27: max(1, int(base_duration × (1-citang_reduction) / multiplier)) | C27: =MAX(1,ROUNDDOWN(配置时长×(1-祠堂减免)/全局倍率,0)) | D27: gameplay/services/manor/core.py::quote_building_upgrade | E27: 祠堂与环境倍率叠加，最低1秒
A28: 建筑实际成本 | B28: max(1, ceil(base_cost × (1-architecture_reduction))) | C28: =MAX(1,ROUNDUP(配置成本×(1-建筑学减免),0)) | D28: gameplay/services/manor/core.py::quote_building_upgrade | E28: 只对实际存在的资源键扣除；成本至少1
A29: 个人技术时长 | B29: 统一按 upgrade_time_budget + time_curve 分配；缺失预算时按新公式安全默认预算分配 | C29: 基础底线 + 剩余预算×POWER(曲线,等级序号)/权重总和；实际再除以全局倍率 | D29: gameplay/services/technology_rules.py::calculate_upgrade_duration | E29: 所有当前个人技术统一走预算公式，曲线控制前期可支付性与相邻级增幅
A30: 个人技术成本 | B30: 统一按 upgrade_cost_budget + cost_curve 分配；缺失预算时按新公式安全默认预算分配 | C30: 基础底线 + 剩余银两预算×POWER(曲线,等级序号)/权重总和；最后一级补差 | D30: gameplay/services/technology_rules.py::calculate_upgrade_cost | E30: 所有当前个人技术统一走预算公式，总银两预算精确落地
A31: 帮会科技成本 | B31: base cost × 离散曲线倍率；覆盖项优先 | C31: 逐级明细中按倍率/override公式计算 | D31: guilds/services/technology.py::calculate_tech_upgrade_cost | E31: 非指数曲线；神秘学2/3级使用覆盖成本
A32: 帮会科技时长 | B32: 无计时字段，事务完成后等级立即+1 | C32: 0秒 | D32: guilds/services/technology.py::upgrade_technology | E32: 与个人技术/建筑的计时升级体验不同
A33: 逐级增长权重 | B33: weight = curve_growth ^ step_index；全等级预算按全部升级次数归一化 | C33: step_index=当前等级-1；总预算按全部升级次数归一化 | D33: gameplay/services/technology_rules.py::allocate_upgrade_budget | E33: 不设末级/首级固定倍数；用相邻级增长率检查曲线平滑度
A34: 预算下限 | B34: 每级基础底线 × 升级次数；总预算不足时保留底线，不产生负数或0秒升级 | C34: 总预算不足时保留底线，不产生负数或0秒升级 | D34: gameplay/services/technology_rules.py::allocate_upgrade_budget | E34: base_upgrade_time/base_cost 只承担基础底线
A35: 兼容策略 | B35: 所有个人技术统一走预算曲线；缺失字段只使用新公式安全默认预算，不调用旧指数公式 | C35: 便于旧建筑类型/测试数据平滑迁移 | D35: technology_catalog._apply_upgrade_profiles / technology_rules | E35: 不要求一次性改完所有历史数据
A36: 个人技术预算目标 | B36: 见个人技术总览 O:R | C36: 全程时长/银两预算 + 曲线 | D36: data/technology_templates.yaml | E36: 武艺技术使用 martial profile；侦查术200级单独配置
A37: 侦查术长线目标 | B37: 200 | C37: 级 | D37: data/technology_templates.yaml | E37: 上限200级；全程180天、2亿银两，曲线1.01保护前期支付

Sheet 建筑总览
A1: 建筑升级总览
A2: 改动前配置基线：用于与预算型公式方案对照；科技页仍按当前配置统计。
A4: 建筑Key | B4: 建筑 | C4: 分类 | D4: 最高等级 | E4: 升级次数 | F4: 基础时间(s) | G4: 时间成长 | H4: 基础银两 | I4: 基础粮食 | J4: 成本成长 | K4: 1→2基准实耗时(s) | L4: 末级升级基准实耗时(s) | M4: 全程基准天数 | N4: 全程祠堂5级天数 | O4: 1→2配置时长(s) | P4: 末级配置时长(s) | Q4: 配置总银两 | R4: 配置总粮食 | S4: 建筑学10级总银两 | T4: 建筑学10级总粮食 | U4: 观察
A5: farm | B5: 农田 | C5: 资源生产 | D5: 50 | E5: =D5-'参数与公式'!$B$9 | F5: 180 | G5: 1.22 | H5: 170 | I5: 0 | J5: 1.33 | K5: =SUMIFS('建筑逐级'!$L$5:$L$328,'建筑逐级'!$A$5:$A$328,$A5,'建筑逐级'!$D$5:$D$328,'参数与公式'!$B$9) | L5: =SUMIFS('建筑逐级'!$L$5:$L$328,'建筑逐级'!$A$5:$A$328,$A5,'建筑逐级'!$D$5:$D$328,$D5-1) | M5: =SUMIF('建筑逐级'!$A$5:$A$328,$A5,'建筑逐级'!$L$5:$L$328)/86400 | N5: =SUMIF('建筑逐级'!$A$5:$A$328,$A5,'建筑逐级'!$M$5:$M$328)/86400 | O5: =SUMIFS('建筑逐级'!$K$5:$K$328,'建筑逐级'!$A$5:$A$328,$A5,'建筑逐级'!$D$5:$D$328,'参数与公式'!$B$9) | P5: =SUMIFS('建筑逐级'!$K$5:$K$328,'建筑逐级'!$A$5:$A$328,$A5,'建筑逐级'!$D$5:$D$328,$D5-1) | Q5: =SUMIF('建筑逐级'!$A$5:$A$328,$A5,'建筑逐级'!$N$5:$N$328) | R5: =SUMIF('建筑逐级'!$A$5:$A$328,$A5,'建筑逐级'!$O$5:$O$328) | S5: =SUMIF('建筑逐级'!$A$5:$A$328,$A5,'建筑逐级'!$P$5:$P$328) | T5: =SUMIF('建筑逐级'!$A$5:$A$328,$A5,'建筑逐级'!$Q$5:$Q$328) | U5: 重点观察：等级上限/成长系数/后期单级耗时
A6: tax_office | B6: 税务司 | C6: 资源生产 | D6: 30 | E6: =D6-'参数与公式'!$B$9 | F6: 210 | G6: 1.25 | H6: 450 | I6: 0 | J6: 1.36 | K6: =SUMIFS('建筑逐级'!$L$5:$L$328,'建筑逐级'!$A$5:$A$328,$A6,'建筑逐级'!$D$5:$D$328,'参数与公式'!$B$9) | L6: =SUMIFS('建筑逐级'!$L$5:$L$328,'建筑逐级'!$A$5:$A$328,$A6,'建筑逐级'!$D$5:$D$328,$D6-1) | M6: =SUMIF('建筑逐级'!$A$5:$A$328,$A6,'建筑逐级'!$L$5:$L$328)/86400 | N6: =SUMIF('建筑逐级'!$A$5:$A$328,$A6,'建筑逐级'!$M$5:$M$328)/86400 | O6: =SUMIFS('建筑逐级'!$K$5:$K$328,'建筑逐级'!$A$5:$A$328,$A6,'建筑逐级'!$D$5:$D$328,'参数与公式'!$B$9) | P6: =SUMIFS('建筑逐级'!$K$5:$K$328,'建筑逐级'!$A$5:$A$328,$A6,'建筑逐级'!$D$5:$D$328,$D6-1) | Q6: =SUMIF('建筑逐级'!$A$5:$A$328,$A6,'建筑逐级'!$N$5:$N$328) | R6: =SUMIF('建筑逐级'!$A$5:$A$328,$A6,'建筑逐级'!$O$5:$O$328) | S6: =SUMIF('建筑逐级'!$A$5:$A$328,$A6,'建筑逐级'!$P$5:$P$328) | T6: =SUMIF('建筑逐级'!$A$5:$A$328,$A6,'建筑逐级'!$Q$5:$Q$328) | U6: 重点观察：等级上限/成长系数/后期单级耗时
A7: bathhouse | B7: 澡堂 | C7: 资源生产 | D7: 20 | E7: =D7-'参数与公式'!$B$9 | F7: 300 | G7: 1.25 | H7: 850 | I7: 0 | J7: 1.35 | K7: =SUMIFS('建筑逐级'!$L$5:$L$328,'建筑逐级'!$A$5:$A$328,$A7,'建筑逐级'!$D$5:$D$328,'参数与公式'!$B$9) | L7: =SUMIFS('建筑逐级'!$L$5:$L$328,'建筑逐级'!$A$5:$A$328,$A7,'建筑逐级'!$D$5:$D$328,$D7-1) | M7: =SUMIF('建筑逐级'!$A$5:$A$328,$A7,'建筑逐级'!$L$5:$L$328)/86400 | N7: =SUMIF('建筑逐级'!$A$5:$A$328,$A7,'建筑逐级'!$M$5:$M$328)/86400 | O7: =SUMIFS('建筑逐级'!$K$5:$K$328,'建筑逐级'!$A$5:$A$328,$A7,'建筑逐级'!$D$5:$D$328,'参数与公式'!$B$9) | P7: =SUMIFS('建筑逐级'!$K$5:$K$328,'建筑逐级'!$A$5:$A$328,$A7,'建筑逐级'!$D$5:$D$328,$D7-1) | Q7: =SUMIF('建筑逐级'!$A$5:$A$328,$A7,'建筑逐级'!$N$5:$N$328) | R7: =SUMIF('建筑逐级'!$A$5:$A$328,$A7,'建筑逐级'!$O$5:$O$328) | S7: =SUMIF('建筑逐级'!$A$5:$A$328,$A7,'建筑逐级'!$P$5:$P$328) | T7: =SUMIF('建筑逐级'!$A$5:$A$328,$A7,'建筑逐级'!$Q$5:$Q$328) | U7: 重点观察：等级上限/成长系数/后期单级耗时
A8: latrine | B8: 茅厕 | C8: 资源生产 | D8: 20 | E8: =D8-'参数与公式'!$B$9 | F8: 300 | G8: 1.25 | H8: 550 | I8: 0 | J8: 1.35 | K8: =SUMIFS('建筑逐级'!$L$5:$L$328,'建筑逐级'!$A$5:$A$328,$A8,'建筑逐级'!$D$5:$D$328,'参数与公式'!$B$9) | L8: =SUMIFS('建筑逐级'!$L$5:$L$328,'建筑逐级'!$A$5:$A$328,$A8,'建筑逐级'!$D$5:$D$328,$D8-1) | M8: =SUMIF('建筑逐级'!$A$5:$A$328,$A8,'建筑逐级'!$L$5:$L$328)/86400 | N8: =SUMIF('建筑逐级'!$A$5:$A$328,$A8,'建筑逐级'!$M$5:$M$328)/86400 | O8: =SUMIFS('建筑逐级'!$K$5:$K$328,'建筑逐级'!$A$5:$A$328,$A8,'建筑逐级'!$D$5:$D$328,'参数与公式'!$B$9) | P8: =SUMIFS('建筑逐级'!$K$5:$K$328,'建筑逐级'!$A$5:$A$328,$A8,'建筑逐级'!$D$5:$D$328,$D8-1) | Q8: =SUMIF('建筑逐级'!$A$5:$A$328,$A8,'建筑逐级'!$N$5:$N$328) | R8: =SUMIF('建筑逐级'!$A$5:$A$328,$A8,'建筑逐级'!$O$5:$O$328) | S8: =SUMIF('建筑逐级'!$A$5:$A$328,$A8,'建筑逐级'!$P$5:$P$328) | T8: =SUMIF('建筑逐级'!$A$5:$A$328,$A8,'建筑逐级'!$Q$5:$Q$328) | U8: 重点观察：等级上限/成长系数/后期单级耗时
A9: granary | B9: 粮仓 | C9: 仓储设施 | D9: 20 | E9: =D9-'参数与公式'!$B$9 | F9: 300 | G9: 1.2 | H9: 950 | I9: 0 | J9: 1.35 | K9: =SUMIFS('建筑逐级'!$L$5:$L$328,'建筑逐级'!$A$5:$A$328,$A9,'建筑逐级'!$D$5:$D$328,'参数与公式'!$B$9) | L9: =SUMIFS('建筑逐级'!$L$5:$L$328,'建筑逐级'!$A$5:$A$328,$A9,'建筑逐级'!$D$5:$D$328,$D9-1) | M9: =SUMIF('建筑逐级'!$A$5:$A$328,$A9,'建筑逐级'!$L$5:$L$328)/86400 | N9: =SUMIF('建筑逐级'!$A$5:$A$328,$A9,'建筑逐级'!$M$5:$M$328)/86400 | O9: =SUMIFS('建筑逐级'!$K$5:$K$328,'建筑逐级'!$A$5:$A$328,$A9,'建筑逐级'!$D$5:$D$328,'参数与公式'!$B$9) | P9: =SUMIFS('建筑逐级'!$K$5:$K$328,'建筑逐级'!$A$5:$A$328,$A9,'建筑逐级'!$D$5:$D$328,$D9-1) | Q9: =SUMIF('建筑逐级'!$A$5:$A$328,$A9,'建筑逐级'!$N$5:$N$328) | R9: =SUMIF('建筑逐级'!$A$5:$A$328,$A9,'建筑逐级'!$O$5:$O$328) | S9: =SUMIF('建筑逐级'!$A$5:$A$328,$A9,'建筑逐级'!$P$5:$P$328) | T9: =SUMIF('建筑逐级'!$A$5:$A$328,$A9,'建筑逐级'!$Q$5:$Q$328) | U9: 重点观察：等级上限/成长系数/后期单级耗时
A10: silver_vault | B10: 银库 | C10: 仓储设施 | D10: 30 | E10: =D10-'参数与公式'!$B$9 | F10: 300 | G10: 1.2 | H10: 1100 | I10: 0 | J10: 1.35 | K10: =SUMIFS('建筑逐级'!$L$5:$L$328,'建筑逐级'!$A$5:$A$328,$A10,'建筑逐级'!$D$5:$D$328,'参数与公式'!$B$9) | L10: =SUMIFS('建筑逐级'!$L$5:$L$328,'建筑逐级'!$A$5:$A$328,$A10,'建筑逐级'!$D$5:$D$328,$D10-1) | M10: =SUMIF('建筑逐级'!$A$5:$A$328,$A10,'建筑逐级'!$L$5:$L$328)/86400 | N10: =SUMIF('建筑逐级'!$A$5:$A$328,$A10,'建筑逐级'!$M$5:$M$328)/86400 | O10: =SUMIFS('建筑逐级'!$K$5:$K$328,'建筑逐级'!$A$5:$A$328,$A10,'建筑逐级'!$D$5:$D$328,'参数与公式'!$B$9) | P10: =SUMIFS('建筑逐级'!$K$5:$K$328,'建筑逐级'!$A$5:$A$328,$A10,'建筑逐级'!$D$5:$D$328,$D10-1) | Q10: =SUMIF('建筑逐级'!$A$5:$A$328,$A10,'建筑逐级'!$N$5:$N$328) | R10: =SUMIF('建筑逐级'!$A$5:$A$328,$A10,'建筑逐级'!$O$5:$O$328) | S10: =SUMIF('建筑逐级'!$A$5:$A$328,$A10,'建筑逐级'!$P$5:$P$328) | T10: =SUMIF('建筑逐级'!$A$5:$A$328,$A10,'建筑逐级'!$Q$5:$Q$328) | U10: 重点观察：等级上限/成长系数/后期单级耗时
A11: treasury | B11: 藏宝阁 | C11: 仓储设施 | D11: 20 | E11: =D11-'参数与公式'!$B$9 | F11: 600 | G11: 1.3 | H11: 7500 | I11: 0 | J11: 1.4 | K11: =SUMIFS('建筑逐级'!$L$5:$L$328,'建筑逐级'!$A$5:$A$328,$A11,'建筑逐级'!$D$5:$D$328,'参数与公式'!$B$9) | L11: =SUMIFS('建筑逐级'!$L$5:$L$328,'建筑逐级'!$A$5:$A$328,$A11,'建筑逐级'!$D$5:$D$328,$D11-1) | M11: =SUMIF('建筑逐级'!$A$5:$A$328,$A11,'建筑逐级'!$L$5:$L$328)/86400 | N11: =SUMIF('建筑逐级'!$A$5:$A$328,$A11,'建筑逐级'!$M$5:$M$328)/86400 | O11: =SUMIFS('建筑逐级'!$K$5:$K$328,'建筑逐级'!$A$5:$A$328,$A11,'建筑逐级'!$D$5:$D$328,'参数与公式'!$B$9) | P11: =SUMIFS('建筑逐级'!$K$5:$K$328,'建筑逐级'!$A$5:$A$328,$A11,'建筑逐级'!$D$5:$D$328,$D11-1) | Q11: =SUMIF('建筑逐级'!$A$5:$A$328,$A11,'建筑逐级'!$N$5:$N$328) | R11: =SUMIF('建筑逐级'!$A$5:$A$328,$A11,'建筑逐级'!$O$5:$O$328) | S11: =SUMIF('建筑逐级'!$A$5:$A$328,$A11,'建筑逐级'!$P$5:$P$328) | T11: =SUMIF('建筑逐级'!$A$5:$A$328,$A11,'建筑逐级'!$Q$5:$Q$328) | U11: 重点观察：等级上限/成长系数/后期单级耗时
A12: ranch | B12: 畜牧场 | C12: 生产加工 | D12: 10 | E12: =D12-'参数与公式'!$B$9 | F12: 300 | G12: 1.25 | H12: 800 | I12: 0 | J12: 1.35 | K12: =SUMIFS('建筑逐级'!$L$5:$L$328,'建筑逐级'!$A$5:$A$328,$A12,'建筑逐级'!$D$5:$D$328,'参数与公式'!$B$9) | L12: =SUMIFS('建筑逐级'!$L$5:$L$328,'建筑逐级'!$A$5:$A$328,$A12,'建筑逐级'!$D$5:$D$328,$D12-1) | M12: =SUMIF('建筑逐级'!$A$5:$A$328,$A12,'建筑逐级'!$L$5:$L$328)/86400 | N12: =SUMIF('建筑逐级'!$A$5:$A$328,$A12,'建筑逐级'!$M$5:$M$328)/86400 | O12: =SUMIFS('建筑逐级'!$K$5:$K$328,'建筑逐级'!$A$5:$A$328,$A12,'建筑逐级'!$D$5:$D$328,'参数与公式'!$B$9) | P12: =SUMIFS('建筑逐级'!$K$5:$K$328,'建筑逐级'!$A$5:$A$328,$A12,'建筑逐级'!$D$5:$D$328,$D12-1) | Q12: =SUMIF('建筑逐级'!$A$5:$A$328,$A12,'建筑逐级'!$N$5:$N$328) | R12: =SUMIF('建筑逐级'!$A$5:$A$328,$A12,'建筑逐级'!$O$5:$O$328) | S12: =SUMIF('建筑逐级'!$A$5:$A$328,$A12,'建筑逐级'!$P$5:$P$328) | T12: =SUMIF('建筑逐级'!$A$5:$A$328,$A12,'建筑逐级'!$Q$5:$Q$328) | U12: 重点观察：等级上限/成长系数/后期单级耗时
A13: smithy | B13: 冶炼坊 | C13: 生产加工 | D13: 10 | E13: =D13-'参数与公式'!$B$9 | F13: 300 | G13: 1.25 | H13: 1000 | I13: 0 | J13: 1.35 | K13: =SUMIFS('建筑逐级'!$L$5:$L$328,'建筑逐级'!$A$5:$A$328,$A13,'建筑逐级'!$D$5:$D$328,'参数与公式'!$B$9) | L13: =SUMIFS('建筑逐级'!$L$5:$L$328,'建筑逐级'!$A$5:$A$328,$A13,'建筑逐级'!$D$5:$D$328,$D13-1) | M13: =SUMIF('建筑逐级'!$A$5:$A$328,$A13,'建筑逐级'!$L$5:$L$328)/86400 | N13: =SUMIF('建筑逐级'!$A$5:$A$328,$A13,'建筑逐级'!$M$5:$M$328)/86400 | O13: =SUMIFS('建筑逐级'!$K$5:$K$328,'建筑逐级'!$A$5:$A$328,$A13,'建筑逐级'!$D$5:$D$328,'参数与公式'!$B$9) | P13: =SUMIFS('建筑逐级'!$K$5:$K$328,'建筑逐级'!$A$5:$A$328,$A13,'建筑逐级'!$D$5:$D$328,$D13-1) | Q13: =SUMIF('建筑逐级'!$A$5:$A$328,$A13,'建筑逐级'!$N$5:$N$328) | R13: =SUMIF('建筑逐级'!$A$5:$A$328,$A13,'建筑逐级'!$O$5:$O$328) | S13: =SUMIF('建筑逐级'!$A$5:$A$328,$A13,'建筑逐级'!$P$5:$P$328) | T13: =SUMIF('建筑逐级'!$A$5:$A$328,$A13,'建筑逐级'!$Q$5:$Q$328) | U13: 重点观察：等级上限/成长系数/后期单级耗时
A14: stable | B14: 马房 | C14: 生产加工 | D14: 10 | E14: =D14-'参数与公式'!$B$9 | F14: 300 | G14: 1.25 | H14: 980 | I14: 0 | J14: 1.35 | K14: =SUMIFS('建筑逐级'!$L$5:$L$328,'建筑逐级'!$A$5:$A$328,$A14,'建筑逐级'!$D$5:$D$328,'参数与公式'!$B$9) | L14: =SUMIFS('建筑逐级'!$L$5:$L$328,'建筑逐级'!$A$5:$A$328,$A14,'建筑逐级'!$D$5:$D$328,$D14-1) | M14: =SUMIF('建筑逐级'!$A$5:$A$328,$A14,'建筑逐级'!$L$5:$L$328)/86400 | N14: =SUMIF('建筑逐级'!$A$5:$A$328,$A14,'建筑逐级'!$M$5:$M$328)/86400 | O14: =SUMIFS('建筑逐级'!$K$5:$K$328,'建筑逐级'!$A$5:$A$328,$A14,'建筑逐级'!$D$5:$D$328,'参数与公式'!$B$9) | P14: =SUMIFS('建筑逐级'!$K$5:$K$328,'建筑逐级'!$A$5:$A$328,$A14,'建筑逐级'!$D$5:$D$328,$D14-1) | Q14: =SUMIF('建筑逐级'!$A$5:$A$328,$A14,'建筑逐级'!$N$5:$N$328) | R14: =SUMIF('建筑逐级'!$A$5:$A$328,$A14,'建筑逐级'!$O$5:$O$328) | S14: =SUMIF('建筑逐级'!$A$5:$A$328,$A14,'建筑逐级'!$P$5:$P$328) | T14: =SUMIF('建筑逐级'!$A$5:$A$328,$A14,'建筑逐级'!$Q$5:$Q$328) | U14: 重点观察：等级上限/成长系数/后期单级耗时
A15: forge | B15: 铁匠铺 | C15: 生产加工 | D15: 10 | E15: =D15-'参数与公式'!$B$9 | F15: 300 | G15: 1.25 | H15: 500 | I15: 500 | J15: 1.35 | K15: =SUMIFS('建筑逐级'!$L$5:$L$328,'建筑逐级'!$A$5:$A$328,$A15,'建筑逐级'!$D$5:$D$328,'参数与公式'!$B$9) | L15: =SUMIFS('建筑逐级'!$L$5:$L$328,'建筑逐级'!$A$5:$A$328,$A15,'建筑逐级'!$D$5:$D$328,$D15-1) | M15: =SUMIF('建筑逐级'!$A$5:$A$328,$A15,'建筑逐级'!$L$5:$L$328)/86400 | N15: =SUMIF('建筑逐级'!$A$5:$A$328,$A15,'建筑逐级'!$M$5:$M$328)/86400 | O15: =SUMIFS('建筑逐级'!$K$5:$K$328,'建筑逐级'!$A$5:$A$328,$A15,'建筑逐级'!$D$5:$D$328,'参数与公式'!$B$9) | P15: =SUMIFS('建筑逐级'!$K$5:$K$328,'建筑逐级'!$A$5:$A$328,$A15,'建筑逐级'!$D$5:$D$328,$D15-1) | Q15: =SUMIF('建筑逐级'!$A$5:$A$328,$A15,'建筑逐级'!$N$5:$N$328) | R15: =SUMIF('建筑逐级'!$A$5:$A$328,$A15,'建筑逐级'!$O$5:$O$328) | S15: =SUMIF('建筑逐级'!$A$5:$A$328,$A15,'建筑逐级'!$P$5:$P$328) | T15: =SUMIF('建筑逐级'!$A$5:$A$328,$A15,'建筑逐级'!$Q$5:$Q$328) | U15: 重点观察：等级上限/成长系数/后期单级耗时
A16: juxianzhuang | B16: 聚贤庄 | C16: 人员管理 | D16: 15 | E16: =D16-'参数与公式'!$B$9 | F16: 3107 | G16: 1.5 | H16: 17164 | I16: 3432 | J16: 1.7 | K16: =SUMIFS('建筑逐级'!$L$5:$L$328,'建筑逐级'!$A$5:$A$328,$A16,'建筑逐级'!$D$5:$D$328,'参数与公式'!$B$9) | L16: =SUMIFS('建筑逐级'!$L$5:$L$328,'建筑逐级'!$A$5:$A$328,$A16,'建筑逐级'!$D$5:$D$328,$D16-1) | M16: =SUMIF('建筑逐级'!$A$5:$A$328,$A16,'建筑逐级'!$L$5:$L$328)/86400 | N16: =SUMIF('建筑逐级'!$A$5:$A$328,$A16,'建筑逐级'!$M$5:$M$328)/86400 | O16: =SUMIFS('建筑逐级'!$K$5:$K$328,'建筑逐级'!$A$5:$A$328,$A16,'建筑逐级'!$D$5:$D$328,'参数与公式'!$B$9) | P16: =SUMIFS('建筑逐级'!$K$5:$K$328,'建筑逐级'!$A$5:$A$328,$A16,'建筑逐级'!$D$5:$D$328,$D16-1) | Q16: =SUMIF('建筑逐级'!$A$5:$A$328,$A16,'建筑逐级'!$N$5:$N$328) | R16: =SUMIF('建筑逐级'!$A$5:$A$328,$A16,'建筑逐级'!$O$5:$O$328) | S16: =SUMIF('建筑逐级'!$A$5:$A$328,$A16,'建筑逐级'!$P$5:$P$328) | T16: =SUMIF('建筑逐级'!$A$5:$A$328,$A16,'建筑逐级'!$Q$5:$Q$328) | U16: 重点观察：等级上限/成长系数/后期单级耗时
... A25: arrow_tower | B25: 箭塔 | C25: 城防建筑 | D25: 10 | E25: =D25-'参数与公式'!$B$9 | F25: 1200 | G25: 1.85 | H25: 18000 | I25: 0 | J25: 1.85 | K25: =SUMIFS('建筑逐级'!$L$5:$L$328,'建筑逐级'!$A$5:$A$328,$A25,'建筑逐级'!$D$5:$D$328,'参数与公式'!$B$9) | L25: =SUMIFS('建筑逐级'!$L$5:$L$328,'建筑逐级'!$A$5:$A$328,$A25,'建筑逐级'!$D$5:$D$328,$D25-1) | M25: =SUMIF('建筑逐级'!$A$5:$A$328,$A25,'建筑逐级'!$L$5:$L$328)/86400 | N25: =SUMIF('建筑逐级'!$A$5:$A$328,$A25,'建筑逐级'!$M$5:$M$328)/86400 | O25: =SUMIFS('建筑逐级'!$K$5:$K$328,'建筑逐级'!$A$5:$A$328,$A25,'建筑逐级'!$D$5:$D$328,'参数与公式'!$B$9) | P25: =SUMIFS('建筑逐级'!$K$5:$K$328,'建筑逐级'!$A$5:$A$328,$A25,'建筑逐级'!$D$5:$D$328,$D25-1) | Q25: =SUMIF('建筑逐级'!$A$5:$A$328,$A25,'建筑逐级'!$N$5:$N$328) | R25: =SUMIF('建筑逐级'!$A$5:$A$328,$A25,'建筑逐级'!$O$5:$O$328) | S25: =SUMIF('建筑逐级'!$A$5:$A$328,$A25,'建筑逐级'!$P$5:$P$328) | T25: =SUMIF('建筑逐级'!$A$5:$A$328,$A25,'建筑逐级'!$Q$5:$Q$328) | U25: 重点观察：等级上限/成长系数/后期单级耗时

Sheet 建筑逐级
A1: 建筑逐级升级明细
A2: 改动前配置基线的逐级明细；预算型公式方案请查看“建筑建议总览/建筑建议逐级”。
A4: 建筑Key | B4: 建筑 | C4: 分类 | D4: 当前等级 | E4: 目标等级 | F4: 基础时间(s) | G4: 时间成长 | H4: 基础银两 | I4: 基础粮食 | J4: 成本成长 | K4: 配置时长(s) | L4: 基准实耗时(s) | M4: 祠堂5级实耗时(s) | N4: 配置银两 | O4: 配置粮食 | P4: 建筑学10级银两 | Q4: 建筑学10级粮食 | R4: 数据来源
A5: farm | B5: 农田 | C5: 资源生产 | D5: 1 | E5: =D5+1 | F5: 180 | G5: 1.22 | H5: 170 | I5: 0 | J5: 1.33 | K5: =ROUNDUP(F5*POWER(G5,D5),0) | L5: =MAX(1,ROUNDDOWN(K5/'参数与公式'!$B$5,0)) | M5: =MAX(1,ROUNDDOWN(K5*(1-'参数与公式'!$B$14)/'参数与公式'!$B$5,0)) | N5: =IF(H5=0,0,ROUNDUP(H5*POWER(J5,D5),0)) | O5: =IF(I5=0,0,ROUNDUP(I5*POWER(J5,D5),0)) | P5: =IF(N5=0,0,MAX(1,ROUNDUP(N5*(1-'参数与公式'!$B$17),0))) | Q5: =IF(O5=0,0,MAX(1,ROUNDUP(O5*(1-'参数与公式'!$B$17),0))) | R5: data/building_templates.yaml; max_level: gameplay/constants.py; formula: gameplay/models/manor.py
A6: farm | B6: 农田 | C6: 资源生产 | D6: 2 | E6: =D6+1 | F6: 180 | G6: 1.22 | H6: 170 | I6: 0 | J6: 1.33 | K6: =ROUNDUP(F6*POWER(G6,D6),0) | L6: =MAX(1,ROUNDDOWN(K6/'参数与公式'!$B$5,0)) | M6: =MAX(1,ROUNDDOWN(K6*(1-'参数与公式'!$B$14)/'参数与公式'!$B$5,0)) | N6: =IF(H6=0,0,ROUNDUP(H6*POWER(J6,D6),0)) | O6: =IF(I6=0,0,ROUNDUP(I6*POWER(J6,D6),0)) | P6: =IF(N6=0,0,MAX(1,ROUNDUP(N6*(1-'参数与公式'!$B$17),0))) | Q6: =IF(O6=0,0,MAX(1,ROUNDUP(O6*(1-'参数与公式'!$B$17),0))) | R6: data/building_templates.yaml; max_level: gameplay/constants.py; formula: gameplay/models/manor.py
A7: farm | B7: 农田 | C7: 资源生产 | D7: 3 | E7: =D7+1 | F7: 180 | G7: 1.22 | H7: 170 | I7: 0 | J7: 1.33 | K7: =ROUNDUP(F7*POWER(G7,D7),0) | L7: =MAX(1,ROUNDDOWN(K7/'参数与公式'!$B$5,0)) | M7: =MAX(1,ROUNDDOWN(K7*(1-'参数与公式'!$B$14)/'参数与公式'!$B$5,0)) | N7: =IF(H7=0,0,ROUNDUP(H7*POWER(J7,D7),0)) | O7: =IF(I7=0,0,ROUNDUP(I7*POWER(J7,D7),0)) | P7: =IF(N7=0,0,MAX(1,ROUNDUP(N7*(1-'参数与公式'!$B$17),0))) | Q7: =IF(O7=0,0,MAX(1,ROUNDUP(O7*(1-'参数与公式'!$B$17),0))) | R7: data/building_templates.yaml; max_level: gameplay/constants.py; formula: gameplay/models/manor.py
A8: farm | B8: 农田 | C8: 资源生产 | D8: 4 | E8: =D8+1 | F8: 180 | G8: 1.22 | H8: 170 | I8: 0 | J8: 1.33 | K8: =ROUNDUP(F8*POWER(G8,D8),0) | L8: =MAX(1,ROUNDDOWN(K8/'参数与公式'!$B$5,0)) | M8: =MAX(1,ROUNDDOWN(K8*(1-'参数与公式'!$B$14)/'参数与公式'!$B$5,0)) | N8: =IF(H8=0,0,ROUNDUP(H8*POWER(J8,D8),0)) | O8: =IF(I8=0,0,ROUNDUP(I8*POWER(J8,D8),0)) | P8: =IF(N8=0,0,MAX(1,ROUNDUP(N8*(1-'参数与公式'!$B$17),0))) | Q8: =IF(O8=0,0,MAX(1,ROUNDUP(O8*(1-'参数与公式'!$B$17),0))) | R8: data/building_templates.yaml; max_level: gameplay/constants.py; formula: gameplay/models/manor.py
A9: farm | B9: 农田 | C9: 资源生产 | D9: 5 | E9: =D9+1 | F9: 180 | G9: 1.22 | H9: 170 | I9: 0 | J9: 1.33 | K9: =ROUNDUP(F9*POWER(G9,D9),0) | L9: =MAX(1,ROUNDDOWN(K9/'参数与公式'!$B$5,0)) | M9: =MAX(1,ROUNDDOWN(K9*(1-'参数与公式'!$B$14)/'参数与公式'!$B$5,0)) | N9: =IF(H9=0,0,ROUNDUP(H9*POWER(J9,D9),0)) | O9: =IF(I9=0,0,ROUNDUP(I9*POWER(J9,D9),0)) | P9: =IF(N9=0,0,MAX(1,ROUNDUP(N9*(1-'参数与公式'!$B$17),0))) | Q9: =IF(O9=0,0,MAX(1,ROUNDUP(O9*(1-'参数与公式'!$B$17),0))) | R9: data/building_templates.yaml; max_level: gameplay/constants.py; formula: gameplay/models/manor.py
A10: farm | B10: 农田 | C10: 资源生产 | D10: 6 | E10: =D10+1 | F10: 180 | G10: 1.22 | H10: 170 | I10: 0 | J10: 1.33 | K10: =ROUNDUP(F10*POWER(G10,D10),0) | L10: =MAX(1,ROUNDDOWN(K10/'参数与公式'!$B$5,0)) | M10: =MAX(1,ROUNDDOWN(K10*(1-'参数与公式'!$B$14)/'参数与公式'!$B$5,0)) | N10: =IF(H10=0,0,ROUNDUP(H10*POWER(J10,D10),0)) | O10: =IF(I10=0,0,ROUNDUP(I10*POWER(J10,D10),0)) | P10: =IF(N10=0,0,MAX(1,ROUNDUP(N10*(1-'参数与公式'!$B$17),0))) | Q10: =IF(O10=0,0,MAX(1,ROUNDUP(O10*(1-'参数与公式'!$B$17),0))) | R10: data/building_templates.yaml; max_level: gameplay/constants.py; formula: gameplay/models/manor.py
A11: farm | B11: 农田 | C11: 资源生产 | D11: 7 | E11: =D11+1 | F11: 180 | G11: 1.22 | H11: 170 | I11: 0 | J11: 1.33 | K11: =ROUNDUP(F11*POWER(G11,D11),0) | L11: =MAX(1,ROUNDDOWN(K11/'参数与公式'!$B$5,0)) | M11: =MAX(1,ROUNDDOWN(K11*(1-'参数与公式'!$B$14)/'参数与公式'!$B$5,0)) | N11: =IF(H11=0,0,ROUNDUP(H11*POWER(J11,D11),0)) | O11: =IF(I11=0,0,ROUNDUP(I11*POWER(J11,D11),0)) | P11: =IF(N11=0,0,MAX(1,ROUNDUP(N11*(1-'参数与公式'!$B$17),0))) | Q11: =IF(O11=0,0,MAX(1,ROUNDUP(O11*(1-'参数与公式'!$B$17),0))) | R11: data/building_templates.yaml; max_level: gameplay/constants.py; formula: gameplay/models/manor.py
A12: farm | B12: 农田 | C12: 资源生产 | D12: 8 | E12: =D12+1 | F12: 180 | G12: 1.22 | H12: 170 | I12: 0 | J12: 1.33 | K12: =ROUNDUP(F12*POWER(G12,D12),0) | L12: =MAX(1,ROUNDDOWN(K12/'参数与公式'!$B$5,0)) | M12: =MAX(1,ROUNDDOWN(K12*(1-'参数与公式'!$B$14)/'参数与公式'!$B$5,0)) | N12: =IF(H12=0,0,ROUNDUP(H12*POWER(J12,D12),0)) | O12: =IF(I12=0,0,ROUNDUP(I12*POWER(J12,D12),0)) | P12: =IF(N12=0,0,MAX(1,ROUNDUP(N12*(1-'参数与公式'!$B$17),0))) | Q12: =IF(O12=0,0,MAX(1,ROUNDUP(O12*(1-'参数与公式'!$B$17),0))) | R12: data/building_templates.yaml; max_level: gameplay/constants.py; formula: gameplay/models/manor.py
A13: farm | B13: 农田 | C13: 资源生产 | D13: 9 | E13: =D13+1 | F13: 180 | G13: 1.22 | H13: 170 | I13: 0 | J13: 1.33 | K13: =ROUNDUP(F13*POWER(G13,D13),0) | L13: =MAX(1,ROUNDDOWN(K13/'参数与公式'!$B$5,0)) | M13: =MAX(1,ROUNDDOWN(K13*(1-'参数与公式'!$B$14)/'参数与公式'!$B$5,0)) | N13: =IF(H13=0,0,ROUNDUP(H13*POWER(J13,D13),0)) | O13: =IF(I13=0,0,ROUNDUP(I13*POWER(J13,D13),0)) | P13: =IF(N13=0,0,MAX(1,ROUNDUP(N13*(1-'参数与公式'!$B$17),0))) | Q13: =IF(O13=0,0,MAX(1,ROUNDUP(O13*(1-'参数与公式'!$B$17),0))) | R13: data/building_templates.yaml; max_level: gameplay/constants.py; formula: gameplay/models/manor.py
A14: farm | B14: 农田 | C14: 资源生产 | D14: 10 | E14: =D14+1 | F14: 180 | G14: 1.22 | H14: 170 | I14: 0 | J14: 1.33 | K14: =ROUNDUP(F14*POWER(G14,D14),0) | L14: =MAX(1,ROUNDDOWN(K14/'参数与公式'!$B$5,0)) | M14: =MAX(1,ROUNDDOWN(K14*(1-'参数与公式'!$B$14)/'参数与公式'!$B$5,0)) | N14: =IF(H14=0,0,ROUNDUP(H14*POWER(J14,D14),0)) | O14: =IF(I14=0,0,ROUNDUP(I14*POWER(J14,D14),0)) | P14: =IF(N14=0,0,MAX(1,ROUNDUP(N14*(1-'参数与公式'!$B$17),0))) | Q14: =IF(O14=0,0,MAX(1,ROUNDUP(O14*(1-'参数与公式'!$B$17),0))) | R14: data/building_templates.yaml; max_level: gameplay/constants.py; formula: gameplay/models/manor.py
A15: farm | B15: 农田 | C15: 资源生产 | D15: 11 | E15: =D15+1 | F15: 180 | G15: 1.22 | H15: 170 | I15: 0 | J15: 1.33 | K15: =ROUNDUP(F15*POWER(G15,D15),0) | L15: =MAX(1,ROUNDDOWN(K15/'参数与公式'!$B$5,0)) | M15: =MAX(1,ROUNDDOWN(K15*(1-'参数与公式'!$B$14)/'参数与公式'!$B$5,0)) | N15: =IF(H15=0,0,ROUNDUP(H15*POWER(J15,D15),0)) | O15: =IF(I15=0,0,ROUNDUP(I15*POWER(J15,D15),0)) | P15: =IF(N15=0,0,MAX(1,ROUNDUP(N15*(1-'参数与公式'!$B$17),0))) | Q15: =IF(O15=0,0,MAX(1,ROUNDUP(O15*(1-'参数与公式'!$B$17),0))) | R15: data/building_templates.yaml; max_level: gameplay/constants.py; formula: gameplay/models/manor.py
A16: farm | B16: 农田 | C16: 资源生产 | D16: 12 | E16: =D16+1 | F16: 180 | G16: 1.22 | H16: 170 | I16: 0 | J16: 1.33 | K16: =ROUNDUP(F16*POWER(G16,D16),0) | L16: =MAX(1,ROUNDDOWN(K16/'参数与公式'!$B$5,0)) | M16: =MAX(1,ROUNDDOWN(K16*(1-'参数与公式'!$B$14)/'参数与公式'!$B$5,0)) | N16: =IF(H16=0,0,ROUNDUP(H16*POWER(J16,D16),0)) | O16: =IF(I16=0,0,ROUNDUP(I16*POWER(J16,D16),0)) | P16: =IF(N16=0,0,MAX(1,ROUNDUP(N16*(1-'参数与公式'!$B$17),0))) | Q16: =IF(O16=0,0,MAX(1,ROUNDUP(O16*(1-'参数与公式'!$B$17),0))) | R16: data/building_templates.yaml; max_level: gameplay/constants.py; formula: gameplay/models/manor.py
... A328: arrow_tower | B328: 箭塔 | C328: 城防建筑 | D328: 9 | E328: =D328+1 | F328: 1200 | G328: 1.85 | H328: 18000 | I328: 0 | J328: 1.85 | K328: =ROUNDUP(F328*POWER(G328,D328),0) | L328: =MAX(1,ROUNDDOWN(K328/'参数与公式'!$B$5,0)) | M328: =MAX(1,ROUNDDOWN(K328*(1-'参数与公式'!$B$14)/'参数与公式'!$B$5,0)) | N328: =IF(H328=0,0,ROUNDUP(H328*POWER(J328,D328),0)) | O328: =IF(I328=0,0,ROUNDUP(I328*POWER(J328,D328),0)) | P328: =IF(N328=0,0,MAX(1,ROUNDUP(N328*(1-'参数与公式'!$B$17),0))) | Q328: =IF(O328=0,0,MAX(1,ROUNDUP(O328*(1-'参数与公式'!$B$17),0))) | R328: data/building_templates.yaml; max_level: gameplay/constants.py; formula: gameplay/models/manor.py

Sheet 建筑建议总览
A1: 建筑建议方案总览｜总预算 + 逐级增长曲线（前期保护版）
A2: 黄色为建议输入/目标，绿色为公式或基线引用。总预算控制满级累计量；逐级增长系数控制相邻等级增幅，不设末级/首级固定倍数；时长为配置游戏秒数，未计祠堂缩时与全局倍率。
A4: 建筑Key | B4: 建筑 | C4: 功能分类 | D4: 最高等级 | E4: 升级次数 | F4: 当前基础时间(s) | G4: 当前时间成长 | H4: 建议基础时间底线(s) | I4: 时长逐级增长系数 | J4: 建议时长预算(s) | K4: 用户目标时间(天) | L4: 建议总时长(天) | M4: 偏差(天) | N4: 当前基础银两 | O4: 当前成本成长 | P4: 建议基础银两底线 | Q4: 建议基础粮食底线 | R4: 成本逐级增长系数 | S4: 建议银两预算 | T4: 建议粮食预算 | U4: 用户目标银两 | V4: 建议总银两 | W4: 偏差 | X4: 建议总粮食 | Y4: 粮银比 | Z4: 调整策略 | AA4: 功能与平衡说明
A5: farm | B5: 农田 | C5: 资源生产 | D5: 50 | E5: =D5-'参数与公式'!$B$9 | F5: ='建筑总览'!$F$5 | G5: ='建筑总览'!$G$5 | H5: 180 | I5: 1.1 | J5: 1728000 | K5: 20 | L5: =SUMIF('建筑建议逐级'!$A$5:$A$328,$A5,'建筑建议逐级'!$M$5:$M$328)/'参数与公式'!$B$21 | M5: =IF(ISNUMBER(K5),L5-K5,"—") | N5: ='建筑总览'!$H$5 | O5: ='建筑总览'!$J$5 | P5: 170 | Q5: 0 | R5: 1.18 | S5: 5000000 | T5: 0 | U5: 5000000 | V5: =SUMIF('建筑建议逐级'!$A$5:$A$328,$A5,'建筑建议逐级'!$X$5:$X$328) | W5: =IF(ISNUMBER(U5),V5-U5,"—") | X5: =SUMIF('建筑建议逐级'!$A$5:$A$328,$A5,'建筑建议逐级'!$Y$5:$Y$328) | Y5: =IF(V5=0,0,X5/V5) | Z5: 基础资源建筑：总预算控制，逐级增长曲线 | AA5: 不再用高指数把末级拉成数天；总预算分布到49次升级。
A6: tax_office | B6: 税务司 | C6: 资源生产 | D6: 30 | E6: =D6-'参数与公式'!$B$9 | F6: ='建筑总览'!$F$6 | G6: ='建筑总览'!$G$6 | H6: 210 | I6: 1.1 | J6: 1728000 | K6: 20 | L6: =SUMIF('建筑建议逐级'!$A$5:$A$328,$A6,'建筑建议逐级'!$M$5:$M$328)/'参数与公式'!$B$21 | M6: =IF(ISNUMBER(K6),L6-K6,"—") | N6: ='建筑总览'!$H$6 | O6: ='建筑总览'!$J$6 | P6: 450 | Q6: 0 | R6: 1.45 | S6: 5000000 | T6: 0 | U6: 5000000 | V6: =SUMIF('建筑建议逐级'!$A$5:$A$328,$A6,'建筑建议逐级'!$X$5:$X$328) | W6: =IF(ISNUMBER(U6),V6-U6,"—") | X6: =SUMIF('建筑建议逐级'!$A$5:$A$328,$A6,'建筑建议逐级'!$Y$5:$Y$328) | Y6: =IF(V6=0,0,X6/V6) | Z6: 资源产出建筑：总预算控制，相邻级平滑增长 | AA6: 与农田同一基础资源档位，但按30级自然形成更长单级时长。
A7: bathhouse | B7: 澡堂 | C7: 资源生产 | D7: 20 | E7: =D7-'参数与公式'!$B$9 | F7: ='建筑总览'!$F$7 | G7: ='建筑总览'!$G$7 | H7: 300 | I7: 1.08 | J7: 864000 | K7: 10 | L7: =SUMIF('建筑建议逐级'!$A$5:$A$328,$A7,'建筑建议逐级'!$M$5:$M$328)/'参数与公式'!$B$21 | M7: =IF(ISNUMBER(K7),L7-K7,"—") | N7: ='建筑总览'!$H$7 | O7: ='建筑总览'!$J$7 | P7: 850 | Q7: 0 | R7: 1.4 | S7: 2000000 | T7: 0 | U7: 2000000 | V7: =SUMIF('建筑建议逐级'!$A$5:$A$328,$A7,'建筑建议逐级'!$X$5:$X$328) | W7: =IF(ISNUMBER(U7),V7-U7,"—") | X7: =SUMIF('建筑建议逐级'!$A$5:$A$328,$A7,'建筑建议逐级'!$Y$5:$Y$328) | Y7: =IF(V7=0,0,X7/V7) | Z7: 生活设施：平滑预算曲线，避免早期过重 | AA7: 早期可升级，后期仍有明显投入感。
A8: latrine | B8: 茅厕 | C8: 资源生产 | D8: 20 | E8: =D8-'参数与公式'!$B$9 | F8: ='建筑总览'!$F$8 | G8: ='建筑总览'!$G$8 | H8: 300 | I8: 1.08 | J8: 864000 | K8: 10 | L8: =SUMIF('建筑建议逐级'!$A$5:$A$328,$A8,'建筑建议逐级'!$M$5:$M$328)/'参数与公式'!$B$21 | M8: =IF(ISNUMBER(K8),L8-K8,"—") | N8: ='建筑总览'!$H$8 | O8: ='建筑总览'!$J$8 | P8: 550 | Q8: 0 | R8: 1.4 | S8: 2000000 | T8: 0 | U8: 2000000 | V8: =SUMIF('建筑建议逐级'!$A$5:$A$328,$A8,'建筑建议逐级'!$X$5:$X$328) | W8: =IF(ISNUMBER(U8),V8-U8,"—") | X8: =SUMIF('建筑建议逐级'!$A$5:$A$328,$A8,'建筑建议逐级'!$Y$5:$Y$328) | Y8: =IF(V8=0,0,X8/V8) | Z8: 生活设施：平滑预算曲线，避免早期过重 | AA8: 基础民生设施，升级压力和澡堂保持同档。
A9: granary | B9: 粮仓 | C9: 仓储设施 | D9: 20 | E9: =D9-'参数与公式'!$B$9 | F9: ='建筑总览'!$F$9 | G9: ='建筑总览'!$G$9 | H9: 300 | I9: 1.08 | J9: 1728000 | K9: 20 | L9: =SUMIF('建筑建议逐级'!$A$5:$A$328,$A9,'建筑建议逐级'!$M$5:$M$328)/'参数与公式'!$B$21 | M9: =IF(ISNUMBER(K9),L9-K9,"—") | N9: ='建筑总览'!$H$9 | O9: ='建筑总览'!$J$9 | P9: 950 | Q9: 0 | R9: 1.5 | S9: 5000000 | T9: 0 | U9: 5000000 | V9: =SUMIF('建筑建议逐级'!$A$5:$A$328,$A9,'建筑建议逐级'!$X$5:$X$328) | W9: =IF(ISNUMBER(U9),V9-U9,"—") | X9: =SUMIF('建筑建议逐级'!$A$5:$A$328,$A9,'建筑建议逐级'!$Y$5:$Y$328) | Y9: =IF(V9=0,0,X9/V9) | Z9: 仓储建筑：20日时长预算，500万银两成本预算 | AA9: 粮仓满级累计时间约20天、银两约500万；时间与成本分别归一化，升级节奏保持平滑。
A10: silver_vault | B10: 银库 | C10: 仓储设施 | D10: 30 | E10: =D10-'参数与公式'!$B$9 | F10: ='建筑总览'!$F$10 | G10: ='建筑总览'!$G$10 | H10: 300 | I10: 1.08 | J10: 2592000 | K10: 30 | L10: =SUMIF('建筑建议逐级'!$A$5:$A$328,$A10,'建筑建议逐级'!$M$5:$M$328)/'参数与公式'!$B$21 | M10: =IF(ISNUMBER(K10),L10-K10,"—") | N10: ='建筑总览'!$H$10 | O10: ='建筑总览'!$J$10 | P10: 1100 | Q10: 0 | R10: 1 | S10: 0 | T10: 0 | V10: =SUMIF('建筑建议逐级'!$A$5:$A$328,$A10,'建筑建议逐级'!$X$5:$X$328) | W10: =IF(ISNUMBER(U10),V10-U10,"—") | X10: =SUMIF('建筑建议逐级'!$A$5:$A$328,$A10,'建筑建议逐级'!$Y$5:$Y$328) | Y10: =IF(V10=0,0,X10/V10) | Z10: 只控制时间预算，容量成本沿用现状 | AA10: 30日是时间预算，成本保留原稀缺性。
A11: treasury | B11: 藏宝阁 | C11: 仓储设施 | D11: 20 | E11: =D11-'参数与公式'!$B$9 | F11: ='建筑总览'!$F$11 | G11: ='建筑总览'!$G$11 | H11: 600 | I11: 1.08 | J11: 2592000 | K11: 30 | L11: =SUMIF('建筑建议逐级'!$A$5:$A$328,$A11,'建筑建议逐级'!$M$5:$M$328)/'参数与公式'!$B$21 | M11: =IF(ISNUMBER(K11),L11-K11,"—") | N11: ='建筑总览'!$H$11 | O11: ='建筑总览'!$J$11 | P11: 7500 | Q11: 0 | R11: 1 | S11: 0 | T11: 0 | V11: =SUMIF('建筑建议逐级'!$A$5:$A$328,$A11,'建筑建议逐级'!$X$5:$X$328) | W11: =IF(ISNUMBER(U11),V11-U11,"—") | X11: =SUMIF('建筑建议逐级'!$A$5:$A$328,$A11,'建筑建议逐级'!$Y$5:$Y$328) | Y11: =IF(V11=0,0,X11/V11) | Z11: 只控制时间预算，珍稀物品成本沿用现状 | AA11: 30日是时间预算，成本保留高价值存储定位。
A12: ranch | B12: 畜牧场 | C12: 生产加工 | D12: 10 | E12: =D12-'参数与公式'!$B$9 | F12: ='建筑总览'!$F$12 | G12: ='建筑总览'!$G$12 | H12: 300 | I12: 1.08 | J12: 864000 | K12: 10 | L12: =SUMIF('建筑建议逐级'!$A$5:$A$328,$A12,'建筑建议逐级'!$M$5:$M$328)/'参数与公式'!$B$21 | M12: =IF(ISNUMBER(K12),L12-K12,"—") | N12: ='建筑总览'!$H$12 | O12: ='建筑总览'!$J$12 | P12: 800 | Q12: 0 | R12: 1.2 | S12: 1000000 | T12: 0 | U12: 1000000 | V12: =SUMIF('建筑建议逐级'!$A$5:$A$328,$A12,'建筑建议逐级'!$X$5:$X$328) | W12: =IF(ISNUMBER(U12),V12-U12,"—") | X12: =SUMIF('建筑建议逐级'!$A$5:$A$328,$A12,'建筑建议逐级'!$Y$5:$Y$328) | Y12: =IF(V12=0,0,X12/V12) | Z12: 生产建筑：统一10日/100万档位 | AA12: 同类生产建筑使用同一预算曲线，减少无意义的指数差异。
A13: smithy | B13: 冶炼坊 | C13: 生产加工 | D13: 10 | E13: =D13-'参数与公式'!$B$9 | F13: ='建筑总览'!$F$13 | G13: ='建筑总览'!$G$13 | H13: 300 | I13: 1.08 | J13: 864000 | K13: 10 | L13: =SUMIF('建筑建议逐级'!$A$5:$A$328,$A13,'建筑建议逐级'!$M$5:$M$328)/'参数与公式'!$B$21 | M13: =IF(ISNUMBER(K13),L13-K13,"—") | N13: ='建筑总览'!$H$13 | O13: ='建筑总览'!$J$13 | P13: 1000 | Q13: 0 | R13: 1.2 | S13: 1000000 | T13: 0 | U13: 1000000 | V13: =SUMIF('建筑建议逐级'!$A$5:$A$328,$A13,'建筑建议逐级'!$X$5:$X$328) | W13: =IF(ISNUMBER(U13),V13-U13,"—") | X13: =SUMIF('建筑建议逐级'!$A$5:$A$328,$A13,'建筑建议逐级'!$Y$5:$Y$328) | Y13: =IF(V13=0,0,X13/V13) | Z13: 生产建筑：统一10日/100万档位 | AA13: 同类生产建筑使用同一预算曲线，减少无意义的指数差异。
A14: stable | B14: 马房 | C14: 生产加工 | D14: 10 | E14: =D14-'参数与公式'!$B$9 | F14: ='建筑总览'!$F$14 | G14: ='建筑总览'!$G$14 | H14: 300 | I14: 1.08 | J14: 864000 | K14: 10 | L14: =SUMIF('建筑建议逐级'!$A$5:$A$328,$A14,'建筑建议逐级'!$M$5:$M$328)/'参数与公式'!$B$21 | M14: =IF(ISNUMBER(K14),L14-K14,"—") | N14: ='建筑总览'!$H$14 | O14: ='建筑总览'!$J$14 | P14: 980 | Q14: 0 | R14: 1.2 | S14: 1000000 | T14: 0 | U14: 1000000 | V14: =SUMIF('建筑建议逐级'!$A$5:$A$328,$A14,'建筑建议逐级'!$X$5:$X$328) | W14: =IF(ISNUMBER(U14),V14-U14,"—") | X14: =SUMIF('建筑建议逐级'!$A$5:$A$328,$A14,'建筑建议逐级'!$Y$5:$Y$328) | Y14: =IF(V14=0,0,X14/V14) | Z14: 生产建筑：统一10日/100万档位 | AA14: 同类生产建筑使用同一预算曲线，减少无意义的指数差异。
A15: forge | B15: 铁匠铺 | C15: 生产加工 | D15: 10 | E15: =D15-'参数与公式'!$B$9 | F15: ='建筑总览'!$F$15 | G15: ='建筑总览'!$G$15 | H15: 300 | I15: 1.08 | J15: 864000 | K15: 10 | L15: =SUMIF('建筑建议逐级'!$A$5:$A$328,$A15,'建筑建议逐级'!$M$5:$M$328)/'参数与公式'!$B$21 | M15: =IF(ISNUMBER(K15),L15-K15,"—") | N15: ='建筑总览'!$H$15 | O15: ='建筑总览'!$J$15 | P15: 500 | Q15: 500 | R15: 1.2 | S15: 1000000 | T15: 1000000 | U15: 1000000 | V15: =SUMIF('建筑建议逐级'!$A$5:$A$328,$A15,'建筑建议逐级'!$X$5:$X$328) | W15: =IF(ISNUMBER(U15),V15-U15,"—") | X15: =SUMIF('建筑建议逐级'!$A$5:$A$328,$A15,'建筑建议逐级'!$Y$5:$Y$328) | Y15: =IF(V15=0,0,X15/V15) | Z15: 生产建筑：粮银预算各100万，比例不变 | AA15: 粮银均按现有1:1比例配置预算。
A16: juxianzhuang | B16: 聚贤庄 | C16: 人员管理 | D16: 15 | E16: =D16-'参数与公式'!$B$9 | F16: ='建筑总览'!$F$16 | G16: ='建筑总览'!$G$16 | H16: 3107 | I16: 1.1 | J16: 15552000 | K16: 180 | L16: =SUMIF('建筑建议逐级'!$A$5:$A$328,$A16,'建筑建议逐级'!$M$5:$M$328)/'参数与公式'!$B$21 | M16: =IF(ISNUMBER(K16),L16-K16,"—") | N16: ='建筑总览'!$H$16 | O16: ='建筑总览'!$J$16 | P16: 17164 | Q16: 3432 | R16: 1 | S16: 0 | T16: 0 | V16: =SUMIF('建筑建议逐级'!$A$5:$A$328,$A16,'建筑建议逐级'!$X$5:$X$328) | W16: =IF(ISNUMBER(U16),V16-U16,"—") | X16: =SUMIF('建筑建议逐级'!$A$5:$A$328,$A16,'建筑建议逐级'!$Y$5:$Y$328) | Y16: =IF(V16=0,0,X16/V16) | Z16: 容量核心：180日预算，后段适度加重 | AA16: 180天长线建筑：时长按逐级增长曲线分配；银两总额未设用户目标，成本先保留现状并建议配合后期解锁条件。
A17: jiadingfang | B17: 家丁房 | C17: 人员管理 | D17: 30 | E17: =D17-'参数与公式'!$B$9 | F17: ='建筑总览'!$F$17 | G17: ='建筑总览'!$G$17 | H17: 300 | I17: 1.08 | J17: 2160000 | K17: 25 | L17: =SUMIF('建筑建议逐级'!$A$5:$A$328,$A17,'建筑建议逐级'!$M$5:$M$328)/'参数与公式'!$B$21 | M17: =IF(ISNUMBER(K17),L17-K17,"—") | N17: ='建筑总览'!$H$17 | O17: ='建筑总览'!$J$17 | P17: 420 | Q17: 0 | R17: 1 | S17: 0 | T17: 0 | V17: =SUMIF('建筑建议逐级'!$A$5:$A$328,$A17,'建筑建议逐级'!$X$5:$X$328) | W17: =IF(ISNUMBER(U17),V17-U17,"—") | X17: =SUMIF('建筑建议逐级'!$A$5:$A$328,$A17,'建筑建议逐级'!$Y$5:$Y$328) | Y17: =IF(V17=0,0,X17/V17) | Z17: 容量建筑：25日预算，成本沿用现状 | AA17: 容量成长较长，但保持低于聚贤庄级别。
A18: lianggongchang | B18: 练功场 | C18: 人员管理 | D18: 10 | E18: =D18-'参数与公式'!$B$9 | F18: ='建筑总览'!$F$18 | G18: ='建筑总览'!$G$18 | H18: 300 | I18: 1.08 | J18: 864000 | K18: 10 | L18: =SUMIF('建筑建议逐级'!$A$5:$A$328,$A18,'建筑建议逐级'!$M$5:$M$328)/'参数与公式'!$B$21 | M18: =IF(ISNUMBER(K18),L18-K18,"—") | N18: ='建筑总览'!$H$18 | O18: ='建筑总览'!$J$18 | P18: 550 | Q18: 0 | R18: 1.2 | S18: 1000000 | T18: 0 | V18: =SUMIF('建筑建议逐级'!$A$5:$A$328,$A18,'建筑建议逐级'!$X$5:$X$328) | W18: =IF(ISNUMBER(U18),V18-U18,"—") | X18: =SUMIF('建筑建议逐级'!$A$5:$A$328,$A18,'建筑建议逐级'!$Y$5:$Y$328) | Y18: =IF(V18=0,0,X18/V18) | Z18: 训练建筑：统一10日/100万档位 | AA18: 训练功能与普通生产建筑共用预算档位。
A19: tavern | B19: 酒馆 | C19: 人员管理 | D19: 10 | E19: =D19-'参数与公式'!$B$9 | F19: ='建筑总览'!$F$19 | G19: ='建筑总览'!$G$19 | H19: 300 | I19: 1.08 | J19: 864000 | K19: 10 | L19: =SUMIF('建筑建议逐级'!$A$5:$A$328,$A19,'建筑建议逐级'!$M$5:$M$328)/'参数与公式'!$B$21 | M19: =IF(ISNUMBER(K19),L19-K19,"—") | N19: ='建筑总览'!$H$19 | O19: ='建筑总览'!$J$19 | P19: 1150 | Q19: 0 | R19: 1.2 | S19: 5000000 | T19: 0 | U19: 5000000 | V19: =SUMIF('建筑建议逐级'!$A$5:$A$328,$A19,'建筑建议逐级'!$X$5:$X$328) | W19: =IF(ISNUMBER(U19),V19-U19,"—") | X19: =SUMIF('建筑建议逐级'!$A$5:$A$328,$A19,'建筑建议逐级'!$Y$5:$Y$328) | Y19: =IF(V19=0,0,X19/V19) | Z19: 复合收益建筑：成本后段略高于普通生产设施 | AA19: 复合收益带来略高的成本后段曲线。
A20: citang | B20: 祠堂 | C20: 特殊建筑 | D20: 5 | E20: =D20-'参数与公式'!$B$9 | F20: ='建筑总览'!$F$20 | G20: ='建筑总览'!$G$20 | H20: 3600 | I20: 1.03 | J20: 2592000 | K20: 30 | L20: =SUMIF('建筑建议逐级'!$A$5:$A$328,$A20,'建筑建议逐级'!$M$5:$M$328)/'参数与公式'!$B$21 | M20: =IF(ISNUMBER(K20),L20-K20,"—") | N20: ='建筑总览'!$H$20 | O20: ='建筑总览'!$J$20 | P20: 10000 | Q20: 5000 | R20: 1.03 | S20: 10000000 | T20: 5000000 | U20: 10000000 | V20: =SUMIF('建筑建议逐级'!$A$5:$A$328,$A20,'建筑建议逐级'!$X$5:$X$328) | W20: =IF(ISNUMBER(U20),V20-U20,"—") | X20: =SUMIF('建筑建议逐级'!$A$5:$A$328,$A20,'建筑建议逐级'!$Y$5:$Y$328) | Y20: =IF(V20=0,0,X20/V20) | Z20: 全局增益建筑：后段曲线更强但不指数爆炸 | AA20: 4次升级共30日，后段加重但仍由总预算封顶。
A21: youxibaota | B21: 悠嘻宝塔 | C21: 特殊建筑 | D21: 15 | E21: =D21-'参数与公式'!$B$9 | F21: ='建筑总览'!$F$21 | G21: ='建筑总览'!$G$21 | H21: 3107 | I21: 1.1 | J21: 15552000 | K21: 180 | L21: =SUMIF('建筑建议逐级'!$A$5:$A$328,$A21,'建筑建议逐级'!$M$5:$M$328)/'参数与公式'!$B$21 | M21: =IF(ISNUMBER(K21),L21-K21,"—") | N21: ='建筑总览'!$H$21 | O21: ='建筑总览'!$J$21 | P21: 20193 | Q21: 4038 | R21: 1 | S21: 0 | T21: 0 | V21: =SUMIF('建筑建议逐级'!$A$5:$A$328,$A21,'建筑建议逐级'!$X$5:$X$328) | W21: =IF(ISNUMBER(U21),V21-U21,"—") | X21: =SUMIF('建筑建议逐级'!$A$5:$A$328,$A21,'建筑建议逐级'!$Y$5:$Y$328) | Y21: =IF(V21=0,0,X21/V21) | Z21: 出征容量核心：180日预算，后段适度加重 | AA21: 180天长线建筑：时长按逐级增长曲线分配；银两总额未设用户目标，成本先保留现状并建议配合后期解锁条件。
A22: jail | B22: 监牢 | C22: 特殊建筑 | D22: 5 | E22: =D22-'参数与公式'!$B$9 | F22: ='建筑总览'!$F$22 | G22: ='建筑总览'!$G$22 | H22: 600 | I22: 1.03 | J22: 2592000 | K22: 30 | L22: =SUMIF('建筑建议逐级'!$A$5:$A$328,$A22,'建筑建议逐级'!$M$5:$M$328)/'参数与公式'!$B$21 | M22: =IF(ISNUMBER(K22),L22-K22,"—") | N22: ='建筑总览'!$H$22 | O22: ='建筑总览'!$J$22 | P22: 1200 | Q22: 800 | R22: 1.03 | S22: 10000000 | T22: 6666667 | U22: 10000000 | V22: =SUMIF('建筑建议逐级'!$A$5:$A$328,$A22,'建筑建议逐级'!$X$5:$X$328) | W22: =IF(ISNUMBER(U22),V22-U22,"—") | X22: =SUMIF('建筑建议逐级'!$A$5:$A$328,$A22,'建筑建议逐级'!$Y$5:$Y$328) | Y22: =IF(V22=0,0,X22/V22) | Z22: 特殊容量建筑：高预算、可控后段溢价 | AA22: 4次升级共30日，末级约12天而非16天以上。
A23: oath_grove | B23: 结义林 | C23: 特殊建筑 | D23: 5 | E23: =D23-'参数与公式'!$B$9 | F23: ='建筑总览'!$F$23 | G23: ='建筑总览'!$G$23 | H23: 600 | I23: 1.03 | J23: 2592000 | K23: 30 | L23: =SUMIF('建筑建议逐级'!$A$5:$A$328,$A23,'建筑建议逐级'!$M$5:$M$328)/'参数与公式'!$B$21 | M23: =IF(ISNUMBER(K23),L23-K23,"—") | N23: ='建筑总览'!$H$23 | O23: ='建筑总览'!$J$23 | P23: 1200 | Q23: 800 | R23: 1.03 | S23: 10000000 | T23: 6666667 | U23: 10000000 | V23: =SUMIF('建筑建议逐级'!$A$5:$A$328,$A23,'建筑建议逐级'!$X$5:$X$328) | W23: =IF(ISNUMBER(U23),V23-U23,"—") | X23: =SUMIF('建筑建议逐级'!$A$5:$A$328,$A23,'建筑建议逐级'!$Y$5:$Y$328) | Y23: =IF(V23=0,0,X23/V23) | Z23: 社交容量建筑：高预算、可控后段溢价 | AA23: 4次升级共30日，末级约12天而非16天以上。
A24: wall | B24: 城墙 | C24: 城防建筑 | D24: 10 | E24: =D24-'参数与公式'!$B$9 | F24: ='建筑总览'!$F$24 | G24: ='建筑总览'!$G$24 | H24: 900 | I24: 1.08 | J24: 864000 | K24: 10 | L24: =SUMIF('建筑建议逐级'!$A$5:$A$328,$A24,'建筑建议逐级'!$M$5:$M$328)/'参数与公式'!$B$21 | M24: =IF(ISNUMBER(K24),L24-K24,"—") | N24: ='建筑总览'!$H$24 | O24: ='建筑总览'!$J$24 | P24: 18000 | Q24: 0 | R24: 1.1 | S24: 1000000 | T24: 0 | U24: 1000000 | V24: =SUMIF('建筑建议逐级'!$A$5:$A$328,$A24,'建筑建议逐级'!$X$5:$X$328) | W24: =IF(ISNUMBER(U24),V24-U24,"—") | X24: =SUMIF('建筑建议逐级'!$A$5:$A$328,$A24,'建筑建议逐级'!$Y$5:$Y$328) | Y24: =IF(V24=0,0,X24/V24) | Z24: 城防建筑：统一10日/100万档位 | AA24: 总成本由预算控制到约100万，时间约10日。
A25: arrow_tower | B25: 箭塔 | C25: 城防建筑 | D25: 10 | E25: =D25-'参数与公式'!$B$9 | F25: ='建筑总览'!$F$25 | G25: ='建筑总览'!$G$25 | H25: 1200 | I25: 1.08 | J25: 864000 | K25: 10 | L25: =SUMIF('建筑建议逐级'!$A$5:$A$328,$A25,'建筑建议逐级'!$M$5:$M$328)/'参数与公式'!$B$21 | M25: =IF(ISNUMBER(K25),L25-K25,"—") | N25: ='建筑总览'!$H$25 | O25: ='建筑总览'!$J$25 | P25: 18000 | Q25: 0 | R25: 1.1 | S25: 1000000 | T25: 0 | U25: 1000000 | V25: =SUMIF('建筑建议逐级'!$A$5:$A$328,$A25,'建筑建议逐级'!$X$5:$X$328) | W25: =IF(ISNUMBER(U25),V25-U25,"—") | X25: =SUMIF('建筑建议逐级'!$A$5:$A$328,$A25,'建筑建议逐级'!$Y$5:$Y$328) | Y25: =IF(V25=0,0,X25/V25) | Z25: 城防建筑：统一10日/100万档位 | AA25: 与城墙保持同一投入档位。

Sheet 建筑建议逐级
A1: 建筑建议方案逐级明细｜总预算 + 逐级增长曲线
A2: 预算模式使用显式“单级权重/权重总和/额外分配/末级余数”列，确保 Excel 与运行代码逐级结果一致；增长系数控制相邻等级增幅，未配置预算时回退旧指数公式。
A4: 建筑Key | B4: 建筑 | C4: 功能分类 | D4: 当前等级 | E4: 目标等级 | F4: 最高等级 | G4: 基础时间底线(s) | H4: 时长逐级增长系数 | I4: 时长预算(s) | J4: 时长权重 | K4: 时长权重总和 | L4: 时长额外分配(s) | M4: 建议单级时长(s) | N4: 单级时长(天) | O4: 基础银两底线 | P4: 基础粮食底线 | Q4: 成本逐级增长系数 | R4: 银两预算 | S4: 粮食预算 | T4: 成本权重 | U4: 成本权重总和 | V4: 银两额外分配 | W4: 粮食额外分配 | X4: 建议银两成本 | Y4: 建议粮食成本 | Z4: 建筑学10级银两 | AA4: 建筑学10级粮食 | AB4: 公式说明 | AC4: 时长相邻增长 | AD4: 银两相邻增长
A5: farm | B5: 农田 | C5: 资源生产 | D5: 1 | E5: =D5+1 | F5: 50 | G5: =INDEX('建筑建议总览'!$H$5:$H$25,MATCH($A5,'建筑建议总览'!$A$5:$A$25,0)) | H5: =INDEX('建筑建议总览'!$I$5:$I$25,MATCH($A5,'建筑建议总览'!$A$5:$A$25,0)) | I5: =INDEX('建筑建议总览'!$J$5:$J$25,MATCH($A5,'建筑建议总览'!$A$5:$A$25,0)) | J5: =POWER(H5,D5-1) | K5: =SUMIF($A$5:$A$328,$A5,$J$5:$J$328) | L5: =IF(I5>0,ROUNDDOWN(MAX(0,I5-G5*(F5-1))*J5/K5,0),0) | M5: =IF(I5>0,G5+L5+IF(D5=F5-1,MAX(0,I5-G5*(F5-1)-SUMIF($A$5:$A$328,$A5,$L$5:$L$328)),0),ROUNDUP(G5*POWER(INDEX('建筑总览'!$G$5:$G$25,MATCH($A5,'建筑总览'!$A$5:$A$25,0)),D5),0)) | N5: =M5/'参数与公式'!$B$21 | O5: =INDEX('建筑建议总览'!$P$5:$P$25,MATCH($A5,'建筑建议总览'!$A$5:$A$25,0)) | P5: =INDEX('建筑建议总览'!$Q$5:$Q$25,MATCH($A5,'建筑建议总览'!$A$5:$A$25,0)) | Q5: =INDEX('建筑建议总览'!$R$5:$R$25,MATCH($A5,'建筑建议总览'!$A$5:$A$25,0)) | R5: =INDEX('建筑建议总览'!$S$5:$S$25,MATCH($A5,'建筑建议总览'!$A$5:$A$25,0)) | S5: =INDEX('建筑建议总览'!$T$5:$T$25,MATCH($A5,'建筑建议总览'!$A$5:$A$25,0)) | T5: =POWER(Q5,D5-1) | U5: =SUMIF($A$5:$A$328,$A5,$T$5:$T$328) | V5: =IF(R5>0,ROUNDDOWN(MAX(0,R5-O5*(F5-1))*T5/U5,0),0) | W5: =IF(S5>0,ROUNDDOWN(MAX(0,S5-P5*(F5-1))*T5/U5,0),0) | X5: =IF(R5>0,O5+V5+IF(D5=F5-1,MAX(0,R5-O5*(F5-1)-SUMIF($A$5:$A$328,$A5,$V$5:$V$328)),0),ROUNDUP(O5*POWER(INDEX('建筑总览'!$J$5:$J$25,MATCH($A5,'建筑总览'!$A$5:$A$25,0)),D5),0)) | Y5: =IF(P5=0,0,IF(S5>0,P5+W5+IF(D5=F5-1,MAX(0,S5-P5*(F5-1)-SUMIF($A$5:$A$328,$A5,$W$5:$W$328)),0),ROUNDUP(P5*POWER(INDEX('建筑总览'!$J$5:$J$25,MATCH($A5,'建筑总览'!$A$5:$A$25,0)),D5),0))) | Z5: =IF(X5=0,0,MAX(1,ROUNDUP(X5*(1-'参数与公式'!$B$17),0))) | AA5: =IF(Y5=0,0,MAX(1,ROUNDUP(Y5*(1-'参数与公式'!$B$17),0))) | AB5: 预算模式末级补足余数；旧模式按指数公式 | AC5: =IF(A5=A4,IFERROR(M5/M4,""),"") | AD5: =IF(AND(A5=A4,X4>0),X5/X4,"")
A6: farm | B6: 农田 | C6: 资源生产 | D6: 2 | E6: =D6+1 | F6: 50 | G6: =INDEX('建筑建议总览'!$H$5:$H$25,MATCH($A6,'建筑建议总览'!$A$5:$A$25,0)) | H6: =INDEX('建筑建议总览'!$I$5:$I$25,MATCH($A6,'建筑建议总览'!$A$5:$A$25,0)) | I6: =INDEX('建筑建议总览'!$J$5:$J$25,MATCH($A6,'建筑建议总览'!$A$5:$A$25,0)) | J6: =POWER(H6,D6-1) | K6: =SUMIF($A$5:$A$328,$A6,$J$5:$J$328) | L6: =IF(I6>0,ROUNDDOWN(MAX(0,I6-G6*(F6-1))*J6/K6,0),0) | M6: =IF(I6>0,G6+L6+IF(D6=F6-1,MAX(0,I6-G6*(F6-1)-SUMIF($A$5:$A$328,$A6,$L$5:$L$328)),0),ROUNDUP(G6*POWER(INDEX('建筑总览'!$G$5:$G$25,MATCH($A6,'建筑总览'!$A$5:$A$25,0)),D6),0)) | N6: =M6/'参数与公式'!$B$21 | O6: =INDEX('建筑建议总览'!$P$5:$P$25,MATCH($A6,'建筑建议总览'!$A$5:$A$25,0)) | P6: =INDEX('建筑建议总览'!$Q$5:$Q$25,MATCH($A6,'建筑建议总览'!$A$5:$A$25,0)) | Q6: =INDEX('建筑建议总览'!$R$5:$R$25,MATCH($A6,'建筑建议总览'!$A$5:$A$25,0)) | R6: =INDEX('建筑建议总览'!$S$5:$S$25,MATCH($A6,'建筑建议总览'!$A$5:$A$25,0)) | S6: =INDEX('建筑建议总览'!$T$5:$T$25,MATCH($A6,'建筑建议总览'!$A$5:$A$25,0)) | T6: =POWER(Q6,D6-1) | U6: =SUMIF($A$5:$A$328,$A6,$T$5:$T$328) | V6: =IF(R6>0,ROUNDDOWN(MAX(0,R6-O6*(F6-1))*T6/U6,0),0) | W6: =IF(S6>0,ROUNDDOWN(MAX(0,S6-P6*(F6-1))*T6/U6,0),0) | X6: =IF(R6>0,O6+V6+IF(D6=F6-1,MAX(0,R6-O6*(F6-1)-SUMIF($A$5:$A$328,$A6,$V$5:$V$328)),0),ROUNDUP(O6*POWER(INDEX('建筑总览'!$J$5:$J$25,MATCH($A6,'建筑总览'!$A$5:$A$25,0)),D6),0)) | Y6: =IF(P6=0,0,IF(S6>0,P6+W6+IF(D6=F6-1,MAX(0,S6-P6*(F6-1)-SUMIF($A$5:$A$328,$A6,$W$5:$W$328)),0),ROUNDUP(P6*POWER(INDEX('建筑总览'!$J$5:$J$25,MATCH($A6,'建筑总览'!$A$5:$A$25,0)),D6),0))) | Z6: =IF(X6=0,0,MAX(1,ROUNDUP(X6*(1-'参数与公式'!$B$17),0))) | AA6: =IF(Y6=0,0,MAX(1,ROUNDUP(Y6*(1-'参数与公式'!$B$17),0))) | AB6: 预算模式末级补足余数；旧模式按指数公式 | AC6: =IF(A6=A5,IFERROR(M6/M5,""),"") | AD6: =IF(AND(A6=A5,X5>0),X6/X5,"")
A7: farm | B7: 农田 | C7: 资源生产 | D7: 3 | E7: =D7+1 | F7: 50 | G7: =INDEX('建筑建议总览'!$H$5:$H$25,MATCH($A7,'建筑建议总览'!$A$5:$A$25,0)) | H7: =INDEX('建筑建议总览'!$I$5:$I$25,MATCH($A7,'建筑建议总览'!$A$5:$A$25,0)) | I7: =INDEX('建筑建议总览'!$J$5:$J$25,MATCH($A7,'建筑建议总览'!$A$5:$A$25,0)) | J7: =POWER(H7,D7-1) | K7: =SUMIF($A$5:$A$328,$A7,$J$5:$J$328) | L7: =IF(I7>0,ROUNDDOWN(MAX(0,I7-G7*(F7-1))*J7/K7,0),0) | M7: =IF(I7>0,G7+L7+IF(D7=F7-1,MAX(0,I7-G7*(F7-1)-SUMIF($A$5:$A$328,$A7,$L$5:$L$328)),0),ROUNDUP(G7*POWER(INDEX('建筑总览'!$G$5:$G$25,MATCH($A7,'建筑总览'!$A$5:$A$25,0)),D7),0)) | N7: =M7/'参数与公式'!$B$21 | O7: =INDEX('建筑建议总览'!$P$5:$P$25,MATCH($A7,'建筑建议总览'!$A$5:$A$25,0)) | P7: =INDEX('建筑建议总览'!$Q$5:$Q$25,MATCH($A7,'建筑建议总览'!$A$5:$A$25,0)) | Q7: =INDEX('建筑建议总览'!$R$5:$R$25,MATCH($A7,'建筑建议总览'!$A$5:$A$25,0)) | R7: =INDEX('建筑建议总览'!$S$5:$S$25,MATCH($A7,'建筑建议总览'!$A$5:$A$25,0)) | S7: =INDEX('建筑建议总览'!$T$5:$T$25,MATCH($A7,'建筑建议总览'!$A$5:$A$25,0)) | T7: =POWER(Q7,D7-1) | U7: =SUMIF($A$5:$A$328,$A7,$T$5:$T$328) | V7: =IF(R7>0,ROUNDDOWN(MAX(0,R7-O7*(F7-1))*T7/U7,0),0) | W7: =IF(S7>0,ROUNDDOWN(MAX(0,S7-P7*(F7-1))*T7/U7,0),0) | X7: =IF(R7>0,O7+V7+IF(D7=F7-1,MAX(0,R7-O7*(F7-1)-SUMIF($A$5:$A$328,$A7,$V$5:$V$328)),0),ROUNDUP(O7*POWER(INDEX('建筑总览'!$J$5:$J$25,MATCH($A7,'建筑总览'!$A$5:$A$25,0)),D7),0)) | Y7: =IF(P7=0,0,IF(S7>0,P7+W7+IF(D7=F7-1,MAX(0,S7-P7*(F7-1)-SUMIF($A$5:$A$328,$A7,$W$5:$W$328)),0),ROUNDUP(P7*POWER(INDEX('建筑总览'!$J$5:$J$25,MATCH($A7,'建筑总览'!$A$5:$A$25,0)),D7),0))) | Z7: =IF(X7=0,0,MAX(1,ROUNDUP(X7*(1-'参数与公式'!$B$17),0))) | AA7: =IF(Y7=0,0,MAX(1,ROUNDUP(Y7*(1-'参数与公式'!$B$17),0))) | AB7: 预算模式末级补足余数；旧模式按指数公式 | AC7: =IF(A7=A6,IFERROR(M7/M6,""),"") | AD7: =IF(AND(A7=A6,X6>0),X7/X6,"")
A8: farm | B8: 农田 | C8: 资源生产 | D8: 4 | E8: =D8+1 | F8: 50 | G8: =INDEX('建筑建议总览'!$H$5:$H$25,MATCH($A8,'建筑建议总览'!$A$5:$A$25,0)) | H8: =INDEX('建筑建议总览'!$I$5:$I$25,MATCH($A8,'建筑建议总览'!$A$5:$A$25,0)) | I8: =INDEX('建筑建议总览'!$J$5:$J$25,MATCH($A8,'建筑建议总览'!$A$5:$A$25,0)) | J8: =POWER(H8,D8-1) | K8: =SUMIF($A$5:$A$328,$A8,$J$5:$J$328) | L8: =IF(I8>0,ROUNDDOWN(MAX(0,I8-G8*(F8-1))*J8/K8,0),0) | M8: =IF(I8>0,G8+L8+IF(D8=F8-1,MAX(0,I8-G8*(F8-1)-SUMIF($A$5:$A$328,$A8,$L$5:$L$328)),0),ROUNDUP(G8*POWER(INDEX('建筑总览'!$G$5:$G$25,MATCH($A8,'建筑总览'!$A$5:$A$25,0)),D8),0)) | N8: =M8/'参数与公式'!$B$21 | O8: =INDEX('建筑建议总览'!$P$5:$P$25,MATCH($A8,'建筑建议总览'!$A$5:$A$25,0)) | P8: =INDEX('建筑建议总览'!$Q$5:$Q$25,MATCH($A8,'建筑建议总览'!$A$5:$A$25,0)) | Q8: =INDEX('建筑建议总览'!$R$5:$R$25,MATCH($A8,'建筑建议总览'!$A$5:$A$25,0)) | R8: =INDEX('建筑建议总览'!$S$5:$S$25,MATCH($A8,'建筑建议总览'!$A$5:$A$25,0)) | S8: =INDEX('建筑建议总览'!$T$5:$T$25,MATCH($A8,'建筑建议总览'!$A$5:$A$25,0)) | T8: =POWER(Q8,D8-1) | U8: =SUMIF($A$5:$A$328,$A8,$T$5:$T$328) | V8: =IF(R8>0,ROUNDDOWN(MAX(0,R8-O8*(F8-1))*T8/U8,0),0) | W8: =IF(S8>0,ROUNDDOWN(MAX(0,S8-P8*(F8-1))*T8/U8,0),0) | X8: =IF(R8>0,O8+V8+IF(D8=F8-1,MAX(0,R8-O8*(F8-1)-SUMIF($A$5:$A$328,$A8,$V$5:$V$328)),0),ROUNDUP(O8*POWER(INDEX('建筑总览'!$J$5:$J$25,MATCH($A8,'建筑总览'!$A$5:$A$25,0)),D8),0)) | Y8: =IF(P8=0,0,IF(S8>0,P8+W8+IF(D8=F8-1,MAX(0,S8-P8*(F8-1)-SUMIF($A$5:$A$328,$A8,$W$5:$W$328)),0),ROUNDUP(P8*POWER(INDEX('建筑总览'!$J$5:$J$25,MATCH($A8,'建筑总览'!$A$5:$A$25,0)),D8),0))) | Z8: =IF(X8=0,0,MAX(1,ROUNDUP(X8*(1-'参数与公式'!$B$17),0))) | AA8: =IF(Y8=0,0,MAX(1,ROUNDUP(Y8*(1-'参数与公式'!$B$17),0))) | AB8: 预算模式末级补足余数；旧模式按指数公式 | AC8: =IF(A8=A7,IFERROR(M8/M7,""),"") | AD8: =IF(AND(A8=A7,X7>0),X8/X7,"")
A9: farm | B9: 农田 | C9: 资源生产 | D9: 5 | E9: =D9+1 | F9: 50 | G9: =INDEX('建筑建议总览'!$H$5:$H$25,MATCH($A9,'建筑建议总览'!$A$5:$A$25,0)) | H9: =INDEX('建筑建议总览'!$I$5:$I$25,MATCH($A9,'建筑建议总览'!$A$5:$A$25,0)) | I9: =INDEX('建筑建议总览'!$J$5:$J$25,MATCH($A9,'建筑建议总览'!$A$5:$A$25,0)) | J9: =POWER(H9,D9-1) | K9: =SUMIF($A$5:$A$328,$A9,$J$5:$J$328) | L9: =IF(I9>0,ROUNDDOWN(MAX(0,I9-G9*(F9-1))*J9/K9,0),0) | M9: =IF(I9>0,G9+L9+IF(D9=F9-1,MAX(0,I9-G9*(F9-1)-SUMIF($A$5:$A$328,$A9,$L$5:$L$328)),0),ROUNDUP(G9*POWER(INDEX('建筑总览'!$G$5:$G$25,MATCH($A9,'建筑总览'!$A$5:$A$25,0)),D9),0)) | N9: =M9/'参数与公式'!$B$21 | O9: =INDEX('建筑建议总览'!$P$5:$P$25,MATCH($A9,'建筑建议总览'!$A$5:$A$25,0)) | P9: =INDEX('建筑建议总览'!$Q$5:$Q$25,MATCH($A9,'建筑建议总览'!$A$5:$A$25,0)) | Q9: =INDEX('建筑建议总览'!$R$5:$R$25,MATCH($A9,'建筑建议总览'!$A$5:$A$25,0)) | R9: =INDEX('建筑建议总览'!$S$5:$S$25,MATCH($A9,'建筑建议总览'!$A$5:$A$25,0)) | S9: =INDEX('建筑建议总览'!$T$5:$T$25,MATCH($A9,'建筑建议总览'!$A$5:$A$25,0)) | T9: =POWER(Q9,D9-1) | U9: =SUMIF($A$5:$A$328,$A9,$T$5:$T$328) | V9: =IF(R9>0,ROUNDDOWN(MAX(0,R9-O9*(F9-1))*T9/U9,0),0) | W9: =IF(S9>0,ROUNDDOWN(MAX(0,S9-P9*(F9-1))*T9/U9,0),0) | X9: =IF(R9>0,O9+V9+IF(D9=F9-1,MAX(0,R9-O9*(F9-1)-SUMIF($A$5:$A$328,$A9,$V$5:$V$328)),0),ROUNDUP(O9*POWER(INDEX('建筑总览'!$J$5:$J$25,MATCH($A9,'建筑总览'!$A$5:$A$25,0)),D9),0)) | Y9: =IF(P9=0,0,IF(S9>0,P9+W9+IF(D9=F9-1,MAX(0,S9-P9*(F9-1)-SUMIF($A$5:$A$328,$A9,$W$5:$W$328)),0),ROUNDUP(P9*POWER(INDEX('建筑总览'!$J$5:$J$25,MATCH($A9,'建筑总览'!$A$5:$A$25,0)),D9),0))) | Z9: =IF(X9=0,0,MAX(1,ROUNDUP(X9*(1-'参数与公式'!$B$17),0))) | AA9: =IF(Y9=0,0,MAX(1,ROUNDUP(Y9*(1-'参数与公式'!$B$17),0))) | AB9: 预算模式末级补足余数；旧模式按指数公式 | AC9: =IF(A9=A8,IFERROR(M9/M8,""),"") | AD9: =IF(AND(A9=A8,X8>0),X9/X8,"")
A10: farm | B10: 农田 | C10: 资源生产 | D10: 6 | E10: =D10+1 | F10: 50 | G10: =INDEX('建筑建议总览'!$H$5:$H$25,MATCH($A10,'建筑建议总览'!$A$5:$A$25,0)) | H10: =INDEX('建筑建议总览'!$I$5:$I$25,MATCH($A10,'建筑建议总览'!$A$5:$A$25,0)) | I10: =INDEX('建筑建议总览'!$J$5:$J$25,MATCH($A10,'建筑建议总览'!$A$5:$A$25,0)) | J10: =POWER(H10,D10-1) | K10: =SUMIF($A$5:$A$328,$A10,$J$5:$J$328) | L10: =IF(I10>0,ROUNDDOWN(MAX(0,I10-G10*(F10-1))*J10/K10,0),0) | M10: =IF(I10>0,G10+L10+IF(D10=F10-1,MAX(0,I10-G10*(F10-1)-SUMIF($A$5:$A$328,$A10,$L$5:$L$328)),0),ROUNDUP(G10*POWER(INDEX('建筑总览'!$G$5:$G$25,MATCH($A10,'建筑总览'!$A$5:$A$25,0)),D10),0)) | N10: =M10/'参数与公式'!$B$21 | O10: =INDEX('建筑建议总览'!$P$5:$P$25,MATCH($A10,'建筑建议总览'!$A$5:$A$25,0)) | P10: =INDEX('建筑建议总览'!$Q$5:$Q$25,MATCH($A10,'建筑建议总览'!$A$5:$A$25,0)) | Q10: =INDEX('建筑建议总览'!$R$5:$R$25,MATCH($A10,'建筑建议总览'!$A$5:$A$25,0)) | R10: =INDEX('建筑建议总览'!$S$5:$S$25,MATCH($A10,'建筑建议总览'!$A$5:$A$25,0)) | S10: =INDEX('建筑建议总览'!$T$5:$T$25,MATCH($A10,'建筑建议总览'!$A$5:$A$25,0)) | T10: =POWER(Q10,D10-1) | U10: =SUMIF($A$5:$A$328,$A10,$T$5:$T$328) | V10: =IF(R10>0,ROUNDDOWN(MAX(0,R10-O10*(F10-1))*T10/U10,0),0) | W10: =IF(S10>0,ROUNDDOWN(MAX(0,S10-P10*(F10-1))*T10/U10,0),0) | X10: =IF(R10>0,O10+V10+IF(D10=F10-1,MAX(0,R10-O10*(F10-1)-SUMIF($A$5:$A$328,$A10,$V$5:$V$328)),0),ROUNDUP(O10*POWER(INDEX('建筑总览'!$J$5:$J$25,MATCH($A10,'建筑总览'!$A$5:$A$25,0)),D10),0)) | Y10: =IF(P10=0,0,IF(S10>0,P10+W10+IF(D10=F10-1,MAX(0,S10-P10*(F10-1)-SUMIF($A$5:$A$328,$A10,$W$5:$W$328)),0),ROUNDUP(P10*POWER(INDEX('建筑总览'!$J$5:$J$25,MATCH($A10,'建筑总览'!$A$5:$A$25,0)),D10),0))) | Z10: =IF(X10=0,0,MAX(1,ROUNDUP(X10*(1-'参数与公式'!$B$17),0))) | AA10: =IF(Y10=0,0,MAX(1,ROUNDUP(Y10*(1-'参数与公式'!$B$17),0))) | AB10: 预算模式末级补足余数；旧模式按指数公式 | AC10: =IF(A10=A9,IFERROR(M10/M9,""),"") | AD10: =IF(AND(A10=A9,X9>0),X10/X9,"")
A11: farm | B11: 农田 | C11: 资源生产 | D11: 7 | E11: =D11+1 | F11: 50 | G11: =INDEX('建筑建议总览'!$H$5:$H$25,MATCH($A11,'建筑建议总览'!$A$5:$A$25,0)) | H11: =INDEX('建筑建议总览'!$I$5:$I$25,MATCH($A11,'建筑建议总览'!$A$5:$A$25,0)) | I11: =INDEX('建筑建议总览'!$J$5:$J$25,MATCH($A11,'建筑建议总览'!$A$5:$A$25,0)) | J11: =POWER(H11,D11-1) | K11: =SUMIF($A$5:$A$328,$A11,$J$5:$J$328) | L11: =IF(I11>0,ROUNDDOWN(MAX(0,I11-G11*(F11-1))*J11/K11,0),0) | M11: =IF(I11>0,G11+L11+IF(D11=F11-1,MAX(0,I11-G11*(F11-1)-SUMIF($A$5:$A$328,$A11,$L$5:$L$328)),0),ROUNDUP(G11*POWER(INDEX('建筑总览'!$G$5:$G$25,MATCH($A11,'建筑总览'!$A$5:$A$25,0)),D11),0)) | N11: =M11/'参数与公式'!$B$21 | O11: =INDEX('建筑建议总览'!$P$5:$P$25,MATCH($A11,'建筑建议总览'!$A$5:$A$25,0)) | P11: =INDEX('建筑建议总览'!$Q$5:$Q$25,MATCH($A11,'建筑建议总览'!$A$5:$A$25,0)) | Q11: =INDEX('建筑建议总览'!$R$5:$R$25,MATCH($A11,'建筑建议总览'!$A$5:$A$25,0)) | R11: =INDEX('建筑建议总览'!$S$5:$S$25,MATCH($A11,'建筑建议总览'!$A$5:$A$25,0)) | S11: =INDEX('建筑建议总览'!$T$5:$T$25,MATCH($A11,'建筑建议总览'!$A$5:$A$25,0)) | T11: =POWER(Q11,D11-1) | U11: =SUMIF($A$5:$A$328,$A11,$T$5:$T$328) | V11: =IF(R11>0,ROUNDDOWN(MAX(0,R11-O11*(F11-1))*T11/U11,0),0) | W11: =IF(S11>0,ROUNDDOWN(MAX(0,S11-P11*(F11-1))*T11/U11,0),0) | X11: =IF(R11>0,O11+V11+IF(D11=F11-1,MAX(0,R11-O11*(F11-1)-SUMIF($A$5:$A$328,$A11,$V$5:$V$328)),0),ROUNDUP(O11*POWER(INDEX('建筑总览'!$J$5:$J$25,MATCH($A11,'建筑总览'!$A$5:$A$25,0)),D11),0)) | Y11: =IF(P11=0,0,IF(S11>0,P11+W11+IF(D11=F11-1,MAX(0,S11-P11*(F11-1)-SUMIF($A$5:$A$328,$A11,$W$5:$W$328)),0),ROUNDUP(P11*POWER(INDEX('建筑总览'!$J$5:$J$25,MATCH($A11,'建筑总览'!$A$5:$A$25,0)),D11),0))) | Z11: =IF(X11=0,0,MAX(1,ROUNDUP(X11*(1-'参数与公式'!$B$17),0))) | AA11: =IF(Y11=0,0,MAX(1,ROUNDUP(Y11*(1-'参数与公式'!$B$17),0))) | AB11: 预算模式末级补足余数；旧模式按指数公式 | AC11: =IF(A11=A10,IFERROR(M11/M10,""),"") | AD11: =IF(AND(A11=A10,X10>0),X11/X10,"")
A12: farm | B12: 农田 | C12: 资源生产 | D12: 8 | E12: =D12+1 | F12: 50 | G12: =INDEX('建筑建议总览'!$H$5:$H$25,MATCH($A12,'建筑建议总览'!$A$5:$A$25,0)) | H12: =INDEX('建筑建议总览'!$I$5:$I$25,MATCH($A12,'建筑建议总览'!$A$5:$A$25,0)) | I12: =INDEX('建筑建议总览'!$J$5:$J$25,MATCH($A12,'建筑建议总览'!$A$5:$A$25,0)) | J12: =POWER(H12,D12-1) | K12: =SUMIF($A$5:$A$328,$A12,$J$5:$J$328) | L12: =IF(I12>0,ROUNDDOWN(MAX(0,I12-G12*(F12-1))*J12/K12,0),0) | M12: =IF(I12>0,G12+L12+IF(D12=F12-1,MAX(0,I12-G12*(F12-1)-SUMIF($A$5:$A$328,$A12,$L$5:$L$328)),0),ROUNDUP(G12*POWER(INDEX('建筑总览'!$G$5:$G$25,MATCH($A12,'建筑总览'!$A$5:$A$25,0)),D12),0)) | N12: =M12/'参数与公式'!$B$21 | O12: =INDEX('建筑建议总览'!$P$5:$P$25,MATCH($A12,'建筑建议总览'!$A$5:$A$25,0)) | P12: =INDEX('建筑建议总览'!$Q$5:$Q$25,MATCH($A12,'建筑建议总览'!$A$5:$A$25,0)) | Q12: =INDEX('建筑建议总览'!$R$5:$R$25,MATCH($A12,'建筑建议总览'!$A$5:$A$25,0)) | R12: =INDEX('建筑建议总览'!$S$5:$S$25,MATCH($A12,'建筑建议总览'!$A$5:$A$25,0)) | S12: =INDEX('建筑建议总览'!$T$5:$T$25,MATCH($A12,'建筑建议总览'!$A$5:$A$25,0)) | T12: =POWER(Q12,D12-1) | U12: =SUMIF($A$5:$A$328,$A12,$T$5:$T$328) | V12: =IF(R12>0,ROUNDDOWN(MAX(0,R12-O12*(F12-1))*T12/U12,0),0) | W12: =IF(S12>0,ROUNDDOWN(MAX(0,S12-P12*(F12-1))*T12/U12,0),0) | X12: =IF(R12>0,O12+V12+IF(D12=F12-1,MAX(0,R12-O12*(F12-1)-SUMIF($A$5:$A$328,$A12,$V$5:$V$328)),0),ROUNDUP(O12*POWER(INDEX('建筑总览'!$J$5:$J$25,MATCH($A12,'建筑总览'!$A$5:$A$25,0)),D12),0)) | Y12: =IF(P12=0,0,IF(S12>0,P12+W12+IF(D12=F12-1,MAX(0,S12-P12*(F12-1)-SUMIF($A$5:$A$328,$A12,$W$5:$W$328)),0),ROUNDUP(P12*POWER(INDEX('建筑总览'!$J$5:$J$25,MATCH($A12,'建筑总览'!$A$5:$A$25,0)),D12),0))) | Z12: =IF(X12=0,0,MAX(1,ROUNDUP(X12*(1-'参数与公式'!$B$17),0))) | AA12: =IF(Y12=0,0,MAX(1,ROUNDUP(Y12*(1-'参数与公式'!$B$17),0))) | AB12: 预算模式末级补足余数；旧模式按指数公式 | AC12: =IF(A12=A11,IFERROR(M12/M11,""),"") | AD12: =IF(AND(A12=A11,X11>0),X12/X11,"")
A13: farm | B13: 农田 | C13: 资源生产 | D13: 9 | E13: =D13+1 | F13: 50 | G13: =INDEX('建筑建议总览'!$H$5:$H$25,MATCH($A13,'建筑建议总览'!$A$5:$A$25,0)) | H13: =INDEX('建筑建议总览'!$I$5:$I$25,MATCH($A13,'建筑建议总览'!$A$5:$A$25,0)) | I13: =INDEX('建筑建议总览'!$J$5:$J$25,MATCH($A13,'建筑建议总览'!$A$5:$A$25,0)) | J13: =POWER(H13,D13-1) | K13: =SUMIF($A$5:$A$328,$A13,$J$5:$J$328) | L13: =IF(I13>0,ROUNDDOWN(MAX(0,I13-G13*(F13-1))*J13/K13,0),0) | M13: =IF(I13>0,G13+L13+IF(D13=F13-1,MAX(0,I13-G13*(F13-1)-SUMIF($A$5:$A$328,$A13,$L$5:$L$328)),0),ROUNDUP(G13*POWER(INDEX('建筑总览'!$G$5:$G$25,MATCH($A13,'建筑总览'!$A$5:$A$25,0)),D13),0)) | N13: =M13/'参数与公式'!$B$21 | O13: =INDEX('建筑建议总览'!$P$5:$P$25,MATCH($A13,'建筑建议总览'!$A$5:$A$25,0)) | P13: =INDEX('建筑建议总览'!$Q$5:$Q$25,MATCH($A13,'建筑建议总览'!$A$5:$A$25,0)) | Q13: =INDEX('建筑建议总览'!$R$5:$R$25,MATCH($A13,'建筑建议总览'!$A$5:$A$25,0)) | R13: =INDEX('建筑建议总览'!$S$5:$S$25,MATCH($A13,'建筑建议总览'!$A$5:$A$25,0)) | S13: =INDEX('建筑建议总览'!$T$5:$T$25,MATCH($A13,'建筑建议总览'!$A$5:$A$25,0)) | T13: =POWER(Q13,D13-1) | U13: =SUMIF($A$5:$A$328,$A13,$T$5:$T$328) | V13: =IF(R13>0,ROUNDDOWN(MAX(0,R13-O13*(F13-1))*T13/U13,0),0) | W13: =IF(S13>0,ROUNDDOWN(MAX(0,S13-P13*(F13-1))*T13/U13,0),0) | X13: =IF(R13>0,O13+V13+IF(D13=F13-1,MAX(0,R13-O13*(F13-1)-SUMIF($A$5:$A$328,$A13,$V$5:$V$328)),0),ROUNDUP(O13*POWER(INDEX('建筑总览'!$J$5:$J$25,MATCH($A13,'建筑总览'!$A$5:$A$25,0)),D13),0)) | Y13: =IF(P13=0,0,IF(S13>0,P13+W13+IF(D13=F13-1,MAX(0,S13-P13*(F13-1)-SUMIF($A$5:$A$328,$A13,$W$5:$W$328)),0),ROUNDUP(P13*POWER(INDEX('建筑总览'!$J$5:$J$25,MATCH($A13,'建筑总览'!$A$5:$A$25,0)),D13),0))) | Z13: =IF(X13=0,0,MAX(1,ROUNDUP(X13*(1-'参数与公式'!$B$17),0))) | AA13: =IF(Y13=0,0,MAX(1,ROUNDUP(Y13*(1-'参数与公式'!$B$17),0))) | AB13: 预算模式末级补足余数；旧模式按指数公式 | AC13: =IF(A13=A12,IFERROR(M13/M12,""),"") | AD13: =IF(AND(A13=A12,X12>0),X13/X12,"")
A14: farm | B14: 农田 | C14: 资源生产 | D14: 10 | E14: =D14+1 | F14: 50 | G14: =INDEX('建筑建议总览'!$H$5:$H$25,MATCH($A14,'建筑建议总览'!$A$5:$A$25,0)) | H14: =INDEX('建筑建议总览'!$I$5:$I$25,MATCH($A14,'建筑建议总览'!$A$5:$A$25,0)) | I14: =INDEX('建筑建议总览'!$J$5:$J$25,MATCH($A14,'建筑建议总览'!$A$5:$A$25,0)) | J14: =POWER(H14,D14-1) | K14: =SUMIF($A$5:$A$328,$A14,$J$5:$J$328) | L14: =IF(I14>0,ROUNDDOWN(MAX(0,I14-G14*(F14-1))*J14/K14,0),0) | M14: =IF(I14>0,G14+L14+IF(D14=F14-1,MAX(0,I14-G14*(F14-1)-SUMIF($A$5:$A$328,$A14,$L$5:$L$328)),0),ROUNDUP(G14*POWER(INDEX('建筑总览'!$G$5:$G$25,MATCH($A14,'建筑总览'!$A$5:$A$25,0)),D14),0)) | N14: =M14/'参数与公式'!$B$21 | O14: =INDEX('建筑建议总览'!$P$5:$P$25,MATCH($A14,'建筑建议总览'!$A$5:$A$25,0)) | P14: =INDEX('建筑建议总览'!$Q$5:$Q$25,MATCH($A14,'建筑建议总览'!$A$5:$A$25,0)) | Q14: =INDEX('建筑建议总览'!$R$5:$R$25,MATCH($A14,'建筑建议总览'!$A$5:$A$25,0)) | R14: =INDEX('建筑建议总览'!$S$5:$S$25,MATCH($A14,'建筑建议总览'!$A$5:$A$25,0)) | S14: =INDEX('建筑建议总览'!$T$5:$T$25,MATCH($A14,'建筑建议总览'!$A$5:$A$25,0)) | T14: =POWER(Q14,D14-1) | U14: =SUMIF($A$5:$A$328,$A14,$T$5:$T$328) | V14: =IF(R14>0,ROUNDDOWN(MAX(0,R14-O14*(F14-1))*T14/U14,0),0) | W14: =IF(S14>0,ROUNDDOWN(MAX(0,S14-P14*(F14-1))*T14/U14,0),0) | X14: =IF(R14>0,O14+V14+IF(D14=F14-1,MAX(0,R14-O14*(F14-1)-SUMIF($A$5:$A$328,$A14,$V$5:$V$328)),0),ROUNDUP(O14*POWER(INDEX('建筑总览'!$J$5:$J$25,MATCH($A14,'建筑总览'!$A$5:$A$25,0)),D14),0)) | Y14: =IF(P14=0,0,IF(S14>0,P14+W14+IF(D14=F14-1,MAX(0,S14-P14*(F14-1)-SUMIF($A$5:$A$328,$A14,$W$5:$W$328)),0),ROUNDUP(P14*POWER(INDEX('建筑总览'!$J$5:$J$25,MATCH($A14,'建筑总览'!$A$5:$A$25,0)),D14),0))) | Z14: =IF(X14=0,0,MAX(1,ROUNDUP(X14*(1-'参数与公式'!$B$17),0))) | AA14: =IF(Y14=0,0,MAX(1,ROUNDUP(Y14*(1-'参数与公式'!$B$17),0))) | AB14: 预算模式末级补足余数；旧模式按指数公式 | AC14: =IF(A14=A13,IFERROR(M14/M13,""),"") | AD14: =IF(AND(A14=A13,X13>0),X14/X13,"")
A15: farm | B15: 农田 | C15: 资源生产 | D15: 11 | E15: =D15+1 | F15: 50 | G15: =INDEX('建筑建议总览'!$H$5:$H$25,MATCH($A15,'建筑建议总览'!$A$5:$A$25,0)) | H15: =INDEX('建筑建议总览'!$I$5:$I$25,MATCH($A15,'建筑建议总览'!$A$5:$A$25,0)) | I15: =INDEX('建筑建议总览'!$J$5:$J$25,MATCH($A15,'建筑建议总览'!$A$5:$A$25,0)) | J15: =POWER(H15,D15-1) | K15: =SUMIF($A$5:$A$328,$A15,$J$5:$J$328) | L15: =IF(I15>0,ROUNDDOWN(MAX(0,I15-G15*(F15-1))*J15/K15,0),0) | M15: =IF(I15>0,G15+L15+IF(D15=F15-1,MAX(0,I15-G15*(F15-1)-SUMIF($A$5:$A$328,$A15,$L$5:$L$328)),0),ROUNDUP(G15*POWER(INDEX('建筑总览'!$G$5:$G$25,MATCH($A15,'建筑总览'!$A$5:$A$25,0)),D15),0)) | N15: =M15/'参数与公式'!$B$21 | O15: =INDEX('建筑建议总览'!$P$5:$P$25,MATCH($A15,'建筑建议总览'!$A$5:$A$25,0)) | P15: =INDEX('建筑建议总览'!$Q$5:$Q$25,MATCH($A15,'建筑建议总览'!$A$5:$A$25,0)) | Q15: =INDEX('建筑建议总览'!$R$5:$R$25,MATCH($A15,'建筑建议总览'!$A$5:$A$25,0)) | R15: =INDEX('建筑建议总览'!$S$5:$S$25,MATCH($A15,'建筑建议总览'!$A$5:$A$25,0)) | S15: =INDEX('建筑建议总览'!$T$5:$T$25,MATCH($A15,'建筑建议总览'!$A$5:$A$25,0)) | T15: =POWER(Q15,D15-1) | U15: =SUMIF($A$5:$A$328,$A15,$T$5:$T$328) | V15: =IF(R15>0,ROUNDDOWN(MAX(0,R15-O15*(F15-1))*T15/U15,0),0) | W15: =IF(S15>0,ROUNDDOWN(MAX(0,S15-P15*(F15-1))*T15/U15,0),0) | X15: =IF(R15>0,O15+V15+IF(D15=F15-1,MAX(0,R15-O15*(F15-1)-SUMIF($A$5:$A$328,$A15,$V$5:$V$328)),0),ROUNDUP(O15*POWER(INDEX('建筑总览'!$J$5:$J$25,MATCH($A15,'建筑总览'!$A$5:$A$25,0)),D15),0)) | Y15: =IF(P15=0,0,IF(S15>0,P15+W15+IF(D15=F15-1,MAX(0,S15-P15*(F15-1)-SUMIF($A$5:$A$328,$A15,$W$5:$W$328)),0),ROUNDUP(P15*POWER(INDEX('建筑总览'!$J$5:$J$25,MATCH($A15,'建筑总览'!$A$5:$A$25,0)),D15),0))) | Z15: =IF(X15=0,0,MAX(1,ROUNDUP(X15*(1-'参数与公式'!$B$17),0))) | AA15: =IF(Y15=0,0,MAX(1,ROUNDUP(Y15*(1-'参数与公式'!$B$17),0))) | AB15: 预算模式末级补足余数；旧模式按指数公式 | AC15: =IF(A15=A14,IFERROR(M15/M14,""),"") | AD15: =IF(AND(A15=A14,X14>0),X15/X14,"")
